File: .gitbook/assets/mane.6962.experimental.session.specimen_rawdata_d (2).csv
Crosshead speed,10,mm/min,,,,,,,
Tensile strain,25.4,mm,,,,,Area,2.64044E-05,
,,,,,,,,,
Time,Extension,Load,Strain from Extensometer,,,,,,
(s),(mm),(N),(mm/mm),,,,,Stress,Strain
0,0,-0.01846,-0.00001,,,,,-699.1259033,0
0.35,0.05812,0.02127,0,,,,,805.5475603,0.414541503
0.7,0.11703,0.0723,0,,,,,2738.18,0.834717689
1.05,0.17516,0.11479,0,,,,,4347.381497,1.249330517
1.4,0.23359,0.17417,0,,,,,6596.24911,1.666083098
1.75,0.29187,0.21603,0,,,,,8181.590947,2.081765802
2.1,0.35,0.26054,0,,,,,9867.294845,2.49637863
2.45,0.40844,0.31566,0,,,,,11954.82571,2.913202536
2.8,0.46687,0.34922,0,,,,,13225.826,3.329955117
3.15,0.525,0.41521,0,,,,,15725.03068,3.744567945
3.5,0.58328,0.45556,0,,,,,17253.18508,4.160250649
3.85,0.64187,0.50625,0,,,,,19172.94087,4.578144432
4.2,0.70016,0.53679,0,,,,,20329.56628,4.993898462
4.55,0.75844,0.61174,0,,,,,23168.10835,5.409581166
4.9,0.81703,0.634,0,,,,,24011.14966,5.827474949
5.25,0.87531,0.68781,0,,,,,26049.06758,6.243157653
5.6,0.93375,0.72651,0,,,,,27514.73239,6.659981559
5.95,0.99234,0.80405,0,,,,,30451.36417,7.077875342
6.3,1.05047,0.82606,0,,,,,31284.93736,7.49248817
6.65,1.10891,0.89601,0,,,,,33934.11704,7.909312076
7,1.1675,0.93165,0,,,,,35283.89208,8.327205859
7.35,1.22562,0.96184,0,,,,,36427.26212,8.741747361
7.7,1.28391,1.017,0,,,,,38516.30789,9.157501391
8.05,1.34234,1.0681,-0.00001,,,,,40451.5914,9.574253972
8.4,1.40062,1.12269,0,,,,,42519.04986,9.989936676
8.75,1.45875,1.1603,0.00002,,,,,43943.43367,10.4045495
9.1,1.51703,1.2129,-0.00001,,,,,45935.5259,10.82023221
9.45,1.57531,1.26068,0.00001,,,,,47745.07279,11.23591491
9.8,1.63359,1.32097,-0.00001,,,,,50028.40436,11.65159762
10.15,1.69187,1.37833,0.00001,,,,,52200.76957,12.06728032
10.5,1.75031,1.41971,0,,,,,53767.93262,12.48410423
10.85,1.80828,1.46635,0,,,,,55534.30489,12.89757585
11.2,1.86672,1.49808,0,,,,,56735.99855,13.31439976
11.55,1.92516,1.5748,0,,,,,59641.57489,13.73122367
11.9,1.98312,1.59228,0.00001,,,,,60303.58577,14.14462397
12.25,2.04172,1.63432,0.00001,,,,,61895.74465,14.56258908
12.6,2.10016,1.70272,0.00001,,,,,64486.22199,14.97941298
12.95,2.15844,1.755,0.00006,,,,,66466.19503,15.39509569
13.3,2.21687,1.80177,-0.00001,,,,,68237.49072,15.81184827
13.65,2.27531,1.83904,0.00002,,,,,69648.99789,16.22867217
14,2.33375,1.91314,0,,,,,72455.34835,16.64549608
14.35,2.39203,1.92779,0.00002,,,,,73010.18012,17.06117878
14.7,2.45047,1.97625,0,,,,,74845.4803,17.47800269
15.05,2.50891,2.05872,0.00001,,,,,77968.82338,17.8948266
15.4,2.56734,2.06388,0,,,,,78164.24535,18.31157918
15.75,2.62578,2.12514,0,,,,,80484.31322,18.72840308
16.1,2.68406,2.18229,0.00001,,,,,82648.72521,19.14408579
16.45,2.74219,2.22395,0,,,,,84226.49255,19.55869862
16.8,2.80078,2.25773,0.00001,,,,,85505.82479,19.9765924
17.15,2.85891,2.30992,-0.00001,,,,,87482.3893,20.39120523
17.5,2.91703,2.36984,0.00001,,,,,89751.70805,20.80574673
17.85,2.97562,2.39623,0.00001,,,,,90751.16269,21.22364051
18.2,3.03375,2.44316,0.00001,,,,,92528.51797,21.63825334
18.55,3.09187,2.49615,0.00001,,,,,94535.38047,22.05279484
18.9,3.15031,2.54462,0,,,,,96371.05937,22.46961875
19.25,3.20859,2.56323,0.00001,,,,,97075.86614,22.88530145
19.6,3.26672,2.63285,0,,,,,99712.54791,23.29991428
19.95,3.325,2.66086,0.00001,,,,,100773.356,23.71559698
20.3,3.38344,2.71489,0,,,,,102819.6058,24.13242089
20.65,3.44172,2.77074,0.00001,,,,,104934.7836,24.5481036
21,3.50016,2.82544,0.00001,,,,,107006.408,24.9649275
21.35,3.55844,2.87056,0.00001,,,,,108715.2141,25.38061021
21.7,3.61672,2.91949,0.00001,,,,,110568.3144,25.79629291
22.05,3.675,2.95438,0,,,,,111889.6851,26.21197561
22.4,3.73359,3.00495,0.00001,,,,,113804.8962,26.6298694
22.75,3.79187,3.05858,0,,,,,115835.997,27.0455521
23.1,3.85031,3.09464,0.00001,,,,,117201.6785,27.46237601
23.45,3.90906,3.13726,0.00001,,,,,118815.8034,27.88141099
23.8,3.96734,3.19245,0,,,,,120905.9854,28.2970937
24.15,4.02547,3.23474,0.00001,,,,,122507.6124,28.71170652
24.5,4.08406,3.27131,0.00001,,,,,123892.6088,29.12960031
24.85,4.14234,3.31222,0,,,,,125441.9718,29.54528301
25.2,4.20047,3.37313,0,,,,,127748.7843,29.95989584
25.55,4.25906,3.41149,0.00001,,,,,129201.5725,30.37778962
25.9,4.31734,3.47177,0,,,,,131484.5253,30.79347233
26.25,4.37531,3.50286,0,,,,,132661.9806,31.20694395
26.6,4.43391,3.53604,0,,,,,133918.5893,31.62490906
26.95,4.49203,3.58066,0,,,,,135608.4592,32.03945056
27.3,4.55016,3.64129,0,,,,,137904.6674,32.45406339
27.65,4.60859,3.69755,0,,,,,140035.3729,32.87081597
28,4.66687,3.7355,0,,,,,141472.6333,33.28649868
28.35,4.725,3.79142,0.00001,,,,,143590.4622,33.7011115
28.7,4.78328,3.80577,0,,,,,144133.9322,34.11679421
29.05,4.84172,3.85344,0.00001,,,,,145939.3131,34.53361812
29.4,4.9,3.88409,0,,,,,147100.1045,34.94930082
29.75,4.95828,3.9363,0.00001,,,,,149077.4265,35.36498352
30.1,5.01687,3.99258,0,,,,,151208.8894,35.78287731
30.45,5.075,4.02119,0.00001,,,,,152292.421,36.19749013
30.8,5.13344,4.07847,0,,,,,154461.7564,36.61431404
31.15,5.19219,4.12351,0.00001,,,,,156167.5327,37.03334902
31.5,5.25031,4.17268,0,,,,,158029.7223,37.44789053
31.85,5.30891,4.21155,-0.00001,,,,,159501.8255,37.86585564
32.2,5.3675,4.25125,0.00002,,,,,161005.3627,38.28374942
32.55,5.42547,4.3148,-0.00002,,,,,163412.1586,38.69722104
32.9,5.48391,4.34717,0.00002,,,,,164638.0906,39.11404495
33.25,5.5425,4.401,0,,,,,166676.766,39.53193873
33.6,5.60062,4.44453,0.00001,,,,,168325.3549,39.94648024
33.95,5.65891,4.45226,0,,,,,168618.1091,40.36223427
34.3,5.71734,4.52086,0.00001,,,,,171216.1609,40.77898685
34.65,5.77578,4.59288,0,,,,,173943.7366,41.19581075
35,5.83375,4.61738,0,,,,,174871.6123,41.60928238
35.35,5.89203,4.64428,0.00001,,,,,175890.3819,42.02496508
35.7,5.95031,4.69357,0,,,,,177757.1162,42.44064779
36.05,6.00859,4.74418,0.00001,,,,,179673.8422,42.85633049
36.4,6.06687,4.77665,0,,,,,180903.5615,43.2720132
36.75,6.12531,4.81149,0,,,,,182223.0386,43.6888371
37.1,6.18328,4.83012,0.00001,,,,,182928.6028,44.10230873
37.45,6.24172,4.91785,-0.00004,,,,,186251.1551,44.51913263
37.8,6.30016,4.97679,0.00003,,,,,188483.3588,44.93595654
38.15,6.35828,4.99754,-0.00001,,,,,189269.2127,45.35049804
38.5,6.41672,5.05054,0.00002,,,,,191276.4539,45.76732195
38.85,6.47516,5.07731,-0.00001,,,,,192290.3001,46.18414586
39.2,6.53344,5.11586,0.00001,,,,,193750.284,46.59982856
39.55,6.59187,5.18112,0.00002,,,,,196221.8418,47.01658114
39.9,6.65031,5.21921,0,,,,,197664.4044,47.43340505
40.25,6.70859,5.25318,0.00001,,,,,198950.9324,47.84908775
40.6,6.76703,5.2715,0,,,,,199644.7562,48.26591166
40.95,6.82562,5.34996,0.00001,,,,,202616.2306,48.68380544
41.3,6.88375,5.37039,0.00001,,,,,203389.9653,49.09841827
41.65,6.94219,5.4306,0.00001,,,,,205670.2671,49.51524217
42,7.00078,5.47279,0.00001,,,,,207268.1068,49.93313596
42.35,7.05906,5.51615,0.00001,,,,,208910.2574,50.34881866
42.7,7.11719,5.53969,0,,,,,209801.7755,50.76343149
43.05,7.17578,5.58164,-0.00002,,,,,211390.5258,51.18132527
43.4,7.23391,5.62291,0.00001,,,,,212953.5229,51.5959381
43.75,7.29203,5.66574,0,,,,,214575.601,52.0104796
44.1,7.35047,5.71421,0.00001,,,,,216411.2799,52.42730351
44.45,7.40875,5.75958,0.00001,,,,,218129.5542,52.84298621
44.8,7.46687,5.79684,0.00001,,,,,219540.6826,53.25752772
45.15,7.52547,5.84254,0.00001,,,,,221271.4548,53.67549282
45.5,7.58359,5.89503,0.00001,,,,,223259.381,54.09003433
45.85,7.64172,5.92382,0.00001,,,,,224349.7296,54.50464715
46.2,7.7,5.97564,0.00001,,,,,226312.2813,54.92032986
46.55,7.75844,5.98874,0.00001,,,,,226808.4107,55.33715377
46.9,7.81672,6.0515,0,,,,,229185.2873,55.75283647
47.25,7.87515,6.10219,0.00001,,,,,231105.0431,56.16958905
47.6,7.93344,6.13606,0.00001,,,,,232387.7839,56.58534308
47.95,7.99187,6.16714,0.00001,,,,,233564.8604,57.00209566
48.3,8.05,6.20927,0.00001,,,,,235160.4278,57.41670849
48.65,8.10875,6.27106,0.00001,,,,,237500.5681,57.83574347
49,8.16687,6.29686,0,,,,,238477.678,58.25028498
49.35,8.22547,6.33618,0.00001,,,,,239966.8237,58.66825008
49.7,8.28406,6.36393,0.00001,,,,,241017.7849,59.08614387
50.05,8.34234,6.41541,0,,,,,242967.46,59.50182657
50.4,8.40047,6.4529,0,,,,,244387.2991,59.9164394
50.75,8.45906,6.50616,0,,,,,246404.3871,60.33433318
51.1,8.51734,6.54686,0,,,,,247945.7969,60.75001589
51.45,8.57562,6.56548,0.00001,,,,,248650.9824,61.16569859
51.8,8.63391,6.62048,0.00001,,,,,250733.9686,61.58145262
52.15,8.69219,6.67651,0.00001,,,,,252855.9634,61.99713532
52.5,8.75047,6.71112,0.00001,,,,,254166.7298,62.41281803
52.85,8.8089,6.74805,0,,,,,255565.3603,62.82957061
53.2,8.86703,6.78463,0.00001,,,,,256950.7355,63.24418344
53.55,8.92515,6.83912,0.00001,,,,,259014.4067,63.65872494
53.9,8.98359,6.88359,0,,,,,260698.5957,64.07554885
54.25,9.04187,6.89666,0.00003,,,,,261193.5889,64.49123155
54.6,9.1,6.96422,0,,,,,263752.2534,64.90584438
54.95,9.15828,6.99654,0.00001,,,,,264976.2918,65.32152708
55.3,9.21687,7.03774,0,,,,,266536.6378,65.73942087
55.65,9.275,7.06367,0.00001,,,,,267518.6711,66.15403369
56,9.33344,7.1097,0.00001,,,,,269261.9412,66.5708576
56.35,9.39187,7.1467,-0.00001,,,,,270663.2228,66.98761018
56.7,9.45,7.20766,0.00003,,,,,272971.9289,67.40222301
57.05,9.50859,7.23448,-0.00001,,,,,273987.6687,67.82011679
57.4,9.56703,7.27745,0.00001,,,,,275615.049,68.2369407
57.75,9.62531,7.32373,0.00001,,,,,277367.7872,68.6526234
58.1,9.6839,7.34527,0,,,,,278183.5603,69.07051718
58.45,9.74234,7.38364,0.00002,,,,,279636.7272,69.48734109
58.8,9.80062,7.43681,0,,,,,281650.4068,69.9030238
59.15,9.8589,7.48556,0.00001,,,,,283496.6899,70.3187065
59.5,9.9175,7.51051,0,,,,,284441.6082,70.73667161
59.85,9.97562,7.57774,0.00001,,,,,286987.7748,71.15121311
60.2,10.03406,7.59018,0.00001,,,,,287458.9084,71.56803702
60.55,10.09234,7.64802,0.00001,,,,,289649.4524,71.98371972
60.9,10.15062,7.68491,0.00001,,,,,291046.568,72.39940243
61.25,10.20875,7.70858,-0.00001,,,,,291943.0095,72.81401525
61.6,10.26703,7.7593,0.00001,,,,,293863.9015,73.22969796
61.95,10.32531,7.79388,0.00001,,,,,295173.5317,73.64538066
62.3,10.38359,7.85552,0.00001,,,,,297507.9911,74.06106337
62.65,10.44187,7.88159,0.00001,,,,,298495.3265,74.47674607
63,10.50031,7.91031,0.00001,,,,,299583.024,74.89356998
63.35,10.55828,7.97424,0.00001,,,,,302004.2114,75.3070416
63.7,10.61672,8.00296,0.00001,,,,,303091.9089,75.72386551
64.05,10.675,8.04831,0.00001,,,,,304809.4257,76.13954821
64.4,10.73312,8.07238,0.00001,,,,,305721.0162,76.55408972
64.75,10.79172,8.12399,0.00001,,,,,307675.6147,76.97205482
65.1,10.85015,8.15149,0.00001,,,,,308717.1078,77.38880741
65.45,10.90844,8.19323,0.00001,,,,,310297.9049,77.80456143
65.8,10.96687,8.24198,0,,,,,312144.1881,78.22131402
66.15,11.02547,8.27344,0.00001,,,,,313335.6562,78.63927912
66.5,11.08359,8.32868,0,,,,,315427.7317,79.05382063
66.85,11.14203,8.35044,0.00001,,,,,316251.8368,79.47064453
67.2,11.20062,8.41246,0.00001,,,,,318600.6878,79.88853832
67.55,11.2589,8.44402,0.00001,,,,,319795.9431,80.30422102
67.9,11.31719,8.45762,0.00001,,,,,320311.0088,80.71997505
68.25,11.37562,8.4998,0,,,,,321908.4698,81.13672763
68.6,11.43406,8.55991,0.00001,,,,,324184.9843,81.55355154
68.95,11.49219,8.58284,0,,,,,325053.4002,81.96816436
69.3,11.55062,8.63697,0.00001,,,,,327103.4373,82.38491695
69.65,11.60875,8.67896,0.00001,,,,,328693.7026,82.79952977
70,11.66703,8.70972,0.00001,,,,,329858.6599,83.21521248
70.35,11.72547,8.7566,0.00001,,,,,331634.1216,83.63203638
70.7,11.78375,8.79382,0,,,,,333043.7351,84.04771909
71.05,11.84187,8.83399,0,,,,,334565.0725,84.46226059
71.4,11.90031,8.88033,0.00001,,,,,336320.083,84.8790845
71.75,11.95859,8.92066,0.00001,,,,,337847.48,85.2947672
72.1,12.01672,8.93104,0.00001,,,,,338240.5963,85.70938003
72.45,12.075,8.98403,0,,,,,340247.4588,86.12506273
72.8,12.13328,9.0188,0.00001,,,,,341564.2847,86.54074544
73.15,12.19172,9.08693,0,,,,,344144.5365,86.95756934
73.5,12.25015,9.12542,0.00001,,,,,345602.2481,87.37432193
73.85,12.30844,9.16499,0,,,,,347100.862,87.79007595
74.2,12.36687,9.18764,0.00001,,,,,347958.6736,88.20682854
74.55,12.42515,9.22602,0,,,,,349412.2192,88.62251124
74.9,12.48375,9.28899,0.00001,,,,,351797.049,89.04047635
75.25,12.54203,9.30794,0.00001,,,,,352514.7324,89.45615905
75.6,12.60031,9.34065,0,,,,,353753.5411,89.87184176
75.95,12.65906,9.3939,0.00001,,,,,355770.2504,90.29087674
76.3,12.71734,9.42308,0,,,,,356875.3693,90.70655945
76.65,12.77547,9.46155,0.00002,,,,,358332.3234,91.12117227
77,12.83406,9.51207,0,,,,,360245.6409,91.53906606
77.35,12.89234,9.54844,0.00001,,,,,361623.0628,91.95474876
77.7,12.95047,9.59672,0,,,,,363451.546,92.36936159
78.05,13.00906,9.62037,0.00001,,,,,364347.23,92.78725537
78.4,13.06719,9.64467,0,,,,,365267.5312,93.2018682
78.75,13.12547,9.70205,0.00001,,,,,367440.6538,93.6175509
79.1,13.1839,9.75864,0,,,,,369583.8572,94.03430348
79.45,13.24203,9.79741,0,,,,,371052.1731,94.44891631
79.8,13.30015,9.84683,0.00001,,,,,372923.8309,94.86345782
80.15,13.35844,9.87275,0,,,,,373905.4854,95.27921184
80.5,13.41687,9.89165,0.00001,,,,,374621.2752,95.69596443
80.85,13.475,9.93548,0,,,,,376281.2259,96.11057725
81.2,13.53328,9.96398,0.00002,,,,,377360.5914,96.52625996
81.55,13.59187,10.02474,0,,,,,379661.723,96.94415374
81.9,13.65,10.06198,0.00001,,,,,381072.094,97.35876657
82.25,13.70828,10.11174,0.00001,,,,,382956.6284,97.77444927
82.6,13.76687,10.16312,0.00001,,,,,384902.5162,98.19234306
82.95,13.82516,10.20947,0.00002,,,,,386657.9055,98.60809709
83.3,13.88344,10.23225,0.00001,,,,,387520.6405,99.02377979
83.65,13.94219,10.28033,-0.00003,,,,,389341.5491,99.44281477
84,14.00031,10.3092,0.00005,,,,,390434.9275,99.85735628
84.35,14.05875,10.3994,-0.00002,,,,,393851.0248,100.2741802
84.7,14.11734,10.39335,0,,,,,393621.8964,100.692074
85.05,14.17547,10.46266,-0.00002,,,,,396246.8376,101.1066868
85.4,14.2339,10.47757,0,,,,,396811.5163,101.5234394
85.75,14.2925,10.49845,0,,,,,397602.2936,101.9414045
86.1,14.35078,10.53389,0,,,,,398944.4941,102.3570872
86.45,14.4089,10.58922,0.00002,,,,,401039.9782,102.7716287
86.8,14.46734,10.61972,-0.00001,,,,,402195.0887,103.1884526
87.15,14.52562,10.66508,0.00002,,,,,403912.9842,103.6041353
87.5,14.58375,10.70645,-0.00001,,,,,405479.7685,104.0187481
87.85,14.64187,10.72732,0.00002,,,,,406270.1671,104.4332896
88.2,14.70031,10.76979,0,,,,,407878.6111,104.8501135
88.55,14.75844,10.81286,0.00001,,,,,409509.7787,105.2647264
88.9,14.81687,10.8711,0,,,,,411715.4717,105.6814789
89.25,14.87531,10.91464,0.00001,,,,,413364.4393,106.0983029
89.6,14.93328,10.95984,0.00001,,,,,415076.2752,106.5117745
89.95,14.99172,10.99065,0,,,,,416243.1261,106.9285984
90.3,15.05015,11.0344,0.00002,,,,,417900.047,107.345351
90.65,15.10828,11.07099,0,,,,,419285.8009,107.7599638
91,15.16672,11.09059,0.00001,,,,,420028.1014,108.1767877
91.35,15.22531,11.12825,0.00001,,,,,421454.3788,108.5946815
91.7,15.28359,11.23142,0,,,,,425361.6821,109.0103642
92.05,15.34203,11.20871,0.00001,,,,,424501.5982,109.4271881
92.4,15.40047,11.25533,0.00002,,,,,426267.213,109.844012
92.75,15.45875,11.30595,-0.00001,,,,,428184.3178,110.2596947
93.1,15.51703,11.33314,0.00001,,,,,429214.0704,110.6753774
93.45,15.57562,11.35619,0.00001,,,,,430087.0309,111.0932712
93.8,15.6339,11.43088,0,,,,,432915.7262,111.5089539
94.15,15.69218,11.48771,0.00003,,,,,435068.019,111.9246366
94.5,15.75062,11.47774,0,,,,,434690.4304,112.3414605
94.85,15.80906,11.55053,0.00002,,,,,437447.1679,112.7582844
95.2,15.86734,11.59188,0.00001,,,,,439013.1948,113.1739671
95.55,15.92578,11.62421,0.00001,,,,,440237.6119,113.590791
95.9,15.9839,11.69514,0,,,,,442923.9066,114.0053325
96.25,16.04203,11.69666,0.00001,,,,,442981.4728,114.4199454
96.6,16.10047,11.78366,0,,,,,446276.3782,114.8367693
96.95,16.15875,11.77561,0.00001,,,,,445971.5047,115.252452
97.3,16.21687,11.82462,0.00001,,,,,447827.6348,115.6669935
97.65,16.27531,11.84355,0,,,,,448544.5608,116.0838174
98,16.33359,11.93758,0.00001,,,,,452105.7097,116.4995001
98.35,16.39171,11.93214,0,,,,,451899.6834,116.9140416
98.7,16.45,12.06791,0.00001,,,,,457041.6294,117.3297956
99.05,16.50828,12.0501,0.00003,,,,,456367.1206,117.7454783
99.4,16.56672,12.05626,0.00002,,,,,456600.4151,118.1623022
99.75,16.625,12.1125,0.00002,,,,,458730.3631,118.5779849
100.1,16.68344,12.14759,0.00003,,,,,460059.3083,118.9948088
100.45,16.74187,12.19241,0,,,,,461756.7527,119.4115614
100.8,16.80015,12.23642,0.00003,,,,,463423.5203,119.8272441
101.15,16.85875,12.27859,0,,,,,465020.6026,120.2452092
101.5,16.91687,12.31883,0.00001,,,,,466544.5911,120.6597507
101.85,16.97531,12.33565,0.00003,,,,,467181.6061,121.0765746
102.2,17.03406,12.42258,-0.00001,,,,,470473.8604,121.4956096
102.55,17.09234,12.46002,0.00003,,,,,471891.8059,121.9112923
102.9,17.15062,12.47052,0,,,,,472289.4669,122.326975
103.25,17.20922,12.52393,0.00003,,,,,474312.2358,122.7449401
103.6,17.26719,12.56583,-0.00001,,,,,475899.0926,123.1584118
103.95,17.32546,12.63595,0.00002,,,,,478554.7106,123.5740231
104.3,17.38406,12.66952,0,,,,,479826.0896,123.9919882
104.65,17.44218,12.71061,0.00001,,,,,481382.2696,124.4065297
105,17.50047,12.75392,0.00002,,,,,483022.5265,124.8222838
105.35,17.5589,12.75843,0.00007,,,,,483193.3314,125.2390364
105.7,17.61719,12.78797,0.0001,,,,,484312.0843,125.6547904
106.05,17.67515,12.87681,0.00011,,,,,487676.6751,126.0681907
106.4,17.73359,12.88282,0.00006,,,,,487904.2887,126.4850146
106.75,17.79203,12.96444,0.00001,,,,,490995.4402,126.9018385
107.1,17.85,13.00695,0,,,,,492605.3991,127.3153101
107.45,17.90843,13.05235,0.00001,,,,,494324.8095,127.7320627
107.8,17.96671,13.0736,0.00001,,,,,495129.5996,128.1477454
108.15,18.025,13.12192,0.00001,,,,,496959.5976,128.5634994
108.5,18.08344,13.20248,0.00002,,,,,500010.6043,128.9803233
108.85,18.14187,13.14909,0.00004,,,,,497988.5928,129.3970759
109.2,18.20015,13.21778,-0.00002,,,,,500590.0532,129.8127586
109.55,18.25843,13.2989,-0.00001,,,,,503662.2684,130.2284413
109.9,18.31703,13.24285,-0.00006,,,,,501539.5161,130.6464064
110.25,18.37531,13.33849,0.00003,,,,,505161.6397,131.0620892
110.6,18.43375,13.35386,-0.00001,,,,,505743.7397,131.4789131
110.95,18.4925,13.42708,0.00003,,,,,508516.7624,131.897948
111.3,18.55046,13.49922,0,,,,,511248.8828,132.3113483
111.65,18.6089,13.48982,-0.00001,,,,,510892.8815,132.7281722
112,18.6675,13.55498,0.00002,,,,,513360.652,133.1461374
112.35,18.72562,13.57792,0.00001,,,,,514229.4466,133.5606789
112.7,18.7839,13.62226,0,,,,,515908.7122,133.9763616
113.05,18.84234,13.7281,0.00002,,,,,519917.135,134.3931855
113.4,18.90062,13.7075,0,,,,,519136.962,134.8088682
113.75,18.95875,13.76572,0,,,,,521341.8976,135.223481
114.1,19.01703,13.79816,0.00001,,,,,522570.4807,135.6391637
114.45,19.07547,13.8572,0,,,,,524806.4716,136.0559876
114.8,19.13343,13.89749,0.00001,,,,,526332.3537,136.4693879
115.15,19.19187,13.91838,0,,,,,527123.5097,136.8862118
115.5,19.25015,13.96445,0.00001,,,,,528868.2947,137.3018945
115.85,19.30828,14.0056,0,,,,,530426.7471,137.7165074
116.2,19.36671,14.04228,0.00001,,,,,531815.9095,138.1332599
116.55,19.42515,14.10192,0.00001,,,,,534074.6239,138.5500838
116.9,19.48328,14.1468,0,,,,,535774.3406,138.9646967
117.25,19.54156,14.1778,0.00001,,,,,536948.3874,139.3803794
117.6,19.60031,14.20723,0,,,,,538062.9744,139.7994144
117.95,19.65844,14.25328,0.00001,,,,,539807.0019,140.2140272
118.3,19.71687,14.30348,0.00001,,,,,541708.2001,140.6307798
118.65,19.77531,14.34293,0.00001,,,,,543202.2693,141.0476037
119,19.83375,14.37561,0.00001,,,,,544439.9418,141.4644276
119.35,19.89203,14.4201,0,,,,,546124.8883,141.8801103
119.7,19.95062,14.46863,0.00001,,,,,547962.8395,142.2980041
120.05,20.0089,14.50897,0.00001,,,,,549490.6152,142.7136868
120.4,20.06718,14.56435,0.00001,,,,,551587.9929,143.1293695
120.75,20.12562,14.61133,0.00001,,,,,553367.2418,143.5461934
121.1,20.18406,14.65248,0.00001,,,,,554925.6942,143.9630173
121.45,20.24218,14.69165,0.00001,,,,,556409.1591,144.3775588
121.8,20.30078,14.7457,0,,,,,558456.1664,144.7955239
122.15,20.3589,14.8123,0.00001,,,,,560978.4733,145.2100654
122.5,20.41703,14.87598,0.00001,,,,,563390.1925,145.6246782
122.85,20.47547,14.91646,0.00001,,,,,564923.2704,146.0415021
123.2,20.53375,14.91951,0.00001,,,,,565038.7814,146.4571848
123.55,20.59187,14.9482,0.00001,,,,,566125.3427,146.8717263
123.9,20.65031,14.97462,0,,,,,567125.9336,147.2885502
124.25,20.70859,15.01521,0.00001,,,,,568663.1773,147.704233
124.6,20.76656,15.07476,0,,,,,570918.4833,148.1177046
124.95,20.825,15.11287,0.00001,,,,,572361.8033,148.5345285
125.3,20.88343,15.18538,0.00001,,,,,575107.9366,148.9512811
125.65,20.94172,15.21025,0.00001,,,,,576049.825,149.3670351
126,21.00015,15.25877,0,,,,,577887.3976,149.7837877
126.35,21.05844,15.30235,0.00001,,,,,579537.8801,150.1995417
126.7,21.11687,15.3289,0.00001,,,,,580543.3943,150.6162943
127.05,21.175,15.38475,0.00001,,,,,582658.5721,151.0309071
127.4,21.23359,15.40912,0,,,,,583581.5243,151.4488009
127.75,21.29203,15.44791,0,,,,,585050.5976,151.8656248
128.1,21.35031,15.48381,0.00001,,,,,586410.2195,152.2813075
128.45,21.40906,15.53197,0.00001,,,,,588234.1579,152.7003425
128.8,21.46734,15.57236,0,,,,,589763.8272,153.1160252
129.15,21.52547,15.62448,0.00001,,,,,591737.7407,153.530638
129.5,21.58422,15.67082,-0.00001,,,,,593492.7512,153.949673
129.85,21.64234,15.7272,0.00001,,,,,595628.0014,154.3642145
130.2,21.70062,15.75641,0,,,,,596734.2564,154.7798972
130.55,21.75906,15.80834,0.00001,,,,,598700.9741,155.1967211
130.9,21.81718,15.84429,0.00001,,,,,600062.4896,155.6112626
131.25,21.87547,15.90192,0,,,,,602245.0804,156.0270167
131.6,21.9339,15.9311,0,,,,,603350.1992,156.4437692
131.95,21.99203,15.99879,0.00001,,,,,605913.7871,156.8583821
132.3,22.05031,16.05068,0.00001,,,,,607878.9899,157.2740648
132.65,22.10859,16.06194,0.00001,,,,,608305.4339,157.6897475
133,22.16687,16.0983,0.00001,,,,,609682.4772,158.1054302
133.35,22.225,16.14471,0.00001,,,,,611440.1388,158.520043
133.7,22.28328,16.21702,0,,,,,614178.6975,158.9357257
134.05,22.34171,16.24867,0.00001,,,,,615377.3613,159.3524783
134.4,22.4,16.29852,0,,,,,617265.3043,159.7682323
134.75,22.45828,16.34734,0.00001,,,,,619114.2385,160.183915
135.1,22.51687,16.36922,0,,,,,619942.8883,160.6018088
135.45,22.575,16.43764,0,,,,,622534.1231,161.0164216
135.8,22.63343,16.46801,0,,,,,623684.3102,161.4331742
136.15,22.69203,16.53473,0,,,,,626211.1618,161.8511393
136.5,22.75031,16.5677,0,,,,,627459.8173,162.266822
136.85,22.8089,16.61402,0,,,,,629214.0704,162.6847158
137.2,22.86734,16.65998,0,,,,,630954.6894,163.1015397
137.55,22.92562,16.698,0,,,,,632394.6009,163.5172224
137.9,22.9839,16.75328,0.00001,,,,,634488.1914,163.9329051
138.25,23.0425,16.80419,0.00001,,,,,636416.2791,164.3508702
138.6,23.10062,16.82283,0.00001,,,,,637122.2221,164.7654117
138.95,23.1589,16.89342,0,,,,,639795.6401,165.1810944
139.3,23.21734,16.9274,0.00001,,,,,641082.5468,165.5979183
139.65,23.27578,16.99033,0,,,,,643465.8618,166.0147423
140,23.33375,17.02482,0,,,,,644772.0834,166.4282139
140.35,23.39203,17.0646,0,,,,,646278.6505,166.8438966
140.7,23.45047,17.10391,0,,,,,647767.4176,167.2607205
141.05,23.50859,17.176,0.00001,,,,,650497.6443,167.675262
141.4,23.56687,17.20305,0.00001,,,,,651522.0948,168.0909447
141.75,23.62531,17.24745,0,,,,,653203.6327,168.5077686
142.1,23.68328,17.29737,0.00001,,,,,655094.2267,168.9212402
142.45,23.74171,17.3425,0,,,,,656803.4116,169.3379928
142.8,23.80015,17.37362,0.00001,,,,,657982.003,169.7548167
143.15,23.85812,17.43106,0,,,,,660157.398,170.1682883
143.5,23.91672,17.47632,0,,,,,661871.5063,170.5862534
143.85,23.97515,17.51253,0,,,,,663242.8686,171.003006
144.2,24.03343,17.55152,0,,,,,664719.5164,171.4186887
144.55,24.09187,17.60777,0.00001,,,,,666849.8432,171.8355126
144.9,24.15047,17.64298,0.00001,,,,,668183.3331,172.2534777
145.25,24.20875,17.69302,0,,,,,670078.4718,172.6691605
145.6,24.26703,17.76547,0,,,,,672822.3326,173.0848432
145.95,24.32562,17.79068,0,,,,,673777.0978,173.5027369
146.3,24.3839,17.84087,0,,,,,675677.9173,173.9184196
146.65,24.44218,17.8853,0.00001,,,,,677360.5914,174.3341023
147,24.50062,17.95331,0,,,,,679936.2985,174.7509263
147.35,24.55906,17.97784,0,,,,,680865.3103,175.1677502
147.7,24.61718,18.0214,0,,,,,682515.0354,175.5822917
148.05,24.67578,18.07408,0,,,,,684510.1574,176.0002568
148.4,24.7339,18.11255,0.00001,,,,,685967.1115,176.4147983
148.75,24.79187,18.17445,0,,,,,688311.4178,176.8282699
149.1,24.85062,18.21694,0,,,,,689920.6193,177.2473049
149.45,24.90874,18.26391,0,,,,,691699.4895,177.6618464
149.8,24.96687,18.30517,0,,,,,693262.1078,178.0764592
150.15,25.02531,18.35385,0,,,,,695105.74,178.4932831
150.5,25.08343,18.41271,0,,,,,697334.9139,178.9078246
150.85,25.14172,18.45942,0,,,,,699103.9372,179.3235787
151.2,25.2,18.50661,0.00001,,,,,700891.1394,179.7392614
151.55,25.25843,18.54534,0,,,,,702357.9403,180.1560139
151.9,25.31672,18.58739,0.00001,,,,,703950.478,180.571768
152.25,25.375,18.6401,0,,,,,705946.7362,180.9874507
152.6,25.43343,18.69768,0,,,,,708127.4333,181.4042033
152.95,25.49187,18.72865,0,,,,,709300.3439,181.8210272
153.3,25.55015,18.78196,0,,,,,711319.3256,182.2367099
153.65,25.60875,18.82921,0,,,,,713108.8,182.654675
154,25.66703,18.87648,0,,,,,714899.032,183.0703577
154.35,25.72531,18.93056,0,,,,,716947.1755,183.4860404
154.7,25.78406,18.98644,0,,,,,719063.4894,183.9050754
155.05,25.84234,19.02346,0,,,,,720465.5285,184.3207581
155.4,25.90047,19.05462,0.00001,,,,,721645.6348,184.7353709
155.75,25.95906,19.11707,0,,,,,724010.7709,185.1532647
156.1,26.01734,19.17963,0,,,,,726380.073,185.5689474
156.45,26.07547,19.21554,0.00001,,,,,727740.0736,185.9835602
156.8,26.13406,19.26633,0,,,,,729663.6167,186.401454
157.15,26.19218,19.31458,0,,,,,731490.9636,186.8159955
157.5,26.25047,19.36082,0,,,,,733242.1869,187.2317495
157.85,26.3089,19.40545,0.00001,,,,,734932.4355,187.6485021
158.2,26.36703,19.46433,0.00001,,,,,737162.3669,188.0631149
158.55,26.42515,19.50206,0.00001,,,,,738591.2954,188.4776564
158.9,26.48359,19.5596,0,,,,,740770.4776,188.8944803
159.25,26.54187,19.60629,0,,,,,742538.7435,189.310163
159.6,26.6,19.64375,0,,,,,743957.4465,189.7247759
159.95,26.65828,19.69087,0,,,,,745741.9975,190.1404586
160.3,26.71671,19.73555,0.00001,,,,,747434.1398,190.5572112
160.65,26.775,19.79938,0,,,,,749851.5399,190.9729652
161,26.83328,19.82749,0.00001,,,,,750916.1352,191.3886479
161.35,26.89187,19.90877,0.00001,,,,,753994.41,191.8065417
161.7,26.95015,19.95313,0,,,,,755674.433,192.2222244
162.05,27.00859,19.99757,0.00001,,,,,757357.4859,192.6390483
162.4,27.06718,20.04852,0,,,,,759287.0885,193.0569421
162.75,27.12531,20.09901,0,,,,,761199.2698,193.4715549
163.1,27.1839,20.16253,0.00002,,,,,763604.9295,193.8894487
163.45,27.24234,20.19392,-0.00002,,,,,764793.7465,194.3062726
163.8,27.30047,20.22982,0.00001,,,,,766153.3684,194.7208854
164.15,27.3589,20.27934,-0.00001,,,,,768028.8134,195.137638
164.5,27.41734,20.31936,0,,,,,769544.4699,195.5544619
164.85,27.47562,20.39821,0,,,,,772530.7146,195.9701446
165.2,27.53406,20.44871,0,,,,,774443.2746,196.3869685
165.55,27.59234,20.49701,0,,,,,776272.5152,196.8026512
165.9,27.65062,20.5493,0.00001,,,,,778252.8669,197.2183339
166.25,27.70875,20.58019,0,,,,,779422.7477,197.6329468
166.6,27.76703,20.66069,0,,,,,782471.482,198.0486295
166.95,27.82531,20.6929,0,,,,,783691.3545,198.4643122
167.3,27.88359,20.7551,0,,,,,786047.0225,198.8799949
167.65,27.94187,20.78893,0,,,,,787328.2483,199.2956776
168,28.00031,20.8385,0.00001,,,,,789205.5869,199.7125015
168.35,28.05828,20.8997,0,,,,,791523.3825,200.1259731
168.7,28.11672,20.93232,0,,,,,792758.7826,200.542797
169.05,28.17515,20.98635,0,,,,,794805.0325,200.9595496
169.4,28.23312,21.04348,0,,,,,796968.687,201.3730212
169.75,28.29172,21.0978,0.00001,,,,,799025.9199,201.7909863
170.1,28.35031,21.139,0,,,,,800586.2659,202.2088801
170.45,28.40859,21.1914,0,,,,,802570.7837,202.6245628
170.8,28.46687,21.24278,0,,,,,804516.6715,203.0402455
171.15,28.52531,21.29993,0,,,,,806681.0835,203.4570694
171.5,28.58375,21.35973,0,,,,,808945.8575,203.8738933
171.85,28.64203,21.40635,0,,,,,810711.4723,204.289576
172.2,28.70047,21.46382,0,,,,,812888.0035,204.7063999
172.55,28.7589,21.49689,0,,,,,814140.4463,205.1231525
172.9,28.81718,21.54447,0,,,,,815942.4187,205.5388352
173.25,28.87578,21.63363,0,,,,,819319.1286,205.9568003
173.6,28.93406,21.66019,0,,,,,820325.0216,206.372483
173.95,28.99218,21.69585,0,,,,,821675.5541,206.7870245
174.3,29.05062,21.78289,0,,,,,824971.9744,207.2038484
174.65,29.1089,21.80123,0,,,,,825666.5556,207.6195311
175,29.16703,21.85312,0,,,,,827631.7583,208.034144
175.35,29.22547,21.92578,0.00001,,,,,830383.5724,208.4509679
175.7,29.28375,21.96424,0,,,,,831840.1479,208.8666506
176.05,29.34187,22.02719,0,,,,,834224.2202,209.2811921
176.4,29.40031,22.06865,0,,,,,835794.4131,209.698016
176.75,29.45859,22.14779,0,,,,,838791.6408,210.1136987
177.1,29.51672,22.19804,0,,,,,840694.7327,210.5283115
177.45,29.575,22.24295,0,,,,,842395.5856,210.9439942
177.8,29.63328,22.29186,0,,,,,844247.9284,211.3596769
178.15,29.69172,22.33075,0,,,,,845720.789,211.7765008
178.5,29.75015,22.40551,0.00001,,,,,848552.1353,212.1932534
178.85,29.80843,22.43141,0.00001,,,,,849533.0324,212.6089361
179.2,29.86687,22.49532,0,,,,,851953.4623,213.02576
179.55,29.92515,22.552,0,,,,,854100.0742,213.4414427
179.9,29.98375,22.59199,0,,,,,855614.5945,213.8594078
180.25,30.04203,22.6386,0,,,,,857379.8306,214.2750906
180.6,30.10046,22.69564,0,,,,,859540.0767,214.6918431
180.95,30.15906,22.75142,0,,,,,861652.6034,215.1098082
181.3,30.21734,22.79639,0,,,,,863355.7286,215.5254909
181.65,30.27547,22.85817,0,,,,,865695.4901,215.9401038
182,30.33406,22.88099,0,,,,,866559.74,216.3579976
182.35,30.39234,22.95124,0,,,,,869220.2815,216.7736803
182.7,30.45046,23.01491,0,,,,,871631.622,217.1882218
183.05,30.50906,23.07614,-0.00001,,,,,873950.5537,217.6061869
183.4,30.56718,23.09767,0,,,,,874765.9481,218.0207284
183.75,30.62531,23.17848,0,,,,,877826.4229,218.4353412
184.1,30.6839,23.23223,0,,,,,879862.0684,218.853235
184.45,30.74218,23.3093,0.00001,,,,,882780.9002,219.2689177
184.8,30.80015,23.34495,0,,,,,884131.0539,219.6823893
185.15,30.85859,23.42272,0,,,,,887076.3964,220.0992132
185.5,30.91687,23.48453,-0.00002,,,,,889417.2941,220.5148959
185.85,30.975,23.53475,0.00002,,,,,891319.2498,220.9295088
186.2,31.03343,23.5738,0,,,,,892798.17,221.3462613
186.55,31.09171,23.62804,0.00001,,,,,894852.3731,221.761944
186.9,31.15,23.67653,0,,,,,896688.8094,222.1776981
187.25,31.20843,23.72544,0,,,,,898541.1522,222.5944506
187.6,31.26687,23.8076,0,,,,,901652.7548,223.0112746
187.95,31.32515,23.83443,0,,,,,902668.8734,223.4269573
188.3,31.38343,23.89759,0,,,,,905060.8989,223.84264
188.65,31.44218,23.96305,0,,,,,907540.0312,224.2616749
189,31.50031,24.00246,0,,,,,909032.5855,224.6762878
189.35,31.55874,24.07178,0,,,,,911657.9055,225.0930404
189.7,31.61734,24.12671,0,,,,,913738.2406,225.5110055
190.05,31.67562,24.19814,0,,,,,916443.4715,225.9266882
190.4,31.7339,24.2374,0,,,,,917930.3449,226.3423709
190.75,31.7925,24.29449,0,,,,,920092.4846,226.760336
191.1,31.85062,24.35433,0,,,,,922358.7735,227.1748775
191.45,31.9089,24.40882,0,,,,,924422.4447,227.5905602
191.8,31.96734,24.47027,0,,,,,926749.7084,228.0073841
192.15,32.02562,24.50886,0,,,,,928211.2072,228.4230668
192.5,32.08374,24.57763,0,,,,,930815.6974,228.8376083
192.85,32.14202,24.61773,0,,,,,932334.3837,229.253291
193.2,32.20031,24.7021,0,,,,,935529.6844,229.669045
193.55,32.25843,24.73937,0,,,,,936941.1916,230.0835865
193.9,32.31687,24.79674,0,,,,,939113.9356,230.5004104
194.25,32.37531,24.844,0,,,,,940903.7888,230.9172343
194.6,32.43327,24.90757,0,,,,,943311.342,231.3306347
194.95,32.49171,24.9637,0,,,,,945437.1241,231.7474586
195.3,32.55015,25.03672,0,,,,,948202.5723,232.1642825
195.65,32.60812,25.07853,0,,,,,949786.0205,232.5777541
196,32.66671,25.14569,0,,,,,952329.536,232.9956479
196.35,32.72515,25.20192,0,,,,,954459.1053,233.4124718
196.7,32.78359,25.25537,0,,,,,956483.3891,233.8292957
197.05,32.84187,25.30939,0,,,,,958529.2603,234.2449784
197.4,32.90031,25.39598,0,,,,,961808.638,234.6618023
197.75,32.95874,25.447,0,,,,,963740.8917,235.0785549
198.1,33.01702,25.48293,0,,,,,965101.6497,235.4942376
198.45,33.07546,25.55423,0,,,,,967801.9572,235.9110615
198.8,33.1339,25.58802,0,,,,,969081.6682,236.3278854
199.15,33.19218,25.66308,0,,,,,971924.3762,236.7435681
199.5,33.25077,25.71725,0,,,,,973975.9283,237.1614619
199.85,33.30906,25.76778,0,,,,,975889.6245,237.5772159
200.2,33.36718,25.84186,0,,,,,978695.2175,237.9917574
200.55,33.42577,25.90118,0,,,,,980941.8127,238.4096512
200.9,33.4839,25.96056,0,,,,,983190.6803,238.824264
201.25,33.54203,26.00176,0,,,,,984751.0263,239.2388769
201.6,33.60046,26.08237,0,,,,,987803.9266,239.6556294
201.95,33.65874,26.1483,0,,,,,990300.8589,240.0713121
202.3,33.71687,26.18551,0,,,,,991710.0938,240.485925
202.65,33.77546,26.25121,0,,,,,994198.3154,240.9038187
203,33.83358,26.30531,0,,,,,996247.2164,241.3183602
203.35,33.89156,26.36022,0,,,,,998326.794,241.7319032
203.7,33.94999,26.43764,0,,,,,1001258.881,242.1486558
204.05,34.00843,26.49639,0,,,,,1003483.889,242.5654797
204.4,34.06671,26.56556,0,,,,,1006103.528,242.9811624
204.75,34.12515,26.61053,0,,,,,1007806.653,243.3979863
205.1,34.18343,26.66766,0,,,,,1009970.308,243.813669
205.45,34.24187,26.73239,0,,,,,1012421.793,244.2304929
205.8,34.30015,26.77777,0,,,,,1014140.446,244.6461756
206.15,34.35859,26.85816,0,,,,,1017185.015,245.0629995
206.5,34.41703,26.91306,0,,,,,1019264.214,245.4798234
206.85,34.4753,26.99051,0,,,,,1022197.437,245.8954348
207.2,34.53406,27.02537,0,,,,,1023517.671,246.3145411
207.55,34.59234,27.07637,0,,,,,1025449.168,246.7302238
207.9,34.65046,27.16107,0,,,,,1028656.966,247.1447653
208.25,34.70921,27.18759,0,,,,,1029661.344,247.5638003
208.6,34.76734,27.26895,0,,,,,1032742.649,247.9784131
208.95,34.82546,27.34443,0,,,,,1035601.263,248.3929546
209.3,34.88406,27.38743,0,,,,,1037229.78,248.8109197
209.65,34.94218,27.45614,0,,,,,1039831.998,249.2254612
210,35.00046,27.52139,0,,,,,1042303.177,249.641144
210.35,35.05874,27.59367,0,,,,,1045040.599,250.0568267
210.7,35.11703,27.63597,0,,,,,1046642.605,250.4725807
211.05,35.17515,27.68958,0,,,,,1048672.948,250.8871222
211.4,35.23359,27.75659,0,,,,,1051210.783,251.3039461
211.75,35.29187,27.81387,0,,,,,1053380.118,251.7196288
212.1,35.34999,27.91392,0,,,,,1057169.26,252.1341703
212.45,35.40827,27.95565,0,,,,,1058749.678,252.549853
212.8,35.46671,28.00064,0,,,,,1060453.561,252.9666769
213.15,35.52499,28.06182,0,,,,,1062770.599,253.3823596
213.5,35.58327,28.14233,0,,,,,1065819.712,253.7980423
213.85,35.64187,28.19999,0,,,,,1068003.439,254.2160074
214.2,35.70015,28.26613,0,,,,,1070508.324,254.6316901
214.55,35.75843,28.33081,0,,,,,1072957.916,255.0473728
214.9,35.81718,28.38266,0,,,,,1074921.604,255.4664078
215.25,35.87531,28.44333,0,,,,,1077219.327,255.8810206
215.6,35.93374,28.50971,0,,,,,1079733.302,256.2977732
215.95,35.99249,28.55256,0,,,,,1081356.138,256.7168082
216.3,36.05046,28.63949,0,,,,,1084648.392,257.1302798
216.65,36.1089,28.68542,0,,,,,1086387.875,257.5471037
217,36.1675,28.74862,0,,,,,1088781.415,257.9650689
217.35,36.22562,28.80729,0,,,,,1091003.393,258.3796104
217.7,36.28405,28.89396,0,,,,,1094285.801,258.7963629
218.05,36.34234,28.95696,0,,,,,1096671.767,259.212117
218.4,36.40062,29.01578,0,,,,,1098899.426,259.6277997
218.75,36.45874,29.09518,0,,,,,1101906.5,260.0423412
219.1,36.51702,29.15512,0,,,,,1104176.577,260.4580239
219.45,36.57531,29.22177,0,,,,,1106700.777,260.8737779
219.8,36.63359,29.28588,0,,,,,1109128.782,261.2894606
220.15,36.69187,29.32562,0,,,,,1110633.834,261.7051433
220.5,36.75031,29.39128,0,,,,,1113120.541,262.1219672
220.85,36.80827,29.47396,0,,,,,1116251.837,262.5353675
221.2,36.86671,29.5432,0,,,,,1118874.127,262.9521914
221.55,36.92515,29.59919,0,,,,,1120994.607,263.3690153
221.9,36.98312,29.66267,0,,,,,1123398.752,263.782487
222.25,37.04171,29.74321,0,,,,,1126449.001,264.2003807
222.6,37.10031,29.80272,0,,,,,1128702.792,264.6183459
222.95,37.15843,29.85814,0,,,,,1130801.685,265.0328874
223.3,37.21703,29.91897,0,,,,,1133105.467,265.4508525
223.65,37.27531,29.99742,0,,,,,1136076.563,265.8665352
224,37.33359,30.05958,0,,,,,1138430.716,266.2822179
224.35,37.39202,30.12455,0,,,,,1140891.291,266.6989705
224.7,37.45062,30.19378,0,,,,,1143513.202,267.1169356
225.05,37.5089,30.24723,0,,,,,1145537.486,267.5326183
225.4,37.56718,30.31021,0,,,,,1147922.695,267.948301
225.75,37.62562,30.37278,0,,,,,1150292.376,268.3651249
226.1,37.68406,30.44562,0,,,,,1153051.007,268.7819488
226.45,37.74218,30.54037,0,,,,,1156639.424,269.1964903
226.8,37.80077,30.57288,0,,,,,1157870.658,269.6143841
227.15,37.8589,30.65493,0,,,,,1160978.095,270.0289969
227.5,37.91703,30.70642,0,,,,,1162928.148,270.4436097
227.85,37.97546,30.77279,0,,,,,1165441.745,270.8603623
228.2,38.03374,30.83448,0,,,,,1167778.098,271.276045
228.55,38.09187,30.91667,0,,,,,1170890.836,271.6906578
228.9,38.15031,30.98058,0,,,,,1173311.266,272.1074817
229.25,38.20859,31.0468,0,,,,,1175819.182,272.5231644
229.6,38.26656,31.12021,0,,,,,1178599.4,272.9366361
229.95,38.32499,31.19338,0,,,,,1181370.529,273.3533887
230.3,38.38327,31.25434,0,,,,,1183679.235,273.7690714
230.65,38.44172,31.33011,0,,,,,1186548.833,274.1859666
231,38.50015,31.37378,0,,,,,1188202.724,274.6027192
231.35,38.55843,31.44831,0,,,,,1191025.359,275.0184019
231.7,38.61687,31.51922,0,,,,,1193710.897,275.4352258
232.05,38.67515,31.59854,0,,,,,1196714.941,275.8509085
232.4,38.73359,31.64433,0,,,,,1198449.122,276.2677324
232.75,38.79203,31.73549,0,,,,,1201901.577,276.6845563
233.1,38.85031,31.80317,0,,,,,1204464.786,277.100239
233.45,38.90905,31.87028,0,,,,,1207006.408,277.5192027
233.8,38.96734,31.95474,0,,,,,1210205.117,277.9349567
234.15,39.02546,32.00454,0,,,,,1212091.167,278.3494982
234.5,39.08405,32.09639,0,,,,,1215569.754,278.767392
234.85,39.14218,32.13917,0,,,,,1217189.938,279.1820048
235.2,39.20046,32.21931,0,,,,,1220225.038,279.5976875
235.55,39.2589,32.2877,0,,,,,1222815.137,280.0145114
235.9,39.31718,32.34656,0,,,,,1225044.311,280.4301941
236.25,39.37546,32.42673,0,,,,,1228080.547,280.8458768
236.6,39.4339,32.4939,0,,,,,1230624.441,281.2627007
236.95,39.49203,32.57714,0,,,,,1233776.946,281.6773136
237.3,39.55015,32.63801,0,,,,,1236082.244,282.0918551
237.65,39.60843,32.70643,0,,,,,1238673.479,282.5075378
238,39.66687,32.77615,0,,,,,1241313.948,282.9243617
238.35,39.72499,32.85868,0,,,,,1244439.563,283.3389032
238.7,39.78343,32.92677,0,,,,,1247018.3,283.7557271
239.05,39.84187,33.00157,0,,,,,1249851.161,284.172551
239.4,39.90015,33.05098,0,,,,,1251722.44,284.5882337
239.75,39.95827,33.14546,0,,,,,1255300.632,285.0027752
240.1,40.01687,33.19712,0,,,,,1257257.124,285.4207403
240.45,40.07499,33.27882,0,,,,,1260351.305,285.8352818
240.8,40.13343,33.35445,0,,,,,1263215.6,286.2521057
241.15,40.19218,33.40142,0,,,,,1264994.471,286.6711407
241.5,40.25031,33.49543,0,,,,,1268554.862,287.0857535
241.85,40.3089,33.56593,0,,,,,1271224.872,287.5036473
242.2,40.36734,33.63661,0,,,,,1273901.698,287.9204712
242.55,40.42546,33.71456,0,,,,,1276853.858,288.3350127
242.9,40.4839,33.75906,0,,,,,1278539.183,288.7518366
243.25,40.54234,33.83637,0,,,,,1281467.104,289.1686605
243.6,40.60062,33.92826,0,,,,,1284947.206,289.5843432
243.95,40.65905,33.99384,0,,,,,1287430.883,290.0010958
244.3,40.71734,34.07682,0,,,,,1290573.541,290.4168498
244.65,40.77562,34.15262,0,,,,,1293444.274,290.8325325
245,40.83374,34.2202,0,,,,,1296003.696,291.247074
245.35,40.89202,34.29668,0,,,,,1298900.183,291.6627568
245.7,40.95031,34.36712,0,,,,,1301567.92,292.0785108
246.05,41.00859,34.4327,0,,,,,1304051.597,292.4941935
246.4,41.06687,34.53326,0,,,,,1307860.054,292.9098762
246.75,41.12531,34.58165,-0.00001,,,,,1309692.703,293.3267001
247.1,41.18327,34.66091,0,,,,,1312694.475,293.7401004
247.45,41.24171,34.75013,0,,,,,1316073.457,294.1569243
247.8,41.30015,34.79532,0,,,,,1317784.915,294.5737482
248.15,41.35827,34.88354,0,,,,,1321126.024,294.9882897
248.5,41.41671,34.96577,0,,,,,1324240.278,295.4051136
248.85,41.47531,35.03933,0,,,,,1327026.177,295.8230787
249.2,41.53343,35.10003,0,,,,,1329325.037,296.2376202
249.55,41.59187,35.16008,0,,,,,1331599.279,296.6544441
249.9,41.65031,35.26209,0,,,,,1335462.65,297.071268
250.25,41.70874,35.3219,0,,,,,1337727.803,297.4880206
250.6,41.76702,35.41155,0,,,,,1341123.07,297.9037033
250.95,41.82546,35.49408,0,,,,,1344248.686,298.3205272
251.3,41.8839,35.56583,0.00001,,,,,1346966.036,298.7373511
251.65,41.94218,35.65514,0,,,,,1350348.427,299.1530338
252,42.00077,35.72339,0,,,,,1352933.223,299.5709276
252.35,42.05906,35.7608,0,,,,,1354350.033,299.9866817
252.7,42.11718,35.86958,0,,,,,1358469.8,300.4012232
253.05,42.17577,35.93116,0,,,,,1360801.988,300.8191169
253.4,42.2339,36.00199,0,,,,,1363484.495,301.2337298
253.75,42.29203,36.09494,0,,,,,1367004.742,301.6483426
254.1,42.35046,36.16002,0,,,,,1369469.482,302.0650952
254.45,42.40874,36.23694,0,,,,,1372382.633,302.4807779
254.8,42.46687,36.33177,0,,,,,1375974.08,302.8953907
255.15,42.52531,36.37354,0,,,,,1377556.013,303.3122146
255.5,42.58359,36.45626,0,,,,,1380688.825,303.7278973
255.85,42.64171,36.54701,0,,,,,1384125.752,304.1424388
256.2,42.69999,36.60569,-0.00001,,,,,1386348.109,304.5581215
256.55,42.75843,36.70287,0,,,,,1390028.556,304.9749454
256.9,42.81672,36.78792,-0.00001,,,,,1393249.61,305.3906995
257.25,42.87531,36.85812,0,,,,,1395908.258,305.8085932
257.6,42.93359,36.92709,0,,,,,1398520.322,306.224276
257.95,42.99187,37.00393,0,,,,,1401430.443,306.6399587
258.3,43.05015,37.12168,0,,,,,1405889.927,307.0556414
258.65,43.10859,37.1797,-0.00001,,,,,1408087.288,307.4724653
259,43.16703,37.24992,-0.00001,,,,,1410746.694,307.8892892
259.35,43.22531,37.30996,-0.00001,,,,,1413020.557,308.3049719
259.7,43.28405,37.39094,0,,,,,1416087.47,308.7239355
260.05,43.34234,37.48392,0,,,,,1419608.853,309.1396896
260.4,43.40046,37.53139,0,,,,,1421406.659,309.5542311
260.75,43.45905,37.65339,-0.00001,,,,,1426027.102,309.9721249
261.1,43.51734,37.71019,-0.00001,,,,,1428178.258,310.3878789
261.45,43.57546,37.79902,0,,,,,1431542.47,310.8024204
261.8,43.63406,37.88252,0,,,,,1434704.822,311.2203855
262.15,43.69218,37.97116,0.00001,,,,,1438061.838,311.634927
262.5,43.75031,38.04943,0.00001,,,,,1441026.117,312.0495398
262.85,43.8089,38.14544,-0.00002,,,,,1444662.253,312.4674336
263.2,43.86703,38.22496,0.00001,,,,,1447673.873,312.8820464
263.55,43.92515,38.28671,0,,,,,1450012.498,313.2965879
263.9,43.98343,38.3689,0,,,,,1453125.237,313.7122706
264.25,44.04187,38.44928,0,,,,,1456169.426,314.1290945
264.6,44.09999,38.53467,-0.00001,,,,,1459403.357,314.5436361
264.95,44.15828,38.6217,0,,,,,1462699.399,314.9593901
265.3,44.21671,38.69022,0,,,,,1465294.421,315.3761427
265.65,44.27515,38.79261,0,,,,,1469172.183,315.7929666
266,44.33327,38.85,0,,,,,1471345.685,316.2075081
266.35,44.39187,38.94538,0,,,,,1474957.962,316.6254732
266.7,44.45015,39.02732,0,,,,,1478061.232,317.0411559
267.05,44.50843,39.09246,0,,,,,1480528.245,317.4568386
267.4,44.56718,39.21085,0,,,,,1485011.968,317.8758736
267.75,44.62531,39.26285,0,,,,,1486981.336,318.2904864
268.1,44.68374,39.34845,0,,,,,1490223.22,318.707239
268.45,44.7425,39.43974,0,,,,,1493680.599,319.1263453
268.8,44.80046,39.51639,0,,,,,1496583.524,319.5397456
269.15,44.8589,39.6075,-0.00001,,,,,1500034.085,319.9565695
269.5,44.9175,39.68317,-0.00001,,,,,1502899.895,320.3745346
269.85,44.97562,39.75037,0,,,,,1505444.926,320.7890761
270.2,45.0339,39.85594,-0.00001,,,,,1509443.123,321.2047588
270.55,45.09234,39.92813,0,,,,,1512177.137,321.6215827
270.9,45.15062,40.03342,0,,,,,1516164.73,322.0372654
271.25,45.20874,40.11499,0,,,,,1519253.988,322.4518069
271.6,45.26702,40.21711,0,,,,,1523121.525,322.8674896
271.95,45.32531,40.27317,0,,,,,1525244.656,323.2832437
272.3,45.38359,40.36451,0,,,,,1528703.928,323.6989264
272.65,45.44187,40.4385,0,,,,,1531506.113,324.1146091
273,45.50031,40.53465,0,,,,,1535147.551,324.531433
273.35,45.55827,40.62298,0,,,,,1538492.827,324.9448333
273.7,45.61671,40.68568,-0.00001,,,,,1540867.431,325.3616572
274.05,45.67515,40.79492,0,,,,,1545004.62,325.7784811
274.4,45.73327,40.84642,-0.00001,,,,,1546955.053,326.1930226
274.75,45.79171,40.91989,-0.00002,,,,,1549737.544,326.6098465
275.1,45.85015,41.03141,-0.00002,,,,,1553961.082,327.0266704
275.45,45.90843,41.11569,0,,,,,1557152.975,327.4423531
275.8,45.96687,41.18271,0,,,,,1559691.188,327.859177
276.15,46.02531,41.30353,0,,,,,1564266.94,328.2760009
276.5,46.08374,41.38882,-0.00001,,,,,1567497.084,328.6927535
276.85,46.14202,41.46856,-0.00001,,,,,1570517.035,329.1084362
277.2,46.20046,41.56145,0,,,,,1574035.009,329.5252601
277.55,46.2589,41.63373,0,,,,,1576772.432,329.942084
277.6,46.26702,41.64433,0,,,,,1577173.88,330