File: .gitbook/assets/mane.6962.experimental.session.specimen_rawdata_a (2).csv
Crosshead speed,10,mm/min,,,,,,,
Tensile strain,25.4,mm,,,,,Area,2.16354E-05,
,,,,,,,,,
Time,Extension,Load,Strain from Extensometer,,,,,,
(s),(mm),(N),(mm/mm),,,,,Stress,Strain
0,0,0.00176,0,,,,,81.34816088,0
0.35,0.05891,0.0124,0,,,,,573.1347699,1.050067066
0.7,0.11719,0.02475,0,,,,,1143.958512,2.088904422
1.05,0.17562,0.06154,0.00001,,,,,2844.412398,3.130415518
1.4,0.23422,0.06435,0.00001,,,,,2974.292132,4.174956854
1.75,0.2925,0.05827,-0.00001,,,,,2693.271213,5.21379421
2.1,0.35062,0.07714,0,,,,,3565.452915,6.249779576
2.45,0.40906,0.08996,-0.00001,,,,,4158.000314,7.291468921
2.8,0.46719,0.13571,0,,,,,6272.590292,8.327632536
3.15,0.52531,0.32042,0.00022,,,,,14809.98734,9.363617902
3.5,0.58375,0.12476,-0.00005,,,,,5766.475314,10.40530725
3.85,0.64219,0.1732,-0.00007,,,,,8005.39856,11.44699659
4.2,0.70016,0.15323,0,,,,,7082.374257,12.48030822
4.55,0.75875,0.21212,-0.00007,,,,,9804.302208,13.5246713
4.9,0.81687,0.19899,0.00005,,,,,9197.42644,14.56065667
5.25,0.875,0.22373,-0.00004,,,,,10340.92275,15.59682029
5.6,0.93344,0.24391,0.00006,,,,,11273.65336,16.63850963
5.95,0.99172,0.27561,-0.00001,,,,,12738.84467,17.67734699
6.3,1.05,0.30057,0.00002,,,,,13892.5095,18.71618434
6.65,1.10859,0.26981,0,,,,,12470.7655,19.76054743
7,1.16687,0.28535,0.00002,,,,,13189.03279,20.79938479
7.35,1.22531,0.29318,0,,,,,13550.93966,21.84107413
7.7,1.28375,0.33061,0.00001,,,,,15280.9747,22.88276348
8.05,1.34219,0.34815,0,,,,,16091.68307,23.92445282
8.4,1.40047,0.36705,0.00001,,,,,16965.25139,24.96329018
8.75,1.45891,0.35326,-0.00002,,,,,16327.87006,26.00497952
9.1,1.51766,0.38839,0.00002,,,,,17951.59784,27.0521946
9.45,1.57578,0.37307,-0.00001,,,,,17243.49908,28.08817997
9.8,1.63406,0.40754,0.00002,,,,,18836.7213,29.12701732
10.15,1.69281,0.4187,0,,,,,19352.54259,30.1742324
10.5,1.75078,0.40322,0.00001,,,,,18637.04854,31.20754402
10.85,1.80891,0.45975,-0.00001,,,,,21249.896,32.24370764
11.2,1.8675,0.4583,0.00001,,,,,21182.87621,33.28807072
11.55,1.92547,0.47289,0.00001,,,,,21857.23398,34.32138235
11.9,1.98375,0.50097,0.00001,,,,,23155.10691,35.36021971
12.25,2.04219,0.49354,0.00001,,,,,22811.68825,36.40190905
12.6,2.10047,0.49587,0,,,,,22919.38212,37.44074641
12.95,2.15859,0.5181,0.00001,,,,,23946.86486,38.47673177
13.3,2.21687,0.52315,0.00001,,,,,24180.27862,39.51556913
13.65,2.27531,0.55893,0,,,,,25834.04975,40.55725847
14,2.33328,0.578,-0.00001,,,,,26715.47556,41.5905701
14.35,2.39187,0.56754,0,,,,,26232.00865,42.63493319
14.7,2.45016,0.57756,0,,,,,26695.13852,43.67394879
15.05,2.50844,0.62368,0.00001,,,,,28826.8301,44.71278615
15.4,2.56687,0.60761,0,,,,,28084.06593,45.75429724
15.75,2.62531,0.62983,0,,,,,29111.08646,46.79598659
16.1,2.68359,0.62823,0,,,,,29037.13359,47.83482394
16.45,2.74203,0.61706,-0.00001,,,,,28520.85009,48.87651329
16.8,2.80062,0.734,0.00005,,,,,33925.88073,49.92087638
17.15,2.85891,0.66718,0.00004,,,,,30837.42385,50.95989198
17.5,2.91734,0.6772,0,,,,,31300.55372,52.00140308
17.85,2.97578,0.69536,0.00003,,,,,32139.91884,53.04309242
18.2,3.03391,0.70982,0.00001,,,,,32808.26793,54.07925604
18.55,3.0925,0.71627,0.00001,,,,,33106.39045,55.12361912
18.9,3.15094,0.76008,0,,,,,35131.31257,56.16530847
19.25,3.20906,0.72525,-0.00001,,,,,33521.45096,57.20129384
19.6,3.26734,0.75919,0.00001,,,,,35090.17629,58.24013119
19.95,3.32578,0.75472,0.00002,,,,,34883.57044,59.28182054
20.3,3.38391,0.82005,0.00001,,,,,37903.15871,60.31798415
20.65,3.44219,0.82208,-0.00001,,,,,37996.98642,61.35682151
21,3.50031,0.82545,0.00001,,,,,38152.74966,62.39280687
21.35,3.55875,0.80801,-0.00001,,,,,37346.66334,63.43449622
21.7,3.61687,0.80599,0.00001,,,,,37253.29784,64.47048159
22.05,3.67531,0.90025,0,,,,,41610.0465,65.51217093
22.4,3.73359,0.87433,0.00003,,,,,40412.00995,66.55100829
22.75,3.79172,0.89952,0,,,,,41576.3055,67.5871719
23.1,3.85031,0.89586,0.00002,,,,,41407.1383,68.63153499
23.45,3.90859,0.97711,0.00001,,,,,45162.55766,69.67037234
23.8,3.96672,0.93853,0.00001,,,,,43379.369,70.70653596
24.15,4.02516,0.94646,-0.00001,,,,,43745.89793,71.7482253
24.5,4.08375,0.95101,0.00001,,,,,43956.20141,72.79258839
24.85,4.14203,0.96035,0.00001,,,,,44387.90131,73.83142575
25.2,4.20062,0.97693,0.00001,,,,,45154.23796,74.87578883
25.55,4.25891,0.99156,0.00001,,,,,45830.44455,75.91480444
25.9,4.31719,1.0077,0.00001,,,,,46576.44416,76.95364179
26.25,4.37547,0.98438,0,,,,,45498.58103,77.99247915
26.6,4.43406,1.03544,0,,,,,47858.60211,79.03684224
26.95,4.4925,1.03339,0.00003,,,,,47763.84999,80.07853158
27.3,4.55078,1.02736,0,,,,,47485.14009,81.11736894
27.65,4.60922,1.07722,0,,,,,49789.69652,82.15905828
28,4.6675,1.06635,0.00001,,,,,49287.27918,83.19789564
28.35,4.72562,1.0848,0.00001,,,,,50140.04825,84.233881
28.7,4.78406,1.08581,0.00001,,,,,50186.73101,85.27557035
29.05,4.84219,1.11331,0.00001,,,,,51457.79602,86.31173397
29.4,4.90031,1.13271,0,,,,,52354.47461,87.34771933
29.75,4.95891,1.13554,0.00001,,,,,52485.27876,88.39226067
30.1,5.01719,1.14416,0,,,,,52883.69986,89.43109802
30.45,5.07516,1.14295,0.00001,,,,,52827.773,90.46440965
30.8,5.13375,1.17037,0.00001,,,,,54095.14037,91.50877273
31.15,5.19203,1.18374,0,,,,,54713.10907,92.54761009
31.5,5.25,1.20874,0,,,,,55868.62272,93.58092171
31.85,5.30859,1.19742,0.00001,,,,,55345.40614,94.6252848
32.2,5.36672,1.22205,-0.00001,,,,,56483.81819,95.66144842
32.55,5.42516,1.24345,0.00001,,,,,57472.93787,96.70313776
32.9,5.48375,1.23106,0,,,,,56900.26531,97.74750085
33.25,5.54203,1.24327,0.00002,,,,,57464.61817,98.7863382
33.6,5.60047,1.26757,0,,,,,58587.77744,99.82802755
33.95,5.65875,1.29862,0.00001,,,,,60022.92539,100.8668649
34.3,5.71719,1.29153,0.00001,,,,,59695.22172,101.9085543
34.65,5.77547,1.3107,-0.00001,,,,,60581.26959,102.9473916
35,5.83375,1.30097,0.00001,,,,,60131.54367,103.986229
35.35,5.89266,1.30214,0,,,,,60185.62171,105.036296
35.7,5.95094,1.31776,0.00001,,,,,60907.58664,106.0751334
36.05,6.00906,1.32282,0.00001,,,,,61141.4626,107.1111188
36.4,6.06766,1.33251,-0.00001,,,,,61589.33969,108.1556601
36.75,6.12578,1.38264,0.00001,,,,,63906.37566,109.1916455
37.1,6.18391,1.3784,0.00001,,,,,63710.40055,110.2278091
37.45,6.2425,1.37824,0.00001,,,,,63703.00526,111.2721722
37.8,6.30062,1.43898,0.00001,,,,,66510.44122,112.3081575
38.15,6.35875,1.39216,-0.00002,,,,,64346.39526,113.3443211
38.5,6.41719,1.40878,0,,,,,65114.58073,114.3860105
38.85,6.47547,1.44361,0,,,,,66724.44235,115.4248478
39.2,6.53359,1.44474,0.00002,,,,,66776.67157,116.4608332
39.55,6.59203,1.49453,-0.00001,,,,,69077.99255,117.5025225
39.9,6.65016,1.4714,0,,,,,68008.91132,118.5386862
40.25,6.70844,1.49227,0.00002,,,,,68973.53412,119.5775235
40.6,6.76672,1.53591,-0.00001,,,,,70990.59874,120.6163609
40.95,6.82531,1.54356,0.00003,,,,,71344.18592,121.660724
41.3,6.88344,1.522,0,,,,,70347.67095,122.6968876
41.65,6.94187,1.49851,0.00006,,,,,69261.95032,123.7383987
42,7.00031,1.56166,-0.00007,,,,,72180.7778,124.780088
42.35,7.05859,1.53726,0.00003,,,,,71052.99648,125.8189254
42.7,7.11703,1.54202,0,,,,,71273.00628,126.8606147
43.05,7.17562,1.57441,0.00001,,,,,72770.08976,127.9049778
43.4,7.23391,1.58496,0.00001,,,,,73257.71652,128.9439934
43.75,7.29234,1.72895,0.00001,,,,,79913.01293,129.9855045
44.1,7.35094,1.58645,0.00003,,,,,73326.58513,131.0300458
44.45,7.40891,1.64152,0.00004,,,,,75871.9506,132.0633575
44.8,7.46734,1.60928,0.00001,,,,,74381.8002,133.1048686
45.15,7.52594,1.61627,0.00003,,,,,74704.88181,134.1494099
45.5,7.58406,1.61583,-0.00003,,,,,74684.54477,135.1853953
45.85,7.64234,1.65638,0.00003,,,,,76558.78791,136.2242326
46.2,7.70078,1.63468,0,,,,,75555.80207,137.265922
46.55,7.75906,1.69997,0.00002,,,,,78573.54151,138.3047593
46.9,7.81719,1.69273,-0.00003,,,,,78238.90476,139.3409229
47.25,7.87547,1.68922,0.00004,,,,,78076.67064,140.3797603
47.6,7.93375,1.7034,-0.00004,,,,,78732.07798,141.4185976
47.95,7.99187,1.75425,0.00004,,,,,81082.39275,142.454583
48.3,8.05031,1.72952,-0.00004,,,,,79939.35864,143.4962724
48.65,8.10859,1.72126,0.00002,,,,,79557.57693,144.5351097
49,8.16672,1.73485,-0.00001,,,,,80185.71415,145.5712733
49.35,8.22515,1.7647,0.00001,,,,,81565.39745,146.6127844
49.7,8.28359,1.78389,0,,,,,82452.36973,147.6544738
50.05,8.34172,1.79515,0.00002,,,,,82972.81307,148.6906374
50.4,8.40015,1.84752,0.00001,,,,,85393.38307,149.7321485
50.75,8.45859,1.82634,0.00001,,,,,84414.4319,150.7738378
51.1,8.51703,1.78999,-0.00001,,,,,82734.31506,151.8155272
51.45,8.57547,1.91328,0.00002,,,,,88432.84617,152.8572165
51.8,8.63391,1.83026,0.00002,,,,,84595.61644,153.8989059
52.15,8.69219,1.83118,0,,,,,84638.13935,154.9377432
52.5,8.75047,1.8654,0.00002,,,,,86219.80643,155.9765806
52.85,8.80906,1.90893,0,,,,,88231.78679,157.0209437
53.2,8.86734,1.88381,0,,,,,87070.72668,158.059781
53.55,8.92578,1.91695,0.00001,,,,,88602.47557,159.1014704
53.9,8.98422,1.88967,0,,,,,87341.57908,160.1431597
54.25,9.0425,1.92691,0.00002,,,,,89062.83221,161.1819971
54.6,9.10062,1.93597,0,,,,,89481.59036,162.2179824
54.95,9.15922,1.93771,0.00001,,,,,89562.01411,163.2625238
55.3,9.21719,1.94759,0,,,,,90018.6731,164.2958354
55.65,9.27531,1.94996,0.00001,,,,,90128.21579,165.3318208
56,9.33391,1.96107,0.00001,,,,,90641.72606,166.3763621
56.35,9.39203,1.98957,0.00001,,,,,91959.01162,167.4123475
56.7,9.45031,1.98804,0,,,,,91888.29418,168.4511848
57.05,9.50875,1.99136,0,,,,,92041.7464,169.4928742
57.4,9.56687,2.02176,0,,,,,93446.85099,170.5288595
57.75,9.625,2.05392,0,,,,,94933.30375,171.5650231
58.1,9.68344,2.02747,0.00002,,,,,93710.77031,172.6067125
58.45,9.74172,2.00143,0,,,,,92507.18729,173.6455498
58.8,9.80015,2.12434,-0.00002,,,,,98188.1546,174.6870609
59.15,9.85859,2.07276,0.00002,,,,,95804.09884,175.7287503
59.5,9.91703,2.14225,0,,,,,99015.96458,176.7704396
59.85,9.97531,2.07901,0.00002,,,,,96092.97725,177.809277
60.2,10.03375,2.11179,0.00002,,,,,97608.08675,178.8509663
60.55,10.09219,2.08029,0,,,,,96152.13955,179.8926557
60.9,10.15047,2.10918,0,,,,,97487.45112,180.931493
61.25,10.2089,2.12823,0,,,,,98367.95252,181.9730041
61.6,10.2675,2.13863,0.00001,,,,,98848.6462,183.0175455
61.95,10.32578,2.10892,-0.00001,,,,,97475.43378,184.0563828
62.3,10.3839,2.2585,0,,,,,104389.103,185.0923682
62.65,10.44265,2.14946,0,,,,,99349.21471,186.1395833
63,10.50078,2.18465,0.00003,,,,,100975.7157,187.1757469
63.35,10.55906,2.16841,0.00001,,,,,100225.0941,188.2145842
63.7,10.6175,2.22155,0.00005,,,,,102681.2539,189.2562736
64.05,10.67547,2.25855,-0.00001,,,,,104391.4141,190.2895852
64.4,10.73375,2.21038,0.00002,,,,,102164.9704,191.3284226
64.75,10.79219,2.23733,0,,,,,103410.6141,192.3701119
65.1,10.85047,2.22499,0.00004,,,,,102840.2525,193.4089493
65.45,10.90859,2.21358,0.00001,,,,,102312.8761,194.4449346
65.8,10.96703,2.26328,0.00002,,,,,104610.0373,195.486624
66.15,11.02516,2.31207,0,,,,,106865.1377,196.5227876
66.5,11.08344,2.2979,0,,,,,106210.1926,197.5616249
66.85,11.14187,2.27812,0,,,,,105295.9502,198.603136
67.2,11.20031,2.29166,0.00003,,,,,105921.7763,199.6448254
67.55,11.25844,2.33309,0.00003,,,,,107836.6936,200.680989
67.9,11.31687,2.32389,-0.00007,,,,,107411.4645,201.7225001
68.25,11.37547,2.31748,0.00014,,,,,107115.1908,202.7670414
68.6,11.43359,2.33015,-0.00003,,,,,107700.8052,203.8030268
68.95,11.49203,2.33592,0.00007,,,,,107967.4977,204.8447161
69.3,11.55062,2.31769,-0.00002,,,,,107124.8972,205.8890792
69.65,11.6089,2.41497,0.00002,,,,,111621.2319,206.9279166
70,11.66734,2.36119,0,,,,,109135.4909,207.9696059
70.35,11.72594,2.38289,0,,,,,110138.4768,209.0141473
70.7,11.7839,2.39807,0.00001,,,,,110840.1046,210.0472806
71.05,11.84234,2.41394,0,,,,,111573.6247,211.08897
71.4,11.90094,2.39721,0,,,,,110800.355,212.1335113
71.75,11.95906,2.44841,0,,,,,113166.8469,213.1694967
72.1,12.01734,2.42411,0,,,,,112043.6877,214.208334
72.45,12.07578,2.44547,0,,,,,113030.9585,215.2500234
72.8,12.1339,2.47488,0.00001,,,,,114390.3048,216.2860088
73.15,12.19203,2.44851,0,,,,,113171.469,217.3221724
73.5,12.25047,2.46602,0.00001,,,,,113980.7907,218.3638617
73.85,12.30875,2.49924,0.00001,,,,,115516.2373,219.4026991
74.2,12.36687,2.48672,-0.00001,,,,,114937.556,220.4386844
74.55,12.42515,2.52344,0.00002,,,,,116634.7745,221.4775218
74.9,12.48359,2.5343,-0.00001,,,,,117136.7296,222.5192111
75.25,12.54172,2.54836,0.00002,,,,,117786.5905,223.5553748
75.6,12.60015,2.5437,0,,,,,117571.2028,224.5968859
75.95,12.65859,2.55792,0.00001,,,,,118228.4589,225.6385752
76.3,12.71672,2.57788,0,,,,,119151.021,226.6747388
76.65,12.77531,2.57339,0.00001,,,,,118943.4908,227.7191019
77,12.83375,2.59429,0.00001,,,,,119909.5002,228.7607912
77.35,12.89203,2.58967,0,,,,,119695.9612,229.7996286
77.7,12.95047,2.60265,0,,,,,120295.9039,230.841318
78.05,13.00906,2.5965,0.00001,,,,,120011.6476,231.885681
78.4,13.06719,2.61096,-0.00001,,,,,120679.9967,232.9218447
78.75,13.12547,2.62245,0.00001,,,,,121211.0707,233.960682
79.1,13.18406,2.64842,0,,,,,122411.4183,235.0050451
79.45,13.24234,2.63363,0.00001,,,,,121727.8164,236.0438824
79.8,13.30078,2.66801,0,,,,,123316.8788,237.0855718
80.15,13.35922,2.658,0,,,,,122854.2112,238.1272611
80.5,13.41765,2.6815,0,,,,,123940.394,239.1687722
80.85,13.47562,2.6851,0,,,,,124106.7879,240.2020839
81.2,13.53406,2.70197,0,,,,,124886.5286,241.2437732
81.55,13.59219,2.68875,0.00001,,,,,124275.4929,242.2799368
81.9,13.65031,2.71045,0.00001,,,,,125278.4788,243.3159222
82.25,13.7089,2.73853,0,,,,,126576.3517,244.3602853
82.6,13.76719,2.71154,0,,,,,125328.8592,245.3993009
82.95,13.82531,2.74197,0.00001,,,,,126735.3504,246.4352862
83.3,13.88375,2.7827,0.00001,,,,,128617.9132,247.4769756
83.65,13.94187,2.75924,0.00001,,,,,127533.5792,248.512961
84,14,2.75365,0.00001,,,,,127275.2064,249.5491246
84.35,14.05844,2.76805,0,,,,,127940.7822,250.5908139
84.7,14.11672,2.78295,0,,,,,128629.4684,251.6296513
85.05,14.17515,2.80304,0.00001,,,,,129558.0391,252.6711624
85.4,14.23359,2.79346,0.00001,,,,,129115.2463,253.7128517
85.75,14.29203,2.82389,0.00001,,,,,130521.7375,254.7545411
86.1,14.35031,2.83714,0.00001,,,,,131134.1598,255.7933784
86.45,14.40875,2.84533,0.00001,,,,,131512.706,256.8350678
86.8,14.46734,2.83246,0.00001,,,,,130917.8476,257.8794308
87.15,14.52547,2.83129,0,,,,,130863.7696,258.9155945
87.5,14.5839,2.85559,0.00001,,,,,131986.9288,259.9571056
87.85,14.64266,2.87228,0.00001,,,,,132758.3497,261.0044989
88.2,14.70078,2.88394,0.00002,,,,,133297.2813,262.0404843
88.55,14.75906,2.89824,0.00001,,,,,133958.2351,263.0793216
88.9,14.81765,2.89377,0,,,,,133751.6293,264.1236847
89.25,14.87562,2.94394,0.00001,,,,,136070.5141,265.1569963
89.6,14.93406,2.92168,0,,,,,135041.6447,266.1986857
89.95,14.9925,2.94189,0.00001,,,,,135975.7619,267.240375
90.3,15.05047,2.96843,0.00001,,,,,137202.4552,268.2736866
90.65,15.10875,2.96406,0,,,,,137000.4714,269.312524
91,15.16734,2.93383,0,,,,,135603.2243,270.3568871
91.35,15.22547,2.9528,0.00001,,,,,136480.0281,271.3930507
91.7,15.28359,2.99062,0,,,,,138228.0892,272.4290361
92.05,15.34203,2.98795,0.00001,,,,,138104.6803,273.4707254
92.4,15.40015,3.00352,0.00001,,,,,138824.3342,274.5067108
92.75,15.45844,2.98849,0.00001,,,,,138129.6394,275.5457264
93.1,15.51687,3.02576,0.00001,,,,,139852.2791,276.5872375
93.45,15.57515,3.01505,0.00001,,,,,139357.2571,277.6260748
93.8,15.63343,3.01868,0,,,,,139525.0377,278.6649122
94.15,15.69203,3.04493,0.00001,,,,,140738.327,279.7094535
94.5,15.75031,3.03439,0.00001,,,,,140251.1624,280.7482909
94.85,15.80875,3.04015,0,,,,,140517.3928,281.7899802
95.2,15.86703,3.06991,0.00001,,,,,141892.9162,282.8288176
95.55,15.92562,3.05795,0.00001,,,,,141340.1185,283.8731807
95.9,15.9839,3.07574,0.00001,,,,,142162.382,284.912018
96.25,16.04234,3.07153,0.00001,,,,,141967.7935,285.9537074
96.6,16.10093,3.09062,0.00001,,,,,142850.1437,286.9980705
96.95,16.1589,3.10385,0.00001,,,,,143461.6416,288.0313821
97.3,16.21734,3.10865,0.00001,,,,,143683.5002,289.0730714
97.65,16.27593,3.13973,0.00001,,,,,145120.0348,290.1174345
98,16.33406,3.1377,0,,,,,145026.207,291.1535981
98.35,16.39234,3.14401,0.00001,,,,,145317.8587,292.1924355
98.7,16.45062,3.14784,0.00001,,,,,145494.8834,293.2312728
99.05,16.5089,3.15644,0.00001,,,,,145892.3801,294.2701102
99.4,16.56718,3.17041,0.00001,,,,,146538.0811,295.3089475
99.75,16.62547,3.1633,0.00001,,,,,146209.453,296.3479632
100.1,16.68375,3.17123,0.00001,,,,,146575.982,297.3868005
100.45,16.74187,3.22351,0.00001,,,,,148992.3921,298.4227859
100.8,16.80031,3.20957,0.00001,,,,,148348.0777,299.4644752
101.15,16.85859,3.27582,-0.00001,,,,,151410.1889,300.5033126
101.5,16.91671,3.23427,0.00002,,,,,149489.7252,301.5392979
101.85,16.97531,3.22172,0.00002,,,,,148909.6573,302.5838393
102.2,17.03359,3.24419,0,,,,,149948.233,303.6226766
102.55,17.09171,3.23266,0.00001,,,,,149415.3101,304.658662
102.9,17.15015,3.29157,0,,,,,152138.1625,305.7003513
103.25,17.20875,3.26212,0.00002,,,,,150776.9674,306.7448927
103.6,17.26703,3.26156,-0.00001,,,,,150751.0839,307.78373
103.95,17.32546,3.28724,0.00002,,,,,151938.0275,308.8252411
104.3,17.3839,3.28407,0,,,,,151791.5084,309.8669305
104.65,17.44218,3.30846,0.00001,,,,,152918.8275,310.9057678
105,17.50047,3.30003,0.00001,,,,,152529.1883,311.9447834
105.35,17.55906,3.29865,0,,,,,152465.4039,312.9891465
105.7,17.6175,3.32213,0.00001,,,,,153550.6623,314.0308359
106.05,17.67562,3.33288,0.00001,,,,,154047.5332,315.0668212
106.4,17.73421,3.3562,0.00001,,,,,155125.3963,316.1111843
106.75,17.7925,3.34566,0,,,,,154638.2318,317.1501999
107.1,17.85062,3.36334,0.00001,,,,,155455.411,318.1861853
107.45,17.90906,3.3756,0.00001,,,,,156022.0749,319.2278746
107.8,17.96718,3.36421,0,,,,,155495.6229,320.26386
108.15,18.02531,3.37314,0.00001,,,,,155908.3724,321.3000236
108.5,18.08375,3.38444,0.00001,,,,,156430.6646,322.341713
108.85,18.14218,3.40209,0.00001,,,,,157246.4572,323.3832241
109.2,18.20031,3.39311,0.00001,,,,,156831.3967,324.4193877
109.55,18.25875,3.42094,0.00001,,,,,158117.7145,325.461077
109.9,18.31703,3.42877,0.00001,,,,,158479.6214,326.4999144
110.25,18.375,3.44527,0,,,,,159242.2604,327.533226
110.6,18.43344,3.44069,0,,,,,159030.5703,328.5749153
110.95,18.49187,3.43477,0,,,,,158756.9446,329.6164264
111.3,18.55015,3.45316,0.00001,,,,,159606.9405,330.6552638
111.65,18.60859,3.46231,0.00001,,,,,160029.8585,331.6969531
112,18.66703,3.4641,0,,,,,160112.5932,332.7386425
112.35,18.72531,3.47095,0.00001,,,,,160429.204,333.7774798
112.7,18.78375,3.49018,0.00001,,,,,161318.0251,334.8191692
113.05,18.84218,3.50719,0.00001,,,,,162104.2366,335.8606803
113.4,18.90047,3.53101,0.00002,,,,,163205.21,336.8996959
113.75,18.9589,3.54158,0.00001,,,,,163693.7612,337.941207
114.1,19.01765,3.52074,0.00001,,,,,162730.525,338.9884221
114.45,19.07593,3.5248,0.00001,,,,,162918.1804,340.0272594
114.8,19.1339,3.51842,0.00001,,,,,162623.2933,341.060571
115.15,19.19265,3.53051,0.00001,,,,,163182.0997,342.1077861
115.5,19.25078,3.54883,0,,,,,164028.8601,343.1439497
115.85,19.30906,3.57037,0.00001,,,,,165024.4507,344.1827871
116.2,19.3675,3.57766,0,,,,,165361.3984,345.2244764
116.55,19.42546,3.57343,0.00002,,,,,165165.8855,346.2576098
116.9,19.48375,3.58266,0,,,,,165592.5012,347.2966254
117.25,19.54218,3.5704,0.00001,,,,,165025.8373,348.3381365
117.6,19.60047,3.59703,0.00001,,,,,166256.6904,349.3771521
117.95,19.65859,3.62423,0,,,,,167513.8893,350.4131375
118.3,19.71703,3.62176,0.00001,,,,,167399.7245,351.4548268
118.65,19.77515,3.65172,0.00001,,,,,168784.4921,352.4908122
119,19.83328,3.63481,0,,,,,168002.9027,353.5269758
119.35,19.89171,3.63388,0.00001,,,,,167959.9175,354.5684869
119.7,19.95031,3.66089,0,,,,,169208.3345,355.6130282
120.05,20.00843,3.65358,0.00002,,,,,168870.4623,356.6490136
120.4,20.06687,3.65646,-0.00001,,,,,169003.5775,357.690703
120.75,20.12531,3.70932,0.00002,,,,,171446.7955,358.7323923
121.1,20.18375,3.71084,0.00001,,,,,171517.0508,359.7740816
121.45,20.24203,3.69414,0,,,,,170745.1676,360.812919
121.8,20.30062,3.70006,0.00002,,,,,171018.7933,361.8572821
122.15,20.3589,3.69288,0.00001,,,,,170686.9298,362.8961194
122.5,20.41734,3.71471,0.00002,,,,,171695.9243,363.9378088
122.85,20.47593,3.72466,-0.00001,,,,,172155.8187,364.9821719
123.2,20.53406,3.75243,0.00001,,,,,173439.3633,366.0183355
123.55,20.59234,3.73887,0.00001,,,,,172812.6127,367.0571729
123.9,20.65093,3.75526,0,,,,,173570.1674,368.1015359
124.25,20.70906,3.75608,0.00002,,,,,173608.0683,369.1376996
124.6,20.76734,3.77762,0,,,,,174603.6588,370.1765369
124.95,20.82578,3.78758,0.00001,,,,,175064.0155,371.2182263
125.3,20.88406,3.79849,0.00001,,,,,175568.2816,372.2570636
125.65,20.94203,3.80628,0.00001,,,,,175928.3397,373.2903752
126,21.00031,3.80246,0.00001,,,,,175751.7772,374.3292126
126.35,21.05875,3.81513,0.00001,,,,,176337.3915,375.3709019
126.7,21.11687,3.83316,0.00001,,,,,177170.7479,376.4068873
127.05,21.17531,3.83262,0.00001,,,,,177145.7888,377.4485766
127.4,21.23359,3.83971,0.00001,,,,,177473.4925,378.487414
127.75,21.29172,3.85881,0.00001,,,,,178356.3049,379.5235776
128.1,21.35015,3.87609,0.00001,,,,,179154.996,380.5650887
128.45,21.40844,3.84881,0.00001,,,,,177894.0995,381.6041043
128.8,21.46671,3.8578,0.00001,,,,,178309.6222,382.6427634
129.15,21.52515,3.86668,0.00001,,,,,178720.0606,383.6844528
129.5,21.58375,3.89237,0.00001,,,,,179907.4665,384.7289941
129.85,21.64203,3.89237,0.00001,,,,,179907.4665,385.7678315
130.2,21.70047,3.90024,0.00001,,,,,180271.2222,386.8095208
130.55,21.7589,3.90465,0.00001,,,,,180475.0548,387.8510319
130.9,21.81718,3.92697,0.00001,,,,,181506.6974,388.8898693
131.25,21.87562,3.93531,0.00001,,,,,181892.1767,389.9315586
131.6,21.93406,3.93817,0.00001,,,,,182024.3675,390.973248
131.95,21.99234,3.92851,0.00001,,,,,181577.877,392.0120853
132.3,22.05062,3.955,0.00001,,,,,182802.2593,393.0509227
132.65,22.10922,3.96686,0.00001,,,,,183350.4349,394.095464
133,22.16765,3.93435,0,,,,,181847.805,395.1369751
133.35,22.22562,3.95518,0.00001,,,,,182810.579,396.1702867
133.7,22.28406,4.01469,0.00001,,,,,185561.1636,397.2119761
134.05,22.34218,3.97964,0,,,,,183941.1335,398.2479614
134.4,22.40031,3.99544,0.00003,,,,,184671.4181,399.284125
134.75,22.4589,4.01988,0.00002,,,,,185801.0483,400.3284881
135.1,22.51718,4.00967,0.00002,,,,,185329.1365,401.3673255
135.45,22.57515,4.01685,0.00002,,,,,185661,402.4006371
135.8,22.63375,4.0541,0,,,,,187382.7154,403.4451784
136.15,22.69187,4.02208,0.00003,,,,,185902.7335,404.4811638
136.5,22.75,4.04855,0,,,,,187126.1913,405.5173274
136.85,22.80843,4.06463,0.00002,,,,,187869.4177,406.5588385
137.2,22.86671,4.06627,0.00001,,,,,187945.2194,407.5976759
137.55,22.92515,4.08667,0.00001,,,,,188888.1185,408.6393652
137.9,22.98359,4.09167,0.00001,,,,,189119.2213,409.6810546
138.25,23.04187,4.08823,0.00001,,,,,188960.2226,410.7198919
138.6,23.10031,4.0823,0.00001,,,,,188686.1348,411.7615813
138.95,23.15875,4.10111,0.00001,,,,,189555.5432,412.8032706
139.3,23.21718,4.097,0.00001,,,,,189365.5768,413.8447817
139.65,23.27547,4.12233,0.00001,,,,,190536.3432,414.8837973
140,23.3339,4.13017,0.00001,,,,,190898.7123,415.9253084
140.35,23.39265,4.13746,0.00001,,,,,191235.6601,416.9725235
140.7,23.45093,4.12221,0.00001,,,,,190530.7967,418.0113609
141.05,23.50906,4.1599,0.00002,,,,,192272.8491,419.0475245
141.4,23.56765,4.15151,0.00001,,,,,191885.0587,420.0918876
141.75,23.62562,4.19796,0.00001,,,,,194032.0031,421.1251992
142.1,23.68406,4.14468,0.00002,,,,,191569.3724,422.1668885
142.45,23.74234,4.1957,0.00001,,,,,193927.5447,423.2057259
142.8,23.80047,4.20371,0.00001,,,,,194297.7712,424.2418895
143.15,23.8589,4.1862,0.00001,,,,,193488.4495,425.2834006
143.5,23.91718,4.19609,0.00001,,,,,193945.5707,426.3222379
143.85,23.97531,4.21509,0.00001,,,,,194823.7611,427.3584016
144.2,24.03359,4.20955,0.00001,,,,,194567.6992,428.3972389
144.55,24.09203,4.23446,0,,,,,195719.053,429.4389283
144.9,24.15015,4.23191,0.00001,,,,,195601.1906,430.4749136
145.25,24.20843,4.24818,0.00001,,,,,196353.1989,431.513751
145.6,24.26672,4.22772,0.00001,,,,,195407.5266,432.5527666
145.95,24.32531,4.24057,0.00001,,,,,196001.4606,433.5971297
146.3,24.38343,4.25989,0.00001,,,,,196894.4415,434.633115
146.65,24.44187,4.27014,0.00001,,,,,197368.2021,435.6748044
147,24.50047,4.28938,0,,,,,198257.4854,436.7193457
147.35,24.55859,4.28832,0.00001,,,,,198208.4916,437.7553311
147.7,24.61703,4.32513,0.00001,,,,,199909.8699,438.7970204
148.05,24.67562,4.28098,0.00001,,,,,197869.2328,439.8413835
148.4,24.7339,4.29874,0.00001,,,,,198690.1097,440.8802209
148.75,24.79234,4.31666,0.00002,,,,,199518.3819,441.9219102
149.1,24.85078,4.34938,0,,,,,201030.7182,442.9635996
149.45,24.9089,4.33223,0.00002,,,,,200238.0358,443.9995849
149.8,24.96734,4.30961,0,,,,,199192.5271,445.0412743
150.15,25.02593,4.34956,0.00002,,,,,201039.0379,446.0856374
150.5,25.08406,4.34263,0,,,,,200718.7295,447.121801
150.85,25.14234,4.35011,0.00002,,,,,201064.4592,448.1606383
151.2,25.20078,4.36854,0,,,,,201916.3038,449.2023277
151.55,25.2589,4.36141,0.00001,,,,,201586.7513,450.238313
151.9,25.31718,4.39555,0.00001,,,,,203164.7208,451.2771504
152.25,25.37531,4.38666,0.00001,,,,,202753.8201,452.313314
152.6,25.43375,4.40592,0.00001,,,,,203644.0278,453.3550034
152.95,25.49187,4.3929,0.00001,,,,,203042.2363,454.3909887
153.3,25.55031,4.41233,0.00001,,,,,203940.3015,455.4326781
153.65,25.60859,4.43061,0.00001,,,,,204785.2131,456.4715154
154,25.66672,4.41156,0.00001,,,,,203904.7117,457.507679
154.35,25.72531,4.43694,0.00001,,,,,205077.7892,458.5520421
154.7,25.78343,4.44808,0.00001,,,,,205592.6861,459.5880275
155.05,25.84171,4.4612,0.00001,,,,,206199.0996,460.6268649
155.4,25.90031,4.45994,0.00001,,,,,206140.8617,461.6714062
155.75,25.95875,4.44257,0,,,,,205338.0109,462.7130955
156.1,26.01687,4.52067,0.00002,,,,,208947.8355,463.7490809
156.45,26.07547,4.52515,0.00001,,,,,209154.9035,464.7936222
156.8,26.1339,4.4856,0.00002,,,,,207326.8809,465.8351333
157.15,26.19218,4.50375,0,,,,,208165.7839,466.8739707
157.5,26.25062,4.50558,0.00002,,,,,208250.3675,467.91566
157.85,26.30906,4.50973,0.00001,,,,,208442.1827,468.9573494
158.2,26.36734,4.51789,0.00002,,,,,208819.3424,469.9961867
158.55,26.42562,4.51506,0.00001,,,,,208688.5382,471.0350241
158.9,26.48421,4.51327,0.00003,,,,,208605.8035,472.0793872
159.25,26.5425,4.54934,0.00001,,,,,210272.9785,473.1184028
159.6,26.60062,4.55683,0.00002,,,,,210619.1704,474.1543881
159.95,26.6589,4.58315,0,,,,,211835.6952,475.1932255
160.3,26.71718,4.582,0.00002,,,,,211782.5416,476.2320629
160.65,26.77531,4.57309,0,,,,,211370.7165,477.2682265
161,26.8339,4.62053,0.00001,,,,,213563.4192,478.3125896
161.35,26.89218,4.62486,0.00002,,,,,213763.5542,479.3514269
161.7,26.95015,4.59869,0.00001,,,,,212553.9625,480.3847385
162.05,27.00875,4.59512,0.00001,,,,,212388.9551,481.4292799
162.4,27.06687,4.58478,0.00004,,,,,211911.0347,482.4652652
162.75,27.125,4.61844,-0.00021,,,,,213466.8183,483.5014289
163.1,27.18359,4.62391,0.00001,,,,,213719.6447,484.5457919
163.45,27.24172,4.6416,0,,,,,214537.2861,485.5819556
163.8,27.30015,4.65216,0.00003,,,,,215025.3751,486.6234667
164.15,27.35875,4.65681,0,,,,,215240.3006,487.668008
164.5,27.41687,4.66311,0.00002,,,,,215531.4901,488.7039934
164.85,27.47531,4.66288,0.00001,,,,,215520.8593,489.7456827
165.2,27.53375,4.67907,-0.00002,,,,,216269.17,490.7873721
165.55,27.59218,4.71274,0.00003,,,,,217825.4158,491.8288831
165.9,27.65047,4.67264,-0.00001,,,,,215971.9719,492.8678988
166.25,27.70906,4.77197,-0.00008,,,,,220563.0587,493.9122618
166.6,27.76765,4.73466,0.00093,,,,,218838.5701,494.9566249
166.95,27.82578,4.76865,0.00062,,,,,220409.6065,495.9927885
167.3,27.88406,4.699,-0.00002,,,,,217190.3455,497.0316259
167.65,27.94265,4.70574,-0.00007,,,,,217501.8719,498.075989
168,28.00078,4.81455,-0.00004,,,,,222531.1295,499.1121526
168.35,28.05906,4.78138,-0.00002,,,,,220997.994,500.15099
168.7,28.1175,4.75243,0.00002,,,,,219659.9092,501.1926793
169.05,28.17547,4.81389,0,,,,,222500.624,502.2259909
169.4,28.2339,4.75554,0.00001,,,,,219803.6551,503.267502
169.75,28.29234,4.86044,0.00001,,,,,224652.1904,504.3091914
170.1,28.35047,4.77091,0.00012,,,,,220514.0649,505.345355
170.45,28.40859,4.77897,-0.00003,,,,,220886.6025,506.3813403
170.8,28.46703,4.79281,0,,,,,221526.2949,507.4230297
171.15,28.52515,4.80673,-0.00005,,,,,222169.6849,508.4590151
171.5,28.58328,4.83183,0.00003,,,,,223329.8206,509.4951787
171.85,28.64172,4.83313,0.00001,,,,,223389.9073,510.536868
172.2,28.70031,4.80251,0.00002,,,,,221974.6342,511.5812311
172.55,28.75843,4.83486,0,,,,,223469.8688,512.6172165
172.9,28.81687,4.85228,0.00001,,,,,224275.0307,513.6589058
173.25,28.87547,4.847,0.00001,,,,,224030.9863,514.7034472
173.6,28.93359,4.84622,0.00001,,,,,223994.9342,515.7394325
173.95,28.99203,4.87446,0.00001,,,,,225300.2024,516.7811219
174.3,29.05062,4.87132,0.00001,,,,,225155.0699,517.8254849
174.65,29.10875,4.87082,0.00001,,,,,225131.9597,518.8616486
175,29.16734,4.88514,0.00001,,,,,225793.8379,519.9060117
175.35,29.22593,4.87445,0.00001,,,,,225299.7402,520.9503747
175.7,29.28406,4.89052,0.00001,,,,,226042.5044,521.9865384
176.05,29.3425,4.89748,0.00001,,,,,226364.1994,523.0282277
176.4,29.40093,4.89993,0.00001,,,,,226477.4398,524.0697388
176.75,29.45906,4.92994,0.00001,,,,,227864.5183,525.1059024
177.1,29.51734,4.92241,0.00001,,,,,227516.4776,526.1447398
177.45,29.57578,4.95027,0.00001,,,,,228804.182,527.1864291
177.8,29.6339,4.94721,0.00001,,,,,228662.7472,528.2224145
178.15,29.69203,4.93209,0.00001,,,,,227963.8925,529.2585781
178.5,29.75047,4.95492,0.00001,,,,,229019.1076,530.3002674
178.85,29.80859,4.95369,0.00001,,,,,228962.2563,531.3362528
179.2,29.86687,4.97204,0.00001,,,,,229810.4033,532.3750902
179.55,29.92531,4.97103,0.00001,,,,,229763.7206,533.4167795
179.9,29.98359,4.99548,0.00001,,,,,230893.8129,534.4556169
180.25,30.04172,4.97898,0.00001,,,,,230131.1739,535.4917805
180.6,30.10031,4.98309,0.00001,,,,,230321.1404,536.5361436
180.95,30.15843,5.01163,0.00001,,,,,231640.2747,537.5721289
181.3,30.21671,5.02432,0.00001,,,,,232226.8135,538.6109663
181.65,30.27531,5.02516,0.00001,,,,,232265.6387,539.6555076
182,30.33375,5.03313,0.00001,,,,,232634.0165,540.697197
182.35,30.39203,5.03028,0.00001,,,,,232502.2879,541.7360343
182.7,30.45046,5.03686,0.00001,,,,,232806.4191,542.7775454
183.05,30.5089,5.04077,0.00001,,,,,232987.1414,543.8192348
183.4,30.56718,5.11017,-0.00011,,,,,236194.8473,544.8580721
183.75,30.62562,5.03403,0.00073,,,,,232675.615,545.8997615
184.1,30.68406,5.06419,0.00013,,,,,234069.6266,546.9414508
184.45,30.74234,5.0631,0.00001,,,,,234019.2462,547.9802882
184.8,30.80078,5.08511,-0.00001,,,,,235036.5605,549.0219775
185.15,30.85921,5.11165,0.00002,,,,,236263.2537,550.0634886
185.5,30.9175,5.12033,0.00001,,,,,236664.4481,551.1025042
185.85,30.97562,5.11313,0.00001,,,,,236331.6601,552.1384896
186.2,31.03406,5.14201,0.00002,,,,,237666.5095,553.1801789
186.55,31.09218,5.15407,0.00001,,,,,238223.9293,554.2161643
186.9,31.15047,5.15495,0.00002,,,,,238264.6034,555.2551799
187.25,31.2089,5.14629,0.00001,,,,,237864.3335,556.296691
187.6,31.26718,5.1441,0.00001,,,,,237763.1105,557.3355283
187.95,31.32515,5.1632,0.00001,,,,,238645.9229,558.36884
188.3,31.38359,5.14398,0.00001,,,,,237757.564,559.4105293
188.65,31.44187,5.1797,0.00001,,,,,239408.5619,560.4493667
189,31.49999,5.17568,0.00001,,,,,239222.7553,561.485352
189.35,31.55843,5.16622,0.00001,,,,,238785.5089,562.5270414
189.7,31.61687,5.21517,0.00001,,,,,241048.0047,563.5687307
190.05,31.67515,5.196,0.00001,,,,,240161.9568,564.6075681
190.4,31.73359,5.20647,0.00001,,,,,240645.8859,565.6492574
190.75,31.79187,5.20116,0.00001,,,,,240400.4548,566.6880948
191.1,31.85046,5.19694,0.00001,,,,,240205.4041,567.7324579
191.45,31.90859,5.24313,0.00001,,,,,242340.3311,568.7686215
191.8,31.96734,5.24376,0.00001,,,,,242369.4501,569.8158366
192.15,32.02546,5.23809,0.00001,,,,,242107.3796,570.8518219
192.5,32.0839,5.24579,0.00001,,,,,242463.2778,571.8935113
192.85,32.14265,5.30194,-0.00001,,,,,245058.5614,572.9407264
193.2,32.20093,5.26873,0.00001,,,,,243523.5771,573.9795637
193.55,32.25921,5.25864,-0.00001,,,,,243057.2118,575.0184011
193.9,32.31765,5.30696,0.00001,,,,,245290.5886,576.0600904
194.25,32.37577,5.25995,0,,,,,243117.7607,577.0960758
194.6,32.43406,5.29879,0.00001,,,,,244912.9667,578.1350914
194.95,32.49249,5.29876,0.00001,,,,,244911.5801,579.1766025
195.3,32.55046,5.30812,0.00002,,,,,245344.2044,580.2099141
195.65,32.60875,5.31853,0.00001,,,,,245825.3603,581.2489297
196,32.66734,5.32213,0.00002,,,,,245991.7543,582.2932928
196.35,32.7253,5.33388,0.00001,,,,,246534.8457,583.3264262
196.7,32.78359,5.34938,0.00001,,,,,247251.2641,584.3654418
197.05,32.84203,5.34828,0.00001,,,,,247200.4215,585.4071311
197.4,32.90015,5.34574,0.00001,,,,,247083.0213,586.4431165
197.75,32.95843,5.34967,0.00001,,,,,247264.6681,587.4819538
198.1,33.01671,5.37007,0.00001,,,,,248207.5672,588.5207912
198.45,33.07531,5.40241,0.00002,,,,,249702.3397,589.5653325
198.8,33.13359,5.39,0.00001,,,,,249128.7427,590.6041699
199.15,33.19187,5.37703,0.00001,,,,,248529.2622,591.6430072
199.5,33.25031,5.36575,0.00001,,,,,248007.8945,592.6846966
199.85,33.30859,5.39794,0,,,,,249495.7338,593.7235339
200.2,33.36703,5.37516,0.00001,,,,,248442.8298,594.7652233
200.55,33.42562,5.38924,0,,,,,249093.6151,595.8095864
200.9,33.48374,5.52634,0.00003,,,,,255430.4519,596.8455717
201.25,33.54234,5.3793,0.00001,,,,,248634.1829,597.8901131
201.6,33.60093,5.43108,-0.00001,,,,,251027.4827,598.9344762
201.95,33.65906,5.48267,0.00002,,,,,253412.0007,599.9706398
202.3,33.71734,5.45078,0.00002,,,,,251938.0275,601.0094771
202.65,33.77593,5.44089,0.00001,,,,,251480.9063,602.0538402
203,33.83406,5.46371,0.00002,,,,,252535.6592,603.0900038
203.35,33.89234,5.45295,0,,,,,252038.3261,604.1288412
203.7,33.95078,5.47454,-0.00001,,,,,253036.2277,605.1705305
204.05,34.0089,5.49087,0.00004,,,,,253791.0092,606.2065159
204.4,34.06702,5.50337,0,,,,,254368.766,607.2425013
204.75,34.12546,5.50299,0.00003,,,,,254351.2022,608.2841906
205.1,34.18374,5.47845,0,,,,,253216.95,609.323028
205.45,34.24187,5.50553,0,,,,,254468.6024,610.3591916
205.8,34.3003,5.53138,0.00002,,,,,255663.4035,611.4007027
206.15,34.35874,5.52463,0.00001,,,,,255351.4148,612.442392
206.5,34.41671,5.5432,0.00002,,,,,256209.7303,613.4757037
206.85,34.47515,5.55161,0.00001,,,,,256598.4451,614.517393
207.2,34.53343,5.55831,0.00002,,,,,256908.1228,615.5562304
207.55,34.59171,5.56547,0.00001,,,,,257239.0619,616.5950677
207.9,34.65031,5.56547,0.00001,,,,,257239.0619,617.639609
208.25,34.70874,5.58528,0.00001,,,,,258154.6909,618.6811201
208.6,34.76702,5.57982,0,,,,,257902.3267,619.7199575
208.95,34.82546,5.58457,0.00002,,,,,258121.8743,620.7616468
209.3,34.8839,5.6371,0.00001,,,,,260549.8396,621.8033362
209.65,34.94218,5.62523,0.00001,,,,,260001.2017,622.8421735
210,35.00062,5.59126,0.00001,,,,,258431.0898,623.8838629
210.35,35.05906,5.6279,0.00001,,,,,260124.6106,624.9255522
210.7,35.11734,5.62794,0.00001,,,,,260126.4594,625.9643896
211.05,35.17577,5.62377,0.00002,,,,,259933.7197,627.0059007
211.4,35.23421,5.65631,0.00001,,,,,261437.7363,628.04759
211.75,35.2925,5.6428,0.00002,,,,,260813.2967,629.0866056
212.1,35.35062,5.6536,0.00001,,,,,261312.4786,630.122591
212.45,35.40905,5.67976,0.00001,,,,,262521.6081,631.1641021
212.8,35.46718,5.66982,0.00001,,,,,262062.1759,632.2002657
213.15,35.52531,5.66289,0.00001,,,,,261741.8675,633.2364293
213.5,35.5839,5.7061,0.00001,,,,,263739.0573,634.2807924
213.85,35.64218,5.69551,0.00001,,,,,263249.5817,635.3196298
214.2,35.70015,5.70224,0.00001,,,,,263560.646,636.3529414
214.55,35.75874,5.70552,0.00001,,,,,263712.2494,637.3973045
214.9,35.81687,5.71163,0.00001,,,,,263994.6569,638.4334681
215.25,35.87499,5.72517,0,,,,,264620.4831,639.4694535
215.6,35.93343,5.72549,0.00002,,,,,264635.2737,640.5111428
215.95,35.99187,5.73136,0.00001,,,,,264906.5883,641.5528322
216.3,36.05015,5.75268,0.00001,,,,,265892.0103,642.5916695
216.65,36.10843,5.74726,0.00001,,,,,265641.495,643.6305069
217,36.16687,5.74394,0.00001,,,,,265488.0427,644.6721962
217.35,36.22531,5.7559,0.00001,,,,,266040.8405,645.7138856
217.7,36.28358,5.76702,0.00001,,,,,266554.8129,646.7525447
218.05,36.34218,5.76995,0.00001,,,,,266690.2391,647.797086
218.4,36.40046,5.77183,0.00001,,,,,266777.1338,648.8359234
218.75,36.4589,5.78477,0.00001,,,,,267375.2276,649.8776127
219.1,36.51765,5.79945,0.00001,,,,,268053.7453,650.9248278
219.45,36.57593,5.80014,0.00001,,,,,268085.6374,651.9636651
219.8,36.63406,5.78751,-0.00001,,,,,267501.8719,652.9998288
220.15,36.69265,5.81112,0,,,,,268593.139,654.0441918
220.5,36.75062,5.88208,0.00001,,,,,271872.949,655.0775035
220.85,36.8089,5.82598,0.00001,,,,,269279.9763,656.1163408
221.2,36.86749,5.86077,0,,,,,270887.9891,657.1607039
221.55,36.92546,5.88287,0.00002,,,,,271909.4632,658.1940155
221.9,36.9839,5.84229,0,,,,,270033.8334,659.2357049
222.25,37.04234,5.85737,0.00002,,,,,270730.8393,660.2773942
222.6,37.10046,5.85263,0.00001,,,,,270511.7539,661.3133796
222.95,37.15858,5.85223,0.00001,,,,,270493.2657,662.349365
223.3,37.21703,5.90052,0.00001,,,,,272725.2558,663.3912325
223.65,37.27531,5.88989,0.00001,,,,,272233.9314,664.4300699
224,37.33343,5.91965,0.00001,,,,,273609.4549,665.4660553
224.35,37.39171,5.91303,0.00002,,,,,273303.4749,666.5048926
224.7,37.45031,5.94966,0.00001,,,,,274996.5335,667.549434
225.05,37.50843,5.93827,0.00002,,,,,274470.0814,668.5854193
225.4,37.56687,5.91582,0.00001,,,,,273432.4302,669.6271087
225.75,37.62531,5.94114,0.00001,,,,,274602.7344,670.668798
226.1,37.68359,5.93183,0.00001,,,,,274172.4211,671.7076354
226.45,37.74203,5.94178,0.00001,,,,,274632.3156,672.7493247
226.8,37.80062,5.95887,0.00001,,,,,275422.2247,673.7936878
227.15,37.8589,5.98418,0.00001,,,,,276592.0667,674.8325252
227.5,37.91734,5.97305,0.00001,,,,,276077.632,675.8742145
227.85,37.97593,5.95679,0.00003,,,,,275326.086,676.9185776
228.2,38.0339,5.97499,0.00002,,,,,276167.2999,677.9518892
228.55,38.09234,5.99403,0.00004,,,,,277047.3391,678.9935786
228.9,38.15093,5.99294,0,,,,,276996.9587,680.0379417
229.25,38.20905,6.03411,0.00004,,,,,278899.8586,681.073927
229.6,38.26734,6.0669,0.00002,,,,,280415.4303,682.1129426
229.95,38.32562,6.0539,0.00001,,,,,279814.5632,683.15178
230.3,38.3839,6.07087,0.00001,,,,,280598.9258,684.1906173
230.65,38.44202,6.05956,0.00002,,,,,280076.1715,685.2266027
231,38.50046,6.04904,0.00001,,,,,279589.9313,686.268292
231.35,38.55874,6.05852,0.00002,,,,,280028.1021,687.3071294
231.7,38.61687,6.11636,0.00001,,,,,282701.4985,688.343293
232.05,38.67515,6.08215,0.00002,,,,,281120.2936,689.3821304
232.4,38.73359,6.08887,0.00001,,,,,281430.8957,690.4238197
232.75,38.79171,6.06691,0.00002,,,,,280415.8925,691.4598051
233.1,38.85015,6.08037,0.00001,,,,,281038.021,692.5014944
233.45,38.90858,6.08104,0.00001,,,,,281068.9888,693.5430055
233.8,38.96671,6.09119,0.00002,,,,,281538.1273,694.5791691
234.15,39.02531,6.10042,0,,,,,281964.743,695.6237105
234.5,39.08374,6.12387,0.00002,,,,,283048.6148,696.6652216
234.85,39.14187,6.11424,0.00001,,,,,282603.5109,697.7013852
235.2,39.20046,6.14421,0.00002,,,,,283988.7407,698.7457483
235.55,39.25906,6.14358,0.00001,,,,,283959.6217,699.7902896
235.9,39.31718,6.15421,0.00002,,,,,284450.9461,700.826275
236.25,39.37562,6.14025,0.00001,,,,,283805.7073,701.8679643
236.6,39.43406,6.1796,0.00001,,,,,285624.4858,702.9096537
236.95,39.49249,6.12927,0.00001,,,,,283298.2057,703.9511648
237.3,39.55062,6.16908,0.00001,,,,,285138.2457,704.9873284
237.65,39.60921,6.20185,0.00001,,,,,286652.8929,706.0316915
238,39.6675,6.20816,0.00001,,,,,286944.5446,707.0707071
238.35,39.72562,6.20359,0.00002,,,,,286733.3167,708.1066924
238.7,39.78405,6.20782,0.00001,,,,,286928.8296,709.1482035
239.05,39.84218,6.23338,0.00003,,,,,288110.2268,710.1843671
239.4,39.90031,6.24788,0.00001,,,,,288780.4247,711.2205308
239.75,39.9589,6.23472,0.00002,,,,,288172.1623,712.2648938
240.1,40.01718,6.25592,0.00002,,,,,289152.0379,713.3037312
240.45,40.07531,6.25894,0.00001,,,,,289291.6239,714.3398948
240.8,40.13374,6.27949,0.00002,,,,,290241.4561,715.3814059
241.15,40.19187,6.2797,0.00002,,,,,290251.1624,716.4175695
241.5,40.24999,6.27914,0.00002,,,,,290225.2789,717.4535549
241.85,40.30843,6.27355,0.00002,,,,,289966.9061,718.4952442
242.2,40.36687,6.29661,0.00002,,,,,291032.7519,719.5369336
242.55,40.42515,6.31649,0.00002,,,,,291951.6163,720.5757709
242.9,40.48359,6.3201,0.00002,,,,,292118.4725,721.6174603
243.25,40.54203,6.32475,0.00002,,,,,292333.398,722.6591496
243.6,40.60031,6.3228,0.00002,,,,,292243.268,723.697987
243.95,40.65874,6.3371,0.00002,,,,,292904.2218,724.7394981
244.3,40.71718,6.35504,0.00002,,,,,293733.4184,725.7811874
244.65,40.77546,6.35192,0.00002,,,,,293589.2103,726.8200248
245,40.8339,6.35536,0.00002,,,,,293748.209,727.8617141
245.35,40.89265,6.37638,0.00001,,,,,294719.7648,728.9089292
245.7,40.95078,6.35631,0.00002,,,,,293792.1185,729.9450928
246.05,41.00906,6.37079,0.00001,,,,,294461.392,730.9839302
246.4,41.06781,6.35233,0.00002,,,,,293608.1607,732.0311453
246.75,41.12577,6.38626,0.00002,,,,,295176.4238,733.0642786
247.1,41.1839,6.38576,0.00002,,,,,295153.3136,734.1004422
247.45,41.2425,6.40245,0.00001,,,,,295924.7345,735.1449836
247.8,41.30046,6.41646,0.00002,,,,,296572.2843,736.178117
248.15,41.35874,6.42446,0.00001,,,,,296942.0487,737.2169543
248.5,41.41718,6.4416,0.00002,,,,,297734.2688,738.2586437
248.85,41.47531,6.41501,0.00002,,,,,296505.2645,739.2948073
249.2,41.53358,6.44915,0.00002,,,,,298083.234,740.3334664
249.55,41.59203,6.43706,0.00002,,,,,297524.4276,741.375334
249.9,41.65015,6.45595,0.00002,,,,,298397.5337,742.4113193
250.25,41.70843,6.46421,0.00002,,,,,298779.3154,743.4501567
250.6,41.76687,6.46255,0.00003,,,,,298702.5893,744.491846
250.95,41.82531,6.48012,0.00002,,,,,299514.6843,745.5335354
251.3,41.88343,6.51125,0.00003,,,,,300953.5299,746.5695208
251.65,41.94187,6.48464,0.00004,,,,,299723.6011,747.6112101
252,42.00031,6.48366,0.00001,,,,,299678.305,748.6528994
252.35,42.05874,6.5447,0.00004,,,,,302499.6071,749.6944105
252.7,42.11703,6.51239,0.00002,,,,,301006.2213,750.7334262
253.05,42.17562,6.50193,0.00002,,,,,300522.7544,751.7777892
253.4,42.2339,6.53439,0.00002,,,,,302023.0733,752.8166266
253.75,42.29234,6.56552,0.00001,,,,,303461.9189,753.8583159
254.1,42.35093,6.55532,0.00002,,,,,302990.4693,754.902679
254.45,42.40905,6.56525,0.00001,,,,,303449.4393,755.9386644
254.8,42.46749,6.5418,0.00002,,,,,302365.5675,756.9803537
255.15,42.52593,6.57176,0.00002,,,,,303750.3351,758.0220431
255.5,42.58405,6.58066,0.00002,,,,,304161.698,759.0580284
255.85,42.64234,6.59007,0.00002,,,,,304596.6333,760.0970441
256.2,42.70062,6.59591,0.00002,,,,,304866.5613,761.1358814
256.55,42.75906,6.60982,0.00002,,,,,305509.4891,762.1775708
256.9,42.81703,6.59736,0.00002,,,,,304933.5811,763.2108824
257.25,42.87546,6.62023,0.00002,,,,,305990.645,764.2523935
257.6,42.93359,6.63243,0.00002,,,,,306554.5356,765.2885571
257.95,42.99187,6.63468,0.00002,,,,,306658.5319,766.3273944
258.3,43.0503,6.649,0.00002,,,,,307320.4101,767.3689055
258.65,43.10859,6.65136,0.00002,,,,,307429.4906,768.4079211
259,43.16671,6.66279,0.00002,,,,,307957.7914,769.4439065
259.35,43.22515,6.64722,0.00002,,,,,307238.1375,770.4855959
259.7,43.28343,6.664,0.00002,,,,,308013.7183,771.5244332
260.05,43.34171,6.68316,0.00002,,,,,308899.3039,772.5632706
260.4,43.40031,6.66868,0.00002,,,,,308230.0304,773.6078119
260.75,43.45874,6.67029,0.00002,,,,,308304.4455,774.649323
261.1,43.51702,6.69411,0.00002,,,,,309405.4189,775.6881604
261.45,43.57546,6.69574,0.00002,,,,,309480.7584,776.7298497
261.8,43.6339,6.70962,0.00002,,,,,310122.2996,777.771539
262.15,43.69218,6.72393,0.00002,,,,,310783.7156,778.8103764
262.5,43.75062,6.73554,0.00002,,,,,311320.3361,779.8520658
262.85,43.80906,6.72847,0.00002,,,,,310993.5569,780.8937551
263.2,43.8675,6.75894,0.00002,,,,,312401.8969,781.9354444
263.55,43.92577,6.73823,0.00002,,,,,311444.6694,782.9741035
263.9,43.98421,6.7773,0.00002,,,,,313250.5061,784.0157929
264.25,44.0425,6.77396,0.00003,,,,,313096.1295,785.0548085
264.6,44.10062,6.76489,0.00002,,,,,312676.9091,786.0907939
264.95,44.15905,6.76727,0.00002,,,,,312786.914,787.132305
265.3,44.21718,6.78955,0.00003,,,,,313816.7078,788.1684686
265.65,44.27531,6.82223,0.00001,,,,,315327.1952,789.2046322
266,44.3339,6.81278,0.00003,,,,,314890.4111,790.2489953
266.35,44.39202,6.79266,0,,,,,313960.4537,791.2849806
266.7,44.45031,6.85339,0.00002,,,,,316767.4275,792.3239962
267.05,44.50859,6.95436,0.00001,,,,,321434.316,793.3628336
267.4,44.56687,6.82069,0.00002,,,,,315256.0156,794.401671
267.75,44.62499,6.82543,0.00005,,,,,315475.101,795.4376563
268.1,44.68343,6.86026,-0.00002,,,,,317084.9626,796.4793457
268.45,44.74187,6.84652,0.00005,,,,,316449.8923,797.521035
268.8,44.80015,6.84671,0,,,,,316458.6742,798.5598724
269.15,44.85859,6.90304,0.00003,,,,,319062.2776,799.6015617
269.5,44.91703,6.9032,0.00002,,,,,319069.6729,800.6432511
269.85,44.97531,6.90399,0.00002,,,,,319106.1871,801.6820884
270.2,45.03374,6.9111,0.00003,,,,,319434.8152,802.7235995
270.55,45.09234,6.90094,0.00002,,,,,318965.2144,803.7681409
270.9,45.15046,6.90402,0.00002,,,,,319107.5737,804.8041262
271.25,45.2089,6.91165,0.00002,,,,,319460.2365,805.8458156
271.6,45.26765,6.91388,0.00002,,,,,319563.3083,806.8930306
271.95,45.32578,6.93111,0.00002,,,,,320359.6883,807.9291943
272.3,45.38406,6.92242,0.00002,,,,,319958.0317,808.9680316
272.65,45.44265,6.95603,0.00002,,,,,321511.5043,810.0123947
273,45.50062,6.97942,0.00003,,,,,322592.6029,811.0457063
273.35,45.5589,6.95789,0.00002,,,,,321597.4745,812.0845437
273.7,45.6175,6.95339,0.00003,,,,,321389.4821,813.129085
274.05,45.67546,6.96087,0.00002,,,,,321735.2117,814.1622184
274.4,45.7339,6.98913,0.00002,,,,,323041.4044,815.2039077
274.75,45.79234,6.98153,0.00002,,,,,322690.1282,816.2455971
275.1,45.85046,6.98546,0.00002,,,,,322871.775,817.2815824
275.45,45.90858,7.00604,0.00002,,,,,323822.9938,818.3175678
275.8,45.96702,6.99729,0,,,,,323418.564,819.3592572
276.15,46.02531,7.06965,0.00003,,,,,326763.0827,820.3982728
276.5,46.08343,7.00659,0.00002,,,,,323848.4151,821.4342581
276.85,46.14186,7.03611,0.00002,,,,,325212.8456,822.4757692
277.2,46.20031,7.04639,0.00003,,,,,325687.9928,823.5176368
277.55,46.25859,7.05452,0.00001,,,,,326063.7659,824.5564742
277.9,46.31687,7.05187,0.00002,,,,,325941.2814,825.5953115
278.25,46.37546,7.09021,0.00003,,,,,327713.3772,826.6396746
278.6,46.43359,7.05677,0.00001,,,,,326167.7621,827.6758382
278.95,46.49202,7.09236,0.00002,,,,,327812.7513,828.7173493
279.3,46.55062,7.11767,0.00001,,,,,328982.5933,829.7618907
279.65,46.6089,7.12272,0.00003,,,,,329216.0071,830.800728
280,46.66734,7.11306,0.00002,,,,,328769.5166,831.8424174
280.35,46.72593,7.12501,0.00003,,,,,329321.8521,832.8867805
280.7,46.7839,7.10466,0.00002,,,,,328381.264,833.9200921
281.05,46.84234,7.14117,0.00003,,,,,330068.7762,834.9617814
281.4,46.90109,7.10449,0.00002,,,,,328373.4065,836.0089965
281.75,46.95906,7.14131,0.00002,,,,,330075.247,837.0423081
282.1,47.01733,7.13861,0.00002,,,,,329950.4516,838.0809672
282.45,47.07578,7.13585,0.00002,,,,,329822.8829,839.1228348
282.75,47.12499,7.10213,0.00002,,,,,328264.3261,840