File: .gitbook/assets/mane.6962.experimental.session.specimen_rawdata_b (2).csv
Crosshead speed,10,mm/min,,,,,,,
Tensile strain,25.4,mm,,,,,Area,2.05629E-05,
,,,,,,,,,
Time,Extension,Load,Strain from Extensometer,,,,,,
(s),(mm),(N),(mm/mm),,,,,Stress,Strain
0,-10.98859,-0.0021,0,,,,,-102.1258716,-207.7577154
0.4,-10.92172,0.01705,0.00001,,,,,829.1648146,-206.493426
0.8,-10.85516,0.03096,0.00001,,,,,1505.627136,-205.2349976
1.2,-10.78844,0.04742,0,,,,,2306.099443,-203.9735442
1.6,-10.72141,0.06964,0,,,,,3386.688428,-202.7062296
2,-10.65453,0.06525,0,,,,,3173.196725,-201.4417511
2.4,-10.58844,0.07505,0,,,,,3649.784125,-200.1922089
2.8,-10.52172,0.08846,0,,,,,4301.930763,-198.9307554
3.2,-10.45453,0.1235,0.00001,,,,,6005.973877,-197.6604158
3.6,-10.38797,0.12634,0,,,,,6144.086961,-196.4019875
4,-10.32156,0.15259,0.00001,,,,,7420.660356,-195.1463951
4.4,-10.25516,0.17343,0.00001,,,,,8434.138053,-193.8909918
4.8,-10.18797,0.18428,0.00001,,,,,8961.788389,-192.6206522
5.2,-10.12125,0.20392,0.00001,,,,,9916.908446,-191.3591987
5.6,-10.05484,0.2392,0.00001,,,,,11632.62309,-190.1036063
6,-9.98844,0.23444,0.00001,,,,,11401.13778,-188.848203
6.4,-9.92156,0.24465,0.00001,,,,,11897.66404,-187.5837245
6.8,-9.85453,0.27128,0.00001,,,,,13192.71736,-186.31641
7.2,-9.78828,0.28562,0.00001,,,,,13890.09116,-185.0638427
7.6,-9.72172,0.31938,0.00001,,,,,15531.88613,-183.8054143
8,-9.655,0.31606,0.00001,,,,,15370.42999,-182.5439608
8.4,-9.58766,0.33284,0.00001,,,,,16186.46433,-181.2707852
8.8,-9.52125,0.34836,0.00001,,,,,16941.22316,-180.0151929
9.2,-9.455,0.35434,0.00001,,,,,17232.03873,-178.7626256
9.6,-9.38813,0.36115,0.00001,,,,,17563.21835,-177.4983361
10,-9.32125,0.39577,0,,,,,19246.83629,-176.2338576
10.4,-9.25469,0.41883,0.00001,,,,,20368.27562,-174.9754292
10.8,-9.18844,0.42496,0.00002,,,,,20666.3859,-173.7228619
11.2,-9.12172,0.4451,0.00003,,,,,21645.82164,-172.4614084
11.6,-9.05453,0.43458,0.00003,,,,,21134.21966,-171.1910688
12,-8.98797,0.4609,0.00001,,,,,22414.19725,-169.9326405
12.4,-8.92172,0.47827,0.00001,,,,,23258.9241,-168.6800732
12.8,-8.85516,0.51031,0.00001,,,,,24817.07311,-167.4216448
13.2,-8.78781,0.52389,0,,,,,25477.48708,-166.1482801
13.6,-8.72109,0.53568,0,,,,,26050.8509,-164.8868267
14,-8.65484,0.53906,0.00001,,,,,26215.22492,-163.6342593
14.4,-8.58828,0.5322,0.00002,,,,,25881.61374,-162.375831
14.8,-8.52125,0.56929,-0.00001,,,,,27685.35116,-161.1085164
15.2,-8.45438,0.57535,-0.00002,,,,,27980.05725,-159.844227
15.6,-8.38828,0.58511,-0.00001,,,,,28454.69939,-158.5944957
16,-8.32188,0.6262,0,,,,,30452.96228,-157.3390924
16.4,-8.25484,0.62478,0,,,,,30383.90574,-156.0715888
16.8,-8.18797,0.64781,0,,,,,31503.88613,-154.8072993
17.2,-8.12156,0.67856,0.00001,,,,,32999.30068,-153.5517069
17.6,-8.05516,0.68408,0.00001,,,,,33267.74583,-152.2963036
18,-7.98812,0.69488,0.00001,,,,,33792.9646,-151.0288
18.4,-7.92109,0.72168,0,,,,,35096.28524,-149.7614855
18.8,-7.85437,0.73766,0,,,,,35873.4145,-148.5000321
19.2,-7.78828,0.73936,0,,,,,35956.08782,-147.2504898
19.6,-7.72156,0.74915,0,,,,,36432.18891,-145.9890364
20,-7.65453,0.78201,0.00001,,,,,38030.21564,-144.7217219
20.4,-7.58797,0.7874,0,,,,,38292.33871,-143.4632935
20.8,-7.52172,0.8154,0,,,,,39654.017,-142.2107262
21.2,-7.45516,0.82699,0.00001,,,,,40217.65455,-140.9522978
21.6,-7.38797,0.841,0.00001,,,,,40898.98001,-139.6819582
22,-7.32125,0.83591,0.00001,,,,,40651.44635,-138.4205047
22.4,-7.25516,0.86113,0.00001,,,,,41877.92943,-137.1709625
22.8,-7.18844,0.88072,0.00001,,,,,42830.61792,-135.909509
23.2,-7.12141,0.89737,0.00001,,,,,43640.33019,-134.6421945
23.6,-7.05438,0.90389,0,,,,,43957.4067,-133.37488
24,-6.98828,0.92756,-0.00001,,,,,45108.51117,-132.1251487
24.4,-6.92156,0.94501,0,,,,,45957.12853,-130.8636952
24.8,-6.85453,0.96187,0,,,,,46777.05339,-129.5963807
25.2,-6.78781,0.95837,0.00001,,,,,46606.8436,-128.3349273
25.6,-6.72172,0.96932,0,,,,,47139.35707,-127.085385
26,-6.65531,0.9822,0,,,,,47765.72909,-125.8297926
26.4,-6.58813,1.02249,0,,,,,49725.08688,-124.5596421
26.8,-6.52125,1.00719,-0.00001,,,,,48981.02696,-123.2951636
27.2,-6.45484,1.03906,0.00007,,,,,50530.90864,-122.0395712
27.6,-6.38859,1.07052,0.00003,,,,,52060.85146,-120.7870039
28,-6.32156,1.08827,-0.00001,,,,,52924.05823,-119.5196894
28.4,-6.25453,0.98795,-0.0001,,,,,48045.35945,-118.2523749
28.8,-6.18812,1.10265,-0.00025,,,,,53623.37729,-116.9967825
29.2,-6.12156,1.09815,0.00073,,,,,53404.53614,-115.7383541
29.6,-6.05484,1.09331,0.00004,,,,,53169.16032,-114.4769007
30,-5.98766,1.12723,0.00002,,,,,54818.7363,-113.2067501
30.4,-5.92125,1.1431,-0.00002,,,,,55590.51611,-111.9511578
30.8,-5.85516,1.17634,-0.00002,,,,,57207.02276,-110.7016155
31.2,-5.78844,1.20635,0.00001,,,,,58666.45009,-109.4401621
31.6,-5.72141,1.19922,0,,,,,58319.70845,-108.1728475
32,-5.65469,1.22751,0,,,,,59695.48983,-106.9113941
32.4,-5.58844,1.23679,0,,,,,60146.78892,-105.6588268
32.8,-5.52156,1.25326,0,,,,,60947.74754,-104.3943483
33.2,-5.45453,1.24875,0,,,,,60728.42007,-103.1270337
33.6,-5.38781,1.24281,-0.00001,,,,,60439.54975,-101.8655803
34,-5.32156,1.26995,-0.00001,,,,,61759.40506,-100.613013
34.4,-5.25516,1.30721,-0.00001,,,,,63571.40981,-99.35760966
34.8,-5.18797,1.30797,0,,,,,63608.36965,-98.08727007
35.2,-5.12125,1.32325,0,,,,,64351.45695,-96.82581662
35.6,-5.05484,1.33245,-0.00001,,,,,64798.86553,-95.57022424
36,-4.98844,1.35716,0.00001,,,,,66000.54662,-94.31482092
36.4,-4.92156,1.3559,0,,,,,65939.27109,-93.0503424
36.8,-4.85453,1.38707,0,,,,,67455.11082,-91.78302788
37.2,-4.78844,1.40147,0,,,,,68155.40251,-90.53348564
37.6,-4.72188,1.41387,-0.00001,,,,,68758.43146,-89.27505725
38,-4.65484,1.44044,-0.00001,,,,,70050.5669,-88.00755367
38.4,-4.58781,1.44298,0,,,,,70174.09057,-86.74023915
38.8,-4.52109,1.46111,0,,,,,71055.77726,-85.4787857
39.2,-4.45516,1.48176,0,,,,,72060.015,-84.23226852
39.6,-4.38812,1.47413,-0.00001,,,,,71688.95766,-82.96476493
40,-4.32125,1.47451,-0.00001,,,,,71707.43758,-81.70047548
40.4,-4.25469,1.52263,0,,,,,74047.57898,-80.4420471
40.8,-4.18844,1.52255,-0.00001,,,,,74043.68848,-79.18947979
41.2,-4.12172,1.53066,-0.00001,,,,,74438.08887,-77.92802633
41.6,-4.05453,1.54854,0,,,,,75307.61771,-76.65768675
42,-3.98797,1.55882,-0.00001,,,,,75807.54817,-75.39925836
42.4,-3.92156,1.59184,0,,,,,77413.35592,-74.14366598
42.8,-3.85516,1.57756,0,,,,,76718.9,-72.88826267
43.2,-3.78797,1.5987,-0.00001,,,,,77746.9671,-71.61792308
43.6,-3.72109,1.62108,0,,,,,78835.33711,-70.35344456
44,-3.655,1.6311,0,,,,,79322.62341,-69.10390232
44.4,-3.58828,1.63529,0,,,,,79526.38884,-67.84244886
44.8,-3.52141,1.6535,0,,,,,80411.96604,-66.57815941
45.2,-3.45438,1.66224,0,,,,,80837.00419,-65.31084489
45.6,-3.38828,1.67448,0,,,,,81432.25213,-64.06111358
46,-3.32188,1.68552,0,,,,,81969.14242,-62.80571027
46.4,-3.25484,1.69644,0,,,,,82500.19696,-61.53820668
46.8,-3.18813,1.71468,0,,,,,83387.2331,-60.2769423
47.2,-3.12156,1.72947,0,,,,,84106.49102,-59.01832485
47.6,-3.05516,1.74783,0,,,,,84999.36293,-57.76292153
48,-2.98812,1.76026,0,,,,,85603.85083,-56.49541794
48.4,-2.92125,1.76826,0,,,,,85992.90177,-55.23112849
48.8,-2.85453,1.77587,0,,,,,86362.98647,-53.96967504
49.2,-2.78828,1.79347,0,,,,,87218.89854,-52.71710773
49.6,-2.72156,1.79784,0,,,,,87431.41761,-51.45565428
50,-2.65438,1.81609,0,,,,,88318.94007,-50.18550376
50.4,-2.58812,1.83653,0,,,,,89312.96522,-48.93274738
50.8,-2.52172,1.86629,0,,,,,90760.23471,-47.67734406
51.2,-2.45516,1.87201,0,,,,,91038.40614,-46.41891568
51.6,-2.38797,1.86332,0,,,,,90615.79955,-45.14857609
52,-2.32141,1.88185,0,,,,,91516.93879,-43.89014771
52.4,-2.25516,1.90973,0,,,,,92872.78132,-42.6375804
52.8,-2.18844,1.91715,0,,,,,93233.62606,-41.37612694
53.2,-2.12141,1.9323,0,,,,,93970.39128,-40.10881242
53.6,-2.05438,1.93781,0,,,,,94238.35011,-38.8414979
54,-1.98828,1.94466,0,,,,,94571.47498,-37.59176659
54.4,-1.92172,1.96718,0,,,,,95666.65337,-36.33333821
54.8,-1.85469,1.96807,0,,,,,95709.93529,-35.06602369
55.2,-1.78797,1.99255,0,,,,,96900.43117,-33.80457024
55.6,-1.72156,1.9942,0,,,,,96980.67292,-32.54897786
56,-1.65531,2.01035,0,,,,,97766.06951,-31.29641054
56.4,-1.58828,2.02453,0,,,,,98455.6623,-30.02909602
56.8,-1.52125,2.03122,0,,,,,98781.00614,-28.7617815
57.2,-1.45469,2.05006,0,,,,,99697.22111,-27.50335312
57.6,-1.38844,2.05819,0,,,,,100092.5941,-26.25078581
58,-1.32156,2.06574,0,,,,,100459.7609,-24.98630729
58.4,-1.25437,2.10238,0,,,,,102241.6143,-23.7159677
58.8,-1.18813,2.09266,0,,,,,101768.9174,-22.46358946
59.2,-1.12156,2.11908,0,,,,,103053.7581,-21.20497201
59.6,-1.05469,2.12526,0,,,,,103354.2999,-19.94068255
60,-0.98766,2.14204,0,,,,,104170.3343,-18.67336803
60.4,-0.92125,2.14094,0,,,,,104116.8398,-17.41777565
60.8,-0.85516,2.16848,0,,,,,105456.1476,-16.16823341
61.2,-0.78844,2.15892,0,,,,,104991.2318,-14.90677996
61.6,-0.72141,2.17798,0,,,,,105918.1456,-13.63946544
62,-0.65469,2.21031,0,,,,,107490.3977,-12.37801199
62.4,-0.58844,2.21312,0,,,,,107627.0519,-11.12544467
62.8,-0.52172,2.22119,0,,,,,108019.507,-9.863991222
63.2,-0.45453,2.23075,0,,,,,108484.4229,-8.593651633
63.6,-0.38781,2.2382,0,,,,,108846.7266,-7.332198182
64,-0.32156,2.24053,-0.00001,,,,,108960.0377,-6.07963087
64.4,-0.25516,2.25463,0,,,,,109645.7399,-4.824227555
64.8,-0.18797,2.27217,0,,,,,110498.7341,-3.553887967
65.2,-0.12125,2.27674,0,,,,,110720.9795,-2.292434516
65.6,-0.05484,2.30067,0,,,,,111884.7281,-1.036842135
66,0.01156,2.31408,0,,,,,112536.8747,0.218561179
66.4,0.07844,2.33874,0,,,,,113736.1243,1.483039698
66.8,0.14547,2.32957,0,,,,,113290.1746,2.750354219
67.2,0.21172,2.34497,0,,,,,114039.0977,4.002921532
67.6,0.27812,2.36803,0,,,,,115160.537,5.258324846
68,0.345,2.36432,0,,,,,114980.1146,6.522803365
68.4,0.41234,2.36598,0,,,,,115060.8427,7.795978955
68.8,0.47875,2.37493,0,,,,,115496.0934,9.051571336
69.2,0.545,2.40097,0,,,,,116762.4543,10.30413865
69.6,0.61187,2.40134,0,,,,,116780.4479,11.5684281
70,0.67875,2.42951,0,,,,,118150.3935,12.83290662
70.4,0.74531,2.45355,0,,,,,119319.4915,14.091335
70.8,0.81156,2.46005,0,,,,,119635.5954,15.34390232
71.2,0.87812,2.47348,0,,,,,120288.7147,16.6023307
71.6,0.94547,2.48053,0,,,,,120631.5658,17.87569535
72,1.01203,2.49874,0,,,,,121517.143,19.13412374
72.4,1.07828,2.50315,0,,,,,121731.6074,20.38669105
72.8,1.14484,2.5188,0,,,,,122492.6883,21.64511943
73.2,1.21203,2.51968,0,,,,,122535.4839,22.91545902
73.6,1.27891,2.52571,0,,,,,122828.731,24.17993754
74,1.345,2.54552,0,,,,,123792.1184,25.42947979
74.4,1.41172,2.57124,0,,,,,125042.9172,26.69093324
74.8,1.47859,2.58033,0,,,,,125484.9763,27.95522269
75.2,1.54562,2.58755,0,,,,,125836.0948,29.22253721
75.6,1.61172,2.58497,0,,,,,125710.6259,30.47226852
76,1.67812,2.58695,0,,,,,125806.916,31.72767183
76.4,1.74516,2.60797,0,,,,,126829.1473,32.99517542
76.8,1.81203,2.62448,0,,,,,127632.0512,34.25946487
77.2,1.87844,2.64623,0,,,,,128689.7834,35.51505725
77.6,1.94469,2.64654,0,,,,,128704.8591,36.76762457
78,2.01187,2.66573,0,,,,,129638.0951,38.03777509
78.4,2.07891,2.67764,0,,,,,130217.2947,39.30527868
78.8,2.14547,2.67947,0,,,,,130306.2901,40.56370706
79.2,2.21172,2.6855,0,,,,,130599.5372,41.81627437
79.6,2.27844,2.70112,0,,,,,131359.1592,43.07772782
80,2.34547,2.72445,0,,,,,132493.729,44.34504234
80.4,2.41203,2.72262,-0.00001,,,,,132404.7336,45.60347073
80.8,2.47828,2.74309,-0.00001,,,,,133400.2177,46.85603804
81.2,2.54484,2.74651,0,,,,,133566.537,48.11446642
81.6,2.61203,2.75137,-0.00001,,,,,133802.8854,49.38480601
82,2.67859,2.7689,-0.00001,,,,,134655.3933,50.64323439
82.4,2.74484,2.78178,-0.00001,,,,,135281.7653,51.8958017
82.8,2.81156,2.7858,-0.00001,,,,,135477.2634,53.15725516
83.2,2.87859,2.79252,-0.00001,,,,,135804.0662,54.42456968
83.6,2.94547,2.79766,0,,,,,136054.0314,55.6890482
84,3.01172,2.82052,0,,,,,137165.7445,56.94161551
84.4,3.07844,2.83131,-0.00001,,,,,137690.4769,58.20306896
84.8,3.14531,2.83508,0,,,,,137873.8172,59.46735841
85.2,3.21203,2.84976,-0.00001,,,,,138587.7256,60.72881186
85.6,3.27828,2.88009,-0.00001,,,,,140062.715,61.98137917
86,3.34469,2.8797,-0.00001,,,,,140043.7488,63.23697156
86.4,3.41187,2.87971,-0.00001,,,,,140044.2351,64.50712208
86.8,3.47875,2.91387,-0.00001,,,,,141705.4826,65.7716006
87.2,3.54516,2.91122,-0.00001,,,,,141576.6095,67.02719298
87.6,3.61156,2.90879,0,,,,,141458.4353,68.28259629
88,3.67844,2.93622,0,,,,,142792.3937,69.54707481
88.4,3.74562,2.93263,0,,,,,142617.8071,70.81722533
88.8,3.81187,2.93782,0,,,,,142870.2039,72.06979265
89.2,3.87844,2.9715,0,,,,,144508.1083,73.32841009
89.6,3.94516,2.98961,0,,,,,145388.8224,74.58986355
90,4.01234,3.00948,-0.00001,,,,,146355.1276,75.86001407
90.4,4.07891,2.99887,0,,,,,145839.1488,77.11863152
90.8,4.14484,3.03076,0,,,,,147390.0031,78.36514869
91.2,4.21156,3.02225,0,,,,,146976.1502,79.62660214
91.6,4.27859,3.04045,0,,,,,147861.2411,80.89391666
92,4.34531,3.02855,0,,,,,147282.5278,82.15537012
92.4,4.41156,3.05134,0,,,,,148390.8367,83.40793743
92.8,4.47828,3.05462,0,,,,,148550.3476,84.66939088
93.2,4.54547,3.07432,0,,,,,149508.3855,85.93973047
93.6,4.61219,3.07198,0,,,,,149394.5881,87.20118392
94,4.67844,3.10392,0,,,,,150947.874,88.45375123
94.4,4.74484,3.11834,0,,,,,151649.1383,89.70915455
94.8,4.81203,3.12853,0,,,,,152144.6919,90.97949413
95.2,4.87891,3.11857,0,,,,,151660.3235,92.24397265
95.6,4.94516,3.14102,0,,,,,152752.0977,93.49653997
96,5.01156,3.1449,0,,,,,152940.7874,94.75194328
96.4,5.07844,3.14755,0,,,,,153069.6605,96.0164218
96.8,5.14531,3.17041,0,,,,,154181.3736,97.28071125
97.2,5.21172,3.18143,0,,,,,154717.2913,98.53630363
97.6,5.27812,3.17973,0,,,,,154634.6179,99.79170695
98,5.345,3.20083,0,,,,,155660.7398,101.0561855
98.4,5.41234,3.21274,0,,,,,156239.9394,102.3293611
98.8,5.47875,3.22272,0,,,,,156725.2804,103.5849534
99.2,5.54484,3.23381,0,,,,,157264.6023,104.8344957
99.6,5.61187,3.25019,0,,,,,158061.1841,106.1018102
100,5.67875,3.23943,0,,,,,157537.9106,107.3662887
100.4,5.74531,3.2376,0,,,,,157448.9152,108.6247171
100.8,5.81156,3.27697,-0.00001,,,,,159363.5321,109.8772844
101.2,5.87828,3.28432,-0.00001,,,,,159720.9727,111.1387379
101.6,5.94531,3.29545,0,,,,,160262.2398,112.4060524
102,6.01203,3.30996,0,,,,,160967.8809,113.6675058
102.4,6.07828,3.29574,0,,,,,160276.3429,114.9200732
102.8,6.14484,3.31694,-0.00001,,,,,161307.3279,116.1785015
103.2,6.21219,3.31578,-0.00001,,,,,161250.9155,117.4518662
103.6,6.27891,3.3419,0,,,,,162521.1668,118.7133196
104,6.345,3.33554,0,,,,,162211.8713,119.9628619
104.4,6.41172,3.36292,0,,,,,163543.3981,121.2243153
104.8,6.47875,3.35807,-0.00001,,,,,163307.536,122.4916299
105.2,6.54562,3.36869,-0.00001,,,,,163824.0011,123.7559193
105.6,6.61172,3.37965,0,,,,,164357.0009,125.0056506
106,6.67812,3.40399,-0.00001,,,,,165540.6884,126.2610539
106.4,6.74516,3.41717,-0.00001,,,,,166181.6498,127.5285575
106.8,6.81203,3.40842,-0.00001,,,,,165756.1254,128.792847
107.2,6.87844,3.43413,-0.00001,,,,,167006.4378,130.0484394
107.6,6.94484,3.44313,0,,,,,167444.1201,131.3038427
108,7.01187,3.44552,-0.00001,,,,,167560.3491,132.5711572
108.4,7.07875,3.4696,-0.00001,,,,,168731.3924,133.8356357
108.8,7.14531,3.47332,-0.00001,,,,,168912.3011,135.0940641
109.2,7.21172,3.47152,-0.00001,,,,,168824.7646,136.3496565
109.6,7.27844,3.50046,0,,,,,170232.1564,137.6111099
110,7.34547,3.50849,0,,,,,170622.6663,138.8784244
110.4,7.41187,3.51541,-0.00001,,,,,170959.1954,140.1338278
110.8,7.47828,3.53249,0,,,,,171789.8191,141.3894201
111.2,7.545,3.52195,0.00001,,,,,171277.2445,142.6508736
111.6,7.61203,3.5398,-0.00001,,,,,172145.3144,143.9181881
112,7.67859,3.55894,-0.00001,,,,,173076.1188,145.1766165
112.4,7.745,3.56254,-0.00001,,,,,173251.1917,146.4322089
112.8,7.81156,3.5809,-0.00001,,,,,174144.0636,147.6906373
113.2,7.87859,3.58462,-0.00001,,,,,174324.9723,148.9579518
113.6,7.94562,3.59277,-0.00001,,,,,174721.3179,150.2252663
114,8.01172,3.61125,-0.00001,,,,,175620.0256,151.4749976
114.4,8.07844,3.61156,-0.00001,,,,,175635.1013,152.7364511
114.8,8.14531,3.6256,-0.00001,,,,,176317.8857,154.0007405
115.2,8.21219,3.60978,0,,,,,175548.5375,155.265219
115.6,8.27844,3.6327,-0.00001,,,,,176663.1685,156.5177863
116,8.34469,3.63292,-0.00001,,,,,176673.8674,157.7703537
116.4,8.41187,3.65947,-0.00001,,,,,177965.0302,159.0405042
116.8,8.47875,3.67106,-0.00001,,,,,178528.6677,160.3049827
117.2,8.54515,3.68456,-0.00001,,,,,179185.1912,161.560386
117.6,8.61156,3.69744,-0.00001,,,,,179811.5632,162.8159784
118,8.67844,3.6924,-0.00001,,,,,179566.4611,164.0804569
118.4,8.74547,3.69727,-0.00001,,,,,179803.2958,165.3477714
118.8,8.81187,3.70657,-0.00001,,,,,180255.5676,166.6031747
119.2,8.87844,3.72573,-0.00001,,,,,181187.3446,167.8617922
119.6,8.94531,3.72646,-0.00001,,,,,181222.8455,169.1260816
120,9.01219,3.73865,-0.00001,,,,,181815.6618,170.3905602
120.4,9.07875,3.74557,-0.00001,,,,,182152.1909,171.6489885
120.8,9.14484,3.76376,-0.00001,,,,,183036.7955,172.8985308
121.2,9.21156,3.79215,-0.00001,,,,,184417.44,174.1599842
121.6,9.27859,3.77967,-0.00001,,,,,183810.5205,175.4272988
122,9.34531,3.79422,-0.00001,,,,,184518.1069,176.6887522
122.4,9.41156,3.79873,-0.00001,,,,,184737.4344,177.9413195
122.8,9.47828,3.81272,-0.00001,,,,,185417.7872,179.202773
123.2,9.54547,3.81649,-0.00001,,,,,185601.1275,180.4731126
123.6,9.61219,3.83048,-0.00001,,,,,186281.4803,181.734566
124,9.67844,3.831,-0.00001,,,,,186306.7686,182.9871333
124.4,9.74484,3.84936,-0.00001,,,,,187199.6405,184.2425366
124.8,9.81203,3.85405,-0.00001,,,,,187427.7216,185.5128762
125.2,9.8789,3.87721,-0.00001,,,,,188554.0241,186.7771657
125.6,9.94515,3.89576,-0.00001,,,,,189456.136,188.029733
126,10.01156,3.89785,-0.00001,,,,,189557.7755,189.2853254
126.4,10.07844,3.90918,-0.00001,,,,,190108.7689,190.5498039
126.8,10.14531,3.9071,-0.00001,,,,,190007.6157,191.8140934
127.2,10.21172,3.90778,-0.00001,,,,,190040.685,193.0696857
127.6,10.27812,3.91903,-0.00001,,,,,190587.7879,194.325089
128,10.345,3.92453,-0.00001,,,,,190855.2604,195.5895676
128.4,10.41219,3.95292,-0.00001,,,,,192235.9049,196.8599072
128.8,10.47875,3.95517,-0.00001,,,,,192345.3255,198.1183355
129.2,10.545,3.96477,-0.00001,,,,,192812.1866,199.3709029
129.6,10.61187,3.9784,-0.00001,,,,,193475.0322,200.6351923
130,10.67875,3.99866,-0.00001,,,,,194460.3037,201.8996708
130.4,10.74531,3.97518,-0.00001,,,,,193318.4392,203.1580992
130.8,10.81156,3.98626,-0.00001,,,,,193857.2747,204.4106665
131.2,10.87812,4.01101,-0.00001,,,,,195060.9011,205.6690949
131.6,10.94531,4.01233,-0.00001,,,,,195125.0945,206.9394345
132,11.01203,4.01789,-0.00001,,,,,195395.4849,208.2008879
132.4,11.07828,4.03728,-0.00001,,,,,196338.4471,209.4534553
132.8,11.145,4.05196,-0.00001,,,,,197052.3556,210.7149087
133.2,11.21203,4.04199,-0.00001,,,,,196567.5008,211.9822232
133.6,11.2789,4.05472,-0.00001,,,,,197186.5781,213.2465127
134,11.345,4.07575,-0.00001,,,,,198209.2958,214.496244
134.4,11.41172,4.09639,-0.00001,,,,,199213.0472,215.7576974
134.8,11.47875,4.08799,-0.00001,,,,,198804.5437,217.025012
135.2,11.54562,4.0828,-0.00001,,,,,198552.1469,218.2893014
135.6,11.61172,4.12165,-0.00001,,,,,200441.4756,219.5390327
136,11.67812,4.1194,-0.00001,,,,,200332.055,220.794436
136.4,11.74516,4.10974,-0.00001,,,,,199862.276,222.0619396
136.8,11.81203,4.14784,-0.00001,,,,,201715.1311,223.3262291
137.2,11.87844,4.16914,-0.00001,,,,,202750.9792,224.5818215
137.6,11.94484,4.15854,-0.00001,,,,,202235.4867,225.8372248
138,12.01187,4.16805,-0.00001,,,,,202697.971,227.1045393
138.4,12.0789,4.17115,-0.00001,,,,,202848.7282,228.3718538
138.8,12.14547,4.18124,-0.00001,,,,,203339.4187,229.6304713
139.2,12.21156,4.20688,-0.00001,,,,,204586.327,230.8800135
139.6,12.27844,4.21262,-0.00001,,,,,204865.471,232.144492
140,12.34547,4.21603,-0.00001,,,,,205031.304,233.4118065
140.4,12.41187,4.22483,-0.00001,,,,,205459.26,234.6672099
140.8,12.47828,4.21525,-0.00001,,,,,204993.3715,235.9228022
141.2,12.54484,4.24171,-0.00001,,,,,206280.1575,237.1812306
141.6,12.61203,4.26507,-0.00001,,,,,207416.1863,238.4515702
142,12.67859,4.23941,-0.00001,,,,,206168.3054,239.7099986
142.4,12.74484,4.272,-0.00001,,,,,207753.2016,240.9625659
142.8,12.81156,4.267,-0.00001,,,,,207510.0448,242.2240194
143.2,12.87859,4.283,-0.00001,,,,,208288.1467,243.4913339
143.6,12.94562,4.29153,-0.00001,,,,,208702.9723,244.7586484
144,13.01172,4.30238,-0.00001,,,,,209230.6226,246.0083797
144.4,13.07843,4.3191,-0.00001,,,,,210043.7391,247.2696441
144.8,13.14531,4.32485,-0.00001,,,,,210323.3694,248.5341226
145.2,13.21218,4.33478,-0.00001,,,,,210806.2789,249.7984121
145.6,13.27828,4.34395,-0.00001,,,,,211252.2285,251.0481434
146,13.34469,4.34865,-0.00001,,,,,211480.796,252.3037358
146.4,13.41187,4.36202,-0.00001,,,,,212130.9973,253.5738863
146.8,13.47875,4.35321,-0.00001,,,,,211702.555,254.8383648
147.2,13.54515,4.36318,-0.00001,,,,,212187.4097,256.0937681
147.6,13.61156,4.39268,-0.00001,,,,,213622.0351,257.3493605
148,13.67844,4.39509,-0.00001,,,,,213739.2367,258.613839
148.4,13.74547,4.4134,-0.00001,,,,,214629.677,259.8811535
148.8,13.81187,4.41015,-0.00001,,,,,214471.6251,261.1365568
149.2,13.87844,4.42422,-0.00001,,,,,215155.8684,262.3951743
149.6,13.94516,4.42738,-0.00001,,,,,215309.5435,263.6566277
150,14.01219,4.43044,-0.00001,,,,,215458.3555,264.9239423
150.4,14.07875,4.43198,-0.00001,,,,,215533.2478,266.1823706
150.8,14.14484,4.45769,-0.00001,,,,,216783.5603,267.4319129
151.2,14.21172,4.48571,-0.00001,,,,,218146.2112,268.6963914
151.6,14.27859,4.47127,-0.00001,,,,,217443.9742,269.9606809
152,14.34547,4.47865,-0.00001,,,,,217802.8737,271.2251594
152.4,14.41156,4.4977,-0.00001,,,,,218729.3013,272.4747016
152.8,14.47828,4.50011,-0.00001,,,,,218846.5029,273.7361551
153.2,14.54547,4.51723,-0.00001,,,,,219679.0719,275.0064947
153.6,14.61219,4.51423,-0.00001,,,,,219533.1778,276.2679481
154,14.67844,4.53274,-0.00001,,,,,220433.3444,277.5205154
154.4,14.745,4.53096,-0.00001,,,,,220346.7806,278.7789438
154.8,14.81203,4.55588,-0.00001,,,,,221558.6742,280.0462583
155.2,14.87875,4.55758,-0.00001,,,,,221641.3476,281.3077118
155.6,14.945,4.56285,-0.00001,,,,,221897.6349,282.5602791
156,15.01156,4.58652,-0.00001,,,,,223048.7393,283.8187075
156.4,15.07844,4.58655,-0.00001,,,,,223050.1983,285.083186
156.8,15.14547,4.60203,-0.00001,,,,,223803.0118,286.3505005
157.2,15.21172,4.60726,-0.00001,,,,,224057.3539,287.6030678
157.6,15.27812,4.60942,-0.00001,,,,,224162.3976,288.8584711
158,15.34515,4.6194,-0.00001,,,,,224647.7387,290.1257857
158.4,15.41234,4.6281,-0.00001,,,,,225070.8316,291.3961253
158.8,15.47875,4.61739,-0.00001,,,,,224549.9896,292.6517176
159.2,15.54484,4.66041,-0.00001,,,,,226642.1111,293.9012599
159.6,15.61187,4.65914,-0.00001,,,,,226580.3492,295.1685744
160,15.67875,4.66491,-0.00001,,,,,226860.9522,296.4330529
160.4,15.74531,4.6551,-0.00001,,,,,226383.8785,297.6914813
160.8,15.81156,4.69645,-0.00001,,,,,228394.7856,298.9440486
161.2,15.87828,4.68821,-0.00001,,,,,227994.0631,300.2055021
161.6,15.94531,4.68747,-0.00001,,,,,227958.0759,301.4728166
162,16.01203,4.71915,-0.00001,,,,,229498.7176,302.73427
162.4,16.07828,4.72484,-0.00001,,,,,229775.4301,303.9868374
162.8,16.14484,4.72005,-0.00001,,,,,229542.4858,305.2452657
163.2,16.21203,4.72087,-0.00001,,,,,229582.3635,306.5156053
163.6,16.2789,4.75233,-0.00001,,,,,231112.3064,307.7798948
164,16.345,4.75883,-0.00001,,,,,231428.4103,309.0296261
164.4,16.41172,4.76448,-0.00001,,,,,231703.1775,310.2910795
164.8,16.47875,4.77337,-0.00001,,,,,232135.5103,311.5583941
165.2,16.54562,4.77939,-0.00001,,,,,232428.2712,312.8226835
165.6,16.61172,4.79559,-0.00001,,,,,233216.0993,314.0724148
166,16.67812,4.77723,-0.00001,,,,,232323.2274,315.3278181
166.4,16.74515,4.81593,-0.00001,,,,,234205.2613,316.5951327
166.8,16.81203,4.81099,-0.00001,,,,,233965.0224,317.8596112
167.2,16.87843,4.81825,-0.00001,,,,,234318.0861,319.1150145
167.6,16.94484,4.83577,-0.00001,,,,,235170.1077,320.3706069
168,17.01187,4.8567,-0.00001,,,,,236187.9622,321.6379214
168.4,17.0789,4.84731,-0.00001,,,,,235731.3136,322.9052359
168.8,17.14547,4.85888,-0.00001,,,,,236293.9786,324.1638534
169.2,17.21172,4.8601,-0.00001,,,,,236353.3088,325.4164207
169.6,17.27843,4.87129,-0.00001,,,,,236897.4938,326.6776851
170,17.34547,4.87905,-0.00001,,,,,237274.8732,327.9451886
170.4,17.41203,4.89856,-0.00001,,,,,238223.6712,329.203617
170.8,17.47828,4.89976,-0.00001,,,,,238282.0289,330.4561843
171.2,17.545,4.9353,-0.00001,,,,,240010.3877,331.7176378
171.6,17.61203,4.90603,-0.00001,,,,,238586.9475,332.9849523
172,17.67859,4.92317,-0.00001,,,,,239420.4892,334.2433807
172.4,17.74484,4.94222,-0.00001,,,,,240346.9167,335.495948
172.8,17.81156,4.94003,-0.00001,,,,,240240.414,336.7574015
173.2,17.87859,4.93483,-0.00001,,,,,239987.5309,338.024716
173.6,17.94547,4.96491,-0.00001,,,,,241450.3624,339.2891945
174,18.01171,4.95937,-0.00001,,,,,241180.9447,340.5415727
174.4,18.07828,4.9758,-0.00001,,,,,241979.958,341.8001902
174.8,18.14531,4.98534,-0.00001,,,,,242443.9013,343.0675047
175.2,18.21218,5.00468,-0.00001,,,,,243384.4319,344.3317942
175.6,18.27843,5.00236,-0.00001,,,,,243271.6072,345.5843615
176,18.34468,4.99311,-0.00001,,,,,242821.767,346.8369288
176.4,18.41171,5.00512,-0.00001,,,,,243405.8297,348.1042433
176.8,18.47875,5.02774,-0.00001,,,,,244505.8713,349.3717469
177.2,18.54531,5.02751,-0.00001,,,,,244494.6861,350.6301753
177.6,18.61156,5.02784,-0.00001,,,,,244510.7344,351.8827426
178,18.67828,5.05923,-0.00001,,,,,246037.273,353.144196
178.4,18.74562,5.05736,-0.00001,,,,,245946.3324,354.4173716
178.8,18.81187,5.06107,-0.00001,,,,,246126.7547,355.6699389
179.2,18.87828,5.07941,-0.00001,,,,,247018.654,356.9255313
179.6,18.94515,5.12328,-0.00001,,,,,249152.1121,358.1898208
180,19.01218,5.10693,-0.00001,,,,,248356.9893,359.4571353
180.4,19.0789,5.0984,-0.00001,,,,,247942.1637,360.7185888
180.8,19.14484,5.11481,-0.00001,,,,,248740.2044,361.965295
181.2,19.21172,5.12635,-0.00001,,,,,249301.4104,363.2297735
181.6,19.27859,5.12746,-0.00001,,,,,249355.3912,364.494063
182,19.34547,5.12733,-0.00001,,,,,249349.0691,365.7585415
182.4,19.41156,5.16206,-0.00001,,,,,251038.0365,367.0080837
182.8,19.47828,5.16155,-0.00001,,,,,251013.2345,368.2695372
183.2,19.54547,5.15004,-0.00001,,,,,250453.4875,369.5398768
183.6,19.61218,5.16808,-0.00001,,,,,251330.7974,370.8011412
184,19.67843,5.18902,-0.00001,,,,,252349.1382,372.0537085
184.4,19.74484,5.21118,-0.00001,,,,,253426.8093,373.3093008
184.8,19.81203,5.19072,-0.00001,,,,,252431.8115,374.5796404
185.2,19.87875,5.22332,-0.00001,,,,,254017.1941,375.8410939
185.6,19.945,5.21873,-0.00001,,,,,253793.9761,377.0936612
186,20.01156,5.23554,-0.00001,,,,,254611.4694,378.3520896
186.4,20.07843,5.23062,-0.00001,,,,,254372.2031,379.616379
186.8,20.14531,5.24029,-0.00001,,,,,254842.4684,380.8808576
187.2,20.21172,5.22705,-0.00001,,,,,254198.5891,382.1364499
187.6,20.27812,5.26194,-0.00001,,,,,255895.3375,383.3918532
188,20.345,5.26953,-0.00001,,,,,256264.4496,384.6563318
188.4,20.41218,5.286,-0.00001,,,,,257065.4082,385.9264823
188.8,20.47875,5.28269,-0.00001,,,,,256904.4384,387.1850997
189.2,20.545,5.31885,-0.00001,,,,,258662.9486,388.4376671
189.6,20.61187,5.30965,-0.00001,,,,,258215.5401,389.7019565
190,20.67875,5.30895,-0.00001,,,,,258181.4981,390.966435
190.4,20.74531,5.31423,-0.00001,,,,,258438.2717,392.2248634
190.8,20.81156,5.31737,-0.00001,,,,,258590.9742,393.4774307
191.2,20.87828,5.33056,-0.00001,,,,,259232.4219,394.7388842
191.6,20.94531,5.3406,-0.00001,,,,,259720.6809,396.0061987
192,21.01187,5.34025,-0.00001,,,,,259703.6599,397.2646271
192.4,21.07828,5.37577,-0.00001,,,,,261431.0461,398.5202195
192.8,21.145,5.3812,-0.00001,,,,,261695.1144,399.7816729
193.2,21.21218,5.36849,-0.00001,,,,,261077.0097,401.0518234
193.6,21.2789,5.38504,-0.00001,,,,,261881.8588,402.3132769
194,21.345,5.39946,-0.00002,,,,,262583.1232,403.5630082
194.4,21.41171,5.41036,-0.00002,,,,,263113.2051,404.8242726
194.8,21.47875,5.41927,-0.00001,,,,,263546.5106,406.0917762
195.2,21.54562,5.42521,-0.00001,,,,,263835.3809,407.3560656
195.6,21.61172,5.43552,-0.00001,,,,,264336.7703,408.6057969
196,21.67812,5.45402,-0.00001,,,,,265236.4506,409.8612002
196.4,21.74515,5.44629,-0.00001,,,,,264860.5301,411.1285148
196.8,21.81203,5.45198,-0.00001,,,,,265137.2426,412.3929933
197.2,21.87828,5.46539,-0.00001,,,,,265789.3892,413.6455606
197.6,21.94484,5.48862,-0.00001,,,,,266919.0959,414.903989
198,22.01187,5.49335,-0.00001,,,,,267149.1223,416.1713035
198.4,22.07875,5.50488,-0.00001,,,,,267709.8419,417.435782
198.8,22.14547,5.49383,-0.00001,,,,,267172.4653,418.6972355
199.2,22.21172,5.51861,-0.00001,,,,,268377.5506,419.9498028
199.6,22.27843,5.53118,-0.00001,,,,,268988.8469,421.2110672
200,22.34546,5.52465,-0.00001,,,,,268671.2841,422.4783817
200.4,22.41203,5.52889,-0.00001,,,,,268877.4811,423.7369991
200.8,22.47828,5.5457,-0.00001,,,,,269694.9743,424.9895664
201.2,22.545,5.5713,-0.00001,,,,,270939.9373,426.2510199
201.6,22.61203,5.56678,-0.00001,,,,,270720.1236,427.5183344
202,22.67859,5.5694,-0.00001,,,,,270847.5377,428.7767628
202.4,22.74484,5.5731,-0.00001,,,,,271027.4738,430.0293301
202.8,22.81156,5.5902,-0.00001,,,,,271859.0702,431.2907836
203.2,22.87859,5.60564,-0.00001,,,,,272609.9385,432.5580981
203.6,22.94562,5.60248,-0.00001,,,,,272456.2634,433.8254126
204,23.01172,5.61822,-0.00001,,,,,273221.7211,435.0751439
204.4,23.07843,5.62273,-0.00001,,,,,273441.0486,436.3364083
204.8,23.14531,5.65195,-0.00001,,,,,274862.0571,437.6008868
205.2,23.21218,5.63092,-0.00001,,,,,273839.3395,438.8651763
205.6,23.27843,5.66852,-0.00001,,,,,275667.8789,440.1177436
206,23.34484,5.66377,-0.00001,,,,,275436.8799,441.373336
206.4,23.41171,5.68211,-0.00001,,,,,276328.7792,442.6376254
206.8,23.47875,5.66652,-0.00001,,,,,275570.6161,443.905129
207.2,23.54515,5.68688,-0.00001,,,,,276560.7508,445.1605323
207.6,23.61156,5.69167,-0.00001,,,,,276793.695,446.4161247
208,23.67843,5.69966,-0.00001,,,,,277182.2597,447.6804141
208.4,23.74547,5.72705,-0.00001,,,,,278514.2728,448.9479177
208.8,23.81187,5.71216,-0.00001,,,,,277790.1518,450.203321
209.2,23.87844,5.7288,-0.00001,,,,,278599.3777,451.4619385
209.6,23.94515,5.74133,-0.00001,,,,,279208.7287,452.7232029
210,24.01234,5.75912,-0.00001,,,,,280073.8808,453.9935425
210.4,24.07875,5.73979,-0.00001,,,,,279133.8364,455.2491349
210.8,24.14484,5.75514,-0.00001,,,,,279880.3279,456.4986771
211.2,24.21172,5.77669,-0.00001,,,,,280928.3339,457.7631556
211.6,24.27859,5.78919,-0.00001,,,,,281536.226,459.0274451
212,24.34531,5.78641,-0.00001,,,,,281401.0308,460.2888985
212.4,24.41156,5.78224,-0.00001,,,,,281198.238,461.5414658
212.8,24.47828,5.80302,-0.00001,,,,,282208.7978,462.8029193
213.2,24.54547,5.81076,-0.00001,,,,,282585.2046,464.0732589
213.6,24.61218,5.82287,-0.00001,,,,,283174.1304,465.3345233
214,24.67843,5.83868,-0.00001,,,,,283942.9924,466.5870906
214.4,24.745,5.83359,-0.00001,,,,,283695.4587,467.845708
214.8,24.81203,5.8414,-0.00002,,,,,284075.2697,469.1130225
215.2,24.87875,5.83031,-0.00001,,,,,283535.9478,470.374476
215.6,24.94515,5.86727,-0.00001,,,,,285333.3632,471.6298793
216,25.01156,5.86369,-0.00001,,,,,285159.2629,472.8854717
216.4,25.07843,5.88341,-0.00001,,,,,286118.2734,474.1497611
216.8,25.14531,5.88938,-0.00001,,,,,286408.6027,475.4142397
217.2,25.21172,5.89736,-0.00001,,,,,286796.681,476.669832
217.6,25.27828,5.91697,-0.00001,,,,,287750.3421,477.9282604
218,25.345,5.91198,-0.00001,,,,,287507.6716,479.1897139
218.4,25.41218,5.92586,-0.00001,,,,,288182.675,480.4598644
218.8,25.47875,5.92148,-0.00001,,,,,287969.6696,481.7184818
219.2,25.545,5.93545,-0.00001,,,,,288649.0498,482.9710492
219.6,25.61187,5.94225,-0.00001,,,,,288979.7431,484.2353386
220,25.67875,5.94887,-0.00001,,,,,289301.6827,485.4998171
220.4,25.74531,5.95416,-0.00001,,,,,289558.9427,486.7582455
220.8,25.81156,5.97586,-0.00002,,,,,290614.2433,488.0108128
221.2,25.87828,5.97509,-0.00001,,,,,290576.7972,489.2722663
221.6,25.94531,5.98568,-0.00001,,,,,291091.8034,490.5395808
222,26.01187,6.00379,-0.00001,,,,,291972.5174,491.7980092
222.4,26.07828,6.00295,-0.00001,,,,,291931.6671,493.0536016
222.8,26.14484,6.00736,-0.00001,,,,,292146.1314,494.3120299
223.2,26.21203,6.03112,-0.00001,,,,,293301.6127,495.5823695
223.6,26.2789,6.02142,-0.00001,,,,,292829.8884,496.846659
224,26.345,6.06023,-0.00001,,,,,294717.2718,498.0963903
224.4,26.41172,6.04019,-0.00001,,,,,293742.6992,499.3578437
224.8,26.47875,6.0498,-0.00001,,,,,294210.0467,500.6251583
225.2,26.54562,6.07511,-0.00001,,,,,295440.9066,501.8894477
225.6,26.61172,6.06466,-0.00001,,,,,294932.7088,503.139179
226,26.67812,6.07483,-0.00001,,,,,295427.2898,504.3945823
226.4,26.74515,6.08565,-0.00001,,,,,295953.4812,505.6618969
226.8,26.81203,6.10235,-0.00001,,,,,296765.625,506.9263754
227.2,26.87843,6.11125,-0.00001,,,,,297198.4442,508.1817787
227.6,26.94484,6.09786,-0.00001,,,,,296547.2702,509.4373711
228,27.01187,6.11989,-0.00001,,,,,297618.6192,510.7046856
228.4,27.07875,6.12311,-0.00001,,,,,297775.2122,511.9691641
228.8,27.14547,6.1323,-0.00001,,,,,298222.1345,513.2306176
229.2,27.21171,6.13805,-0.00001,,,,,298501.7648,514.4829958
229.6,27.27843,6.14019,-0.00001,,,,,298605.836,515.7444493
230,27.34546,6.17726,-0.00001,,,,,300408.6007,517.0117638
230.4,27.41187,6.16528,-0.00001,,,,,299825.997,518.2673562
230.8,27.47828,6.17148,-0.00001,,,,,300127.5114,519.5229485
231.2,27.54484,6.156,-0.00002,,,,,299374.6979,520.7813769
231.6,27.61203,6.25658,-0.00002,,,,,304266.0408,522.0517165
232,27.67859,6.20375,-0.00009,,,,,301696.8457,523.3101449
232.4,27.74484,6.21776,-0.00001,,,,,302378.1711,524.5627122
232.8,27.81156,6.23075,-0.00002,,,,,303009.8926,525.8241657
233.2,27.87859,6.22595,-0.00002,,,,,302776.462,527.0914802
233.6,27.94562,6.30461,-0.00002,,,,,306601.8054,528.3587947
234,28.01171,6.2242,0.00001,,,,,302691.3571,529.6083369
234.4,28.07843,6.25105,-0.00001,,,,,303997.1094,530.8697904
234.8,28.14547,6.25046,-0.00003,,,,,303968.4168,532.137294
235.2,28.21218,6.23342,-0.00003,,,,,303139.7383,533.3985584
235.6,28.27828,6.30586,-0.00002,,,,,306662.5946,534.6482897
236,28.34468,6.2749,-0.00001,,,,,305156.9675,535.903693
236.4,28.41187,6.30999,-0.00001,,,,,306863.4421,537.1740326
236.8,28.47875,6.33013,-0.00001,,,,,307842.8779,538.4385111
237.2,28.54515,6.30006,-0.00001,,,,,306380.5327,539.6939144
237.6,28.61172,6.33943,-0.00001,,,,,308295.1496,540.9525319
238,28.67843,6.35463,-0.00001,,,,,309034.3464,542.2137962
238.4,28.74546,6.33485,-0.00001,,,,,308072.4179,543.4811108
238.8,28.81187,6.35057,-0.00002,,,,,308836.903,544.7367031
239.2,28.87828,6.36859,-0.00002,,,,,309713.2403,545.9922955
239.6,28.94515,6.38131,-0.00001,,,,,310331.8313,547.256585
240,29.01218,6.36802,-0.00001,,,,,309685.5204,548.5238995
240.4,29.07875,6.36918,-0.00002,,,,,309741.9328,549.782517
240.8,29.145,6.4113,-0.00002,,,,,311790.286,551.0350843
241.2,29.21156,6.40807,-0.00001,,,,,311633.2067,552.2935126
241.6,29.27859,6.41643,-0.00001,,,,,312039.7649,553.5608272
242,29.34547,6.41818,-0.00001,,,,,312124.8698,554.8253057
242.4,29.41156,6.4242,-0.00001,,,,,312417.6306,556.0748479
242.8,29.47843,6.45984,-0.00001,,,,,314150.8526,557.3391374
243.2,29.54547,6.44845,-0.00001,,,,,313596.9413,558.606641
243.6,29.61218,6.44217,-0.00001,,,,,313291.5363,559.8679054
244,29.67843,6.45219,-0.00002,,,,,313778.8226,561.1204727
244.4,29.74484,6.48127,-0.00001,,,,,315193.0228,562.376065
244.8,29.81203,6.4768,0.00001,,,,,314975.6405,563.6464046
245.2,29.87875,6.47627,-0.00002,,,,,314949.8659,564.9078581
245.6,29.94515,6.4966,-0.00001,,,,,315938.5416,566.1632614
246,30.01156,6.50062,-0.00002,,,,,316134.0397,567.4188538
246.4,30.07843,6.5139,-0.00001,,,,,316779.8643,568.6831432
246.8,30.14546,6.50949,-0.00002,,,,,316565.3999,569.9504578
247.2,30.21172,6.53007,-0.00001,,,,,317566.2335,571.2032141
247.6,30.27828,6.53722,-0.00001,,,,,317913.9478,572.4616425
248,30.345,6.5376,-0.00003,,,,,317932.4277,573.723096
248.4,30.41218,6.5386,-0.00003,,,,,317981.0591,574.9932465
248.8,30.47859,6.55265,-0.00002,,,,,318664.3298,576.2488389
249.2,30.54484,6.5626,-0.00001,,,,,319148.2119,577.5014062
249.6,30.61187,6.58858,0,,,,,320411.6548,578.7687207
250,30.67875,6.59872,0,,,,,320904.7769,580.0331992
250.4,30.74531,6.62308,-0.00001,,,,,322089.437,581.2916276
250.8,30.81156,6.61232,-0.00002,,,,,321566.1635,582.5441949
251.2,30.87828,6.60877,-0.00002,,,,,321393.5221,583.8056484
251.6,30.94531,6.63784,-0.00001,,,,,322807.236,585.0729629
252,31.01203,6.63331,-0.00001,,,,,322586.9359,586.3344163
252.4,31.07828,6.64184,-0.00001,,,,,323001.7614,587.5869837
252.8,31.145,6.65037,-0.00001,,,,,323416.587,588.8484371
253.2,31.21218,6.65914,-0.00001,,,,,323843.0841,590.1185876
253.6,31.2789,6.70215,-0.00003,,,,,325934.7192,591.3800411
254,31.345,6.67394,-0.00002,,,,,324562.8283,592.6297724
254.4,31.41171,6.70239,-0.00001,,,,,325946.3907,593.8910368
254.8,31.47874,6.7119,-0.00003,,,,,326408.875,595.1583513
255.2,31.54562,6.70543,-0.00003,,,,,326094.2301,596.4228298
255.6,31.61171,6.67553,-0.00002,,,,,324640.1522,597.6723721
256,31.67812,6.96996,0.00001,,,,,338958.6857,598.9279644
256.4,31.74515,6.88582,0.00046,,,,,334866.8425,600.195279
256.8,31.81202,6.76248,0.00003,,,,,328868.6496,601.4595684
257.2,31.87843,6.73009,0.00003,,,,,327293.4796,602.7151608
257.6,31.94484,6.75235,0,,,,,328376.0138,603.9707532
258,32.01187,6.77603,0,,,,,329527.6046,605.2380677
258.4,32.07874,6.76497,-0.00001,,,,,328989.7417,606.5023571
258.8,32.14546,6.7929,-0.00001,,,,,330348.0158,607.7638106
259.2,32.21171,6.78669,0,,,,,330046.015,609.0163779
259.6,32.27843,6.8235,-0.00001,,,,,331836.1356,610.2778314
260,32.34546,6.79878,-0.00002,,,,,330633.9682,611.5451459
260.4,32.41187,6.81247,-0.00001,,,,,331299.7317,612.8007383
260.8,32.47828,6.82076,-0.00001,,,,,331702.8857,614.0563306
261.2,32.54484,6.86481,-0.00001,,,,,333845.0974,615.314759
261.6,32.61203,6.84339,-0.00001,,,,,332803.4135,616.5850986
262,32.67874,6.84201,-0.00001,,,,,332736.3022,617.846363
262.4,32.74499,6.85297,-0.00001,,,,,333269.302,619.0989303
262.8,32.81156,6.86676,0,,,,,333939.9286,620.3575478
263.2,32.87859,6.88626,0,,,,,334888.2403,621.6248623
263.6,32.94562,6.86628,-0.00002,,,,,333916.5855,622.8921768
264,33.01171,6.90713,0.00002,,,,,335903.1769,624.141719
264.4,33.07827,6.93681,0.00014,,,,,337346.5559,625.4001474
264.8,33.14546,6.93346,0.00002,,,,,337183.6408,626.670487
265.2,33.21218,6.91934,0,,,,,336496.9659,627.9319405
265.6,33.27843,6.92735,0,,,,,336886.5031,629.1845078
266,33.34468,6.91449,0,,,,,336261.1038,630.4370751
266.4,33.41187,6.96563,-0.00001,,,,,338748.1119,631.7074147
266.8,33.47874,6.95005,-0.00001,,,,,337990.4352,632.9717041
267.2,33.54515,6.94095,0,,,,,337547.8897,634.2272965
267.6,33.61155,6.95154,-0.00001,,,,,338062.8959,635.4826998
268,33.67828,6.97619,-0.00001,,,,,339261.6591,636.7443423
268.4,33.74546,6.99102,-0.00001,,,,,339982.8623,638.0144929
268.8,33.81187,6.9948,-0.00001,,,,,340166.6889,639.2700852
269.2,33.87843,7.01128,-0.00001,,,,,340968.1338,640.5285136
269.6,33.94515,7.02422,-0.00001,,,,,341597.4237,641.7899671
270,34.01218,7.01473,-0.00001,,,,,341135.912,643.0572816
270.4,34.07874,7.03217,-0.00001,,,,,341984.0431,644.31571
270.8,34.14484,7.02396,-0.00001,,,,,341584.7795,645.5654413
271.2,34.21156,7.06688,-0.00001,,,,,343672.0378,646.8268947
271.6,34.27859,7.05276,-0.00001,,,,,342985.3629,648.0942093
272,34.34531,7.07288,-0.00001,,,,,343963.826,649.3556627
272.4,34.41171,7.07818,-0.00001,,,,,344221.5723,650.611066
272.8,34.47827,7.1035,-0.00001,,,,,345452.9185,651.8694944
273.2,34.54546,7.09901,0,,,,,345234.5637,653.139834
273.6,34.61218,7.09734,-0.00001,,,,,345153.3493,654.4012875
274,34.67843,7.11967,-0.00001,,,,,346239.2877,655.6538548
274.4,34.74483,7.11148,0,,,,,345840.9968,656.9092581
274.8,34.81203,7.13789,0,,,,,347125.3512,658.1797867
275.2,34.87874,7.145,-0.00001,,,,,347471.1203,659.4410511
275.6,34.94499,7.14237,-0.00001,,,,,347343.2198,660.6936184
276,35.01155,7.16347,0,,,,,348369.3416,661.9520468
276.4,35.07843,7.16326,0,,,,,348359.129,663.2165253
276.8,35.14546,7.17606,0,,,,,348981.6105,664.4838399
277.2,35.21171,7.18099,-0.00001,,,,,349221.3632,665.7364072
277.6,35.27812,7.19672,-0.00001,,,,,349986.3346,666.9919995
278,35.34515,7.22341,-0.00001,,,,,351284.3058,668.2593141
278.4,35.41218,7.21617,0,,,,,350932.2147,669.5266286
278.8,35.47874,7.21613,0,,,,,350930.2694,670.785057
279.2,35.54499,7.22457,0,,,,,351340.7182,672.0376243
279.6,35.61187,7.23954,0,,,,,352068.7297,673.3021028
280,35.67875,7.23919,0,,,,,352051.7088,674.5665813
280.4,35.74531,7.26787,0,,,,,353446.4564,675.8250097
280.8,35.81155,7.26777,-0.00001,,,,,353441.5932,677.077388
281.2,35.87827,7.26983,-0.00001,,,,,353541.7739,678.3388414
281.6,35.94531,7.29038,-0.00001,,,,,354541.1485,679.606345
282,36.01202,7.30532,0,,,,,355267.7011,680.8676094
282.4,36.07827,7.283,-0.00001,,,,,354182.249,682.1201767
282.8,36.14484,7.29007,0,,,,,354526.0727,683.3787941
283.2,36.21202,7.33135,-0.00001,,,,,356533.5756,684.6489447
283.6,36.27874,7.32858,-0.00001,,,,,356398.8667,685.9103981
284,36.34499,7.34112,-0.00001,,,,,357008.704,687.1629654
284.4,36.41171,7.34755,-0.00001,,,,,357321.4037,688.4244189
284.8,36.47874,7.37918,-0.00001,,,,,358859.6139,689.6917334
285.2,36.54546,7.35871,0,,,,,357864.1298,690.9531868
285.6,36.61171,7.37482,-0.00001,,,,,358647.5811,692.2057542
286,36.67827,7.37206,-0.00001,,,,,358513.3586,693.4641825
286.4,36.74515,7.37263,-0.00001,,,,,358541.0784,694.7286611
286.8,36.81203,7.37999,-0.00001,,,,,358899.0053,695.9931396
287.2,36.87843,7.415,-0.00001,,,,,360601.5895,697.2485429
287.6,36.94484,7.41773,-0.00001,,,,,360734.3531,698.5041353
288,37.01187,7.43749,-0.00001,,,,,361695.3089,699.7714498
288.4,37.07874,7.43391,0,,,,,361521.2086,701.0357392
288.8,37.14546,7.43596,-0.00001,,,,,361620.9029,702.2971927
289.2,37.21171,7.45301,-0.00001,,,,,362450.0677,703.54976
289.6,37.27843,7.46894,-0.00001,,,,,363224.7654,704.8112135
290,37.34546,7.47386,-0.00001,,,,,363464.0318,706.078528
290.4,37.41203,7.4777,-0.00001,,,,,363650.7762,707.3371454
290.8,37.47843,7.4971,-0.00001,,,,,364594.2247,708.5925487
291.2,37.54483,7.50152,-0.00001,,,,,364809.1754,709.8479521
291.6,37.61203,7.49814,-0.00001,,,,,364644.8014,711.1184807
292,37.67859,7.50546,-0.00001,,,,,365000.783,712.3769091
292.4,37.74484,7.53868,0,,,,,366616.317,713.6294764
292.8,37.81155,7.51766,-0.00001,,,,,365594.0856,714.8907408
293.2,37.87859,7.54439,-0.00001,,,,,366894.0021,716.1582444
293.6,37.94562,7.55986,-0.00001,,,,,367646.3294,717.4255589
294,38.01171,7.59055,-0.00001,,,,,369138.826,718.6751011
294.4,38.07843,7.5842,-0.00001,,,,,368830.0168,719.9365546
294.8,38.14546,7.57301,-0.00001,,,,,368285.8318,721.2038691
295.2,38.21218,7.5871,-0.00001,,,,,368971.0478,722.4653226
295.6,38.27827,7.59937,-0.00001,,,,,369567.7547,723.7148648
296,38.34468,7.62484,-0.00001,,,,,370806.3956,724.9704572
296.4,38.41187,7.63409,-0.00001,,,,,371256.2358,726.2407968
296.8,38.47874,7.62869,-0.00001,,,,,370993.6264,727.5050862
297.2,38.54515,7.64313,-0.00001,,,,,371695.8633,728.7606786
297.6,38.61156,7.64394,-0.00001,,,,,371735.2547,730.016271
298,38.67843,7.65936,0,,,,,372485.1504,731.2805604
298.4,38.74546,7.68644,-0.00001,,,,,373802.0878,732.547875
298.8,38.81187,7.6773,-0.00001,,,,,373357.5971,733.8034673
299.2,38.87843,7.66922,-0.00001,,,,,372964.6557,735.0618957
299.6,38.94515,7.70382,-0.00001,,,,,374647.301,736.3233492
300,39.01218,7.70586,-0.00001,,,,,374746.509,737.5906637
300.4,39.0789,7.70509,-0.00001,,,,,374709.0628,738.8521172
300.8,39.14484,7.73927,-0.00001,,,,,376371.283,740.0988234
301.2,39.21156,7.71311,0,,,,,375099.0864,741.3602768
301.6,39.27859,7.74696,-0.00001,,,,,376745.2582,742.6275914
302,39.34531,7.75103,0,,,,,376943.1879,743.8890448
302.4,39.41156,7.76386,0,,,,,377567.1283,745.1416121
302.8,39.47843,7.77118,0,,,,,377923.1099,746.4059016
303.2,39.5453,7.77991,0,,,,,378347.6618,747.670191
303.6,39.61218,7.77744,0,,,,,378227.5423,748.9346696
304,39.67843,7.80514,0,,,,,379574.6312,750.1872369
304.4,39.74499,7.80321,0,,,,,379480.7726,751.4456653
304.8,39.81202,7.80895,0,,,,,379759.9167,752.7129798
305.2,39.87875,7.82419,0,,,,,380501.0587,753.9746223
305.6,39.94515,7.8055,-0.00001,,,,,379592.1384,755.2300256
306,40.0114,7.84417,-0.00001,,,,,381472.7134,756.4825929
306.4,40.07843,7.82741,-0.00001,,,,,380657.6517,757.7499074
306.8,40.14546,7.86453,0,,,,,382462.8481,759.017222
307.2,40.21171,7.87382,0,,,,,382914.6335,760.2697893
307.6,40.27812,7.88098,0,,,,,383262.8341,761.5253817
308,40.34499,7.88978,0,,,,,383690.7901,762.7896711
308.4,40.41218,7.8877,-0.00001,,,,,383589.6369,764.0600107
308.8,40.4789,7.91649,0,,,,,384989.7339,765.3214641
309.2,40.54499,7.89653,0,,,,,384019.0518,766.5710064
309.6,40.61187,7.9075,0,,,,,384552.5379,767.8354849
310,40.67874,7.92615,0,,,,,385459.5129,769.0997744
310.4,40.74515,7.92448,-0.00001,,,,,385378.2985,770.3553667
310.8,40.81156,7.9578,-0.00001,,,,,386998.6957,771.6109591
311.2,40.87827,7.96646,0,,,,,387419.8433,772.8722235
311.6,40.9453,7.97503,0,,,,,387836.6142,774.139538
312,41.01203,7.97476,-0.00001,,,,,387823.4837,775.4011805
312.4,41.07843,7.99004,-0.00001,,,,,388566.571,776.6565839
312.8,41.14484,7.97903,-0.00001,,,,,388031.1396,777.9121762
313.2,41.21202,7.98595,-0.00001,,,,,388367.6687,779.1823268
313.6,41.2789,7.99963,-0.00001,,,,,389032.9458,780.4468053
314,41.34499,8.01089,-0.00001,,,,,389580.535,781.6963475
314.4,41.41171,8.02725,-0.00001,,,,,390376.1442,782.957801
314.8,41.47874,8.04359,-0.00001,,,,,391170.7807,784.2251155
315.2,41.54562,8.04286,-0.00001,,,,,391135.2798,785.489594
315.6,41.61171,8.05156,-0.00001,,,,,391558.3727,786.7391363
316,41.67812,8.06999,-0.00001,,,,,392454.6488,787.9947286
316.4,41.74515,8.07704,-0.00001,,,,,392797.5,789.2620432
316.8,41.81202,8.0923,0,,,,,393539.6146,790.5263326
317.2,41.87843,8.09029,-0.00001,,,,,393441.8656,791.781925
317.6,41.94484,8.07957,-0.00001,,,,,392920.5373,793.0375174
318,42.01187,8.11134,-0.00001,,,,,394465.5559,794.3048319
318.4,42.07874,8.11215,-0.00001,,,,,394504.9473,795.5691213
318.8,42.14546,8.12089,-0.00001,,,,,394929.9854,796.8305748
319.2,42.21171,8.13512,-0.00001,,,,,395622.0098,798.0831421
319.6,42.27843,8.15361,-0.00001,,,,,396521.2038,799.3445956
320,42.34546,8.15676,-0.00001,,,,,396674.3926,800.6119101
320.4,42.41203,8.17699,-0.00001,,,,,397658.2051,801.8705275
320.8,42.47828,8.18179,-0.00001,,,,,397891.6357,803.1230948
321.2,42.54484,8.17426,-0.00001,,,,,397525.4415,804.3815232
321.6,42.61202,8.19009,-0.00001,,,,,398295.276,805.6516737
322,42.67875,8.19696,-0.00001,,,,,398629.3735,806.9133163
322.4,42.745,8.20273,0,,,,,398909.9765,808.1658836
322.8,42.81156,8.22332,0,,,,,399911.2964,809.424312
323.2,42.87859,8.23328,-0.00001,,,,,400395.6648,810.6916265
323.6,42.94562,8.23258,-0.00001,,,,,400361.6228,811.958941
324,43.01171,8.26586,-0.00001,,,,,401980.0748,813.2084832
324.4,43.07843,8.25798,-0.00001,,,,,401596.8596,814.4699367
324.8,43.14546,8.27921,-0.00001,,,,,402629.3035,815.7372512
325.2,43.21218,8.25285,-0.00001,,,,,401347.3807,816.9987047
325.6,43.27827,8.2822,-0.00001,,,,,402774.7113,818.2482469
326,43.34468,8.29858,0,,,,,403571.2931,819.5038393
326.4,43.41187,8.32055,0,,,,,404639.7242,820.7741789
326.8,43.47874,8.32345,0,,,,,404780.7552,822.0384683
327.2,43.54515,8.3119,0,,,,,404219.0629,823.2940607
327.6,43.61156,8.34518,-0.00001,,,,,405837.5148,824.5496531
328,43.67843,8.34132,0,,,,,405649.7977,825.8139425
328.4,43.74562,8.34867,0,,,,,406007.2383,827.0842821
328.8,43.81187,8.35763,0,,,,,406442.9753,828.3368494
329.2,43.87843,8.37261,0,,,,,407171.4732,829.5952778
329.6,43.9453,8.37928,0,,,,,407495.8444,830.8595673
330,44.01234,8.39361,-0.00001,,,,,408192.7319,832.1270709
330.4,44.07875,8.38413,0,,,,,407731.7066,833.3826633
330.8,44.14484,8.40029,-0.00001,,,,,408517.5895,834.6322055
331.2,44.21156,8.41721,0,,,,,409340.4322,835.8936589
331.6,44.27859,8.4268,0,,,,,409806.807,837.1609735
332,44.3453,8.41774,0,,,,,409366.2068,838.4222379
332.4,44.41156,8.44146,-0.00001,,,,,410519.7429,839.6749942
332.5,44.42875,8.39229,-0.00001,,,,,408128.5385,840