File: .gitbook/assets/specimen_rawdata_c.csv
 ,10,mm/min,,,,,Average Strain,,
Tensile strain,25.4,mm,,,,,Area,2.47811E-05,
,,,,,,,,,
Time,Extension,Load,Strain from Extensometer,,,,,,
(s),(mm),(N),(mm/mm),,,,,Stress,Strain
0,0,-0.00084,0.00002,,,,,-33.89677303,0
0.3,0.04906,0.02562,-0.00002,,,,,1033.851577,0.408404715
0.6,0.10047,0.08041,-0.00004,,,,,3244.808951,0.836372232
0.9,0.15031,0.15342,-0.00005,,,,,6191.003474,1.251270132
1.2,0.2,0.17621,-0.00007,,,,,7110.655208,1.664919342
1.5,0.25078,0.18526,-0.00006,,,,,7475.852585,2.087642363
1.8,0.30016,0.23969,-0.00005,,,,,9672.28277,2.498710949
2.1,0.35031,0.24904,-0.00003,,,,,10049.58614,2.916189474
2.4,0.40047,0.26217,-0.00003,,,,,10579.42498,3.333751245
2.7,0.45047,0.30762,-0.00002,,,,,12413.48252,3.74998108
3,0.50016,0.3543,-0.00002,,,,,14297.17462,4.163630291
3.3,0.55047,0.38184,-0.00001,,,,,15408.50454,4.582440752
3.6,0.60047,0.42056,0,,,,,16970.98436,4.998670587
3.9,0.65,0.49576,0,,,,,20005.55261,5.410987862
4.2,0.70047,0.49862,0,,,,,20120.96306,5.831130258
4.5,0.75031,0.55698,0.00001,,,,,22475.98172,6.246028158
4.8,0.8,0.6092,0.00002,,,,,24583.2311,6.659677369
5.1,0.85016,0.62419,0.00002,,,,,25188.12709,7.07723914
5.4,0.90062,0.67209,0,,,,,27121.05022,7.49729829
5.7,0.95,0.70737,0,,,,,28544.71469,7.908366876
6,1.00031,0.76344,0.00001,,,,,30807.32429,8.327177336
6.3,1.05062,0.78838,0.00001,,,,,31813.73562,8.745987797
6.6,1.09984,0.83052,0.00002,,,,,33514.22373,9.155724447
6.9,1.15031,0.87822,0,,,,,35439.0762,9.575866843
7.2,1.20047,0.89529,0,,,,,36127.90705,9.993428614
7.5,1.25031,0.93746,0,,,,,37829.60576,10.40832651
7.8,1.3,0.98004,0,,,,,39547.84933,10.82197572
8.1,1.35062,1.02115,0,,,,,41206.77354,11.24336681
8.4,1.40031,1.08751,0,,,,,43884.61861,11.65701602
8.7,1.45,1.10763,0.00002,,,,,44696.52703,12.07066523
9,1.50078,1.13669,0,,,,,45869.19397,12.49338825
9.3,1.55016,1.16818,-0.00001,,,,,47139.91942,12.90445684
9.6,1.60016,1.21884,0,,,,,49184.21766,13.32068667
9.9,1.65047,1.25486,0,,,,,50637.74357,13.73949713
10.2,1.70047,1.29924,-0.00001,,,,,52428.62308,14.15572697
10.5,1.75,1.32212,-0.00001,,,,,53351.90661,14.56804424
10.8,1.80047,1.36599,0.00001,,,,,55122.20594,14.98818664
11.1,1.85047,1.41793,0,,,,,57218.1564,15.40441648
11.4,1.9,1.46651,0,,,,,59178.51978,15.81673375
11.7,1.95047,1.50816,0,,,,,60859.23477,16.23687615
12,2.00031,1.5376,-0.00001,,,,,62047.23596,16.65177405
12.3,2.05,1.57887,-0.00002,,,,,63712.6167,17.06542326
12.6,2.10016,1.6142,0,,,,,65138.29883,17.48298503
12.9,2.15062,1.65059,0.00003,,,,,66606.75547,17.90304418
13.2,2.2,1.7135,0.00001,,,,,69145.38165,18.31411276
13.5,2.25031,1.73581,-0.00002,,,,,70045.6638,18.73292323
13.8,2.30062,1.76138,-0.00002,,,,,71077.49771,19.15173369
14.1,2.35,1.79229,-0.00001,,,,,72324.81825,19.56280227
14.4,2.40031,1.83175,0,,,,,73917.15951,19.98161273
14.7,2.45047,1.87477,0,,,,,75653.15853,20.3991745
15,2.50031,1.91486,0,,,,,77270.92238,20.8140724
15.3,2.55,1.95034,0,,,,,78702.65751,21.22772161
15.6,2.60047,1.98698,0.00001,,,,,80181.20246,21.64786401
15.9,2.65031,2.01156,0,,,,,81173.08661,22.06276191
16.2,2.70016,2.06785,0,,,,,83444.57393,22.47774306
16.5,2.75062,2.10472,0,,,,,84932.40015,22.89780221
16.8,2.80016,2.16422,0,,,,,87333.42157,23.31020273
17.1,2.85016,2.18072,0,,,,,87999.25104,23.72643256
17.4,2.90047,2.21844,0,,,,,89521.37756,24.14524302
17.7,2.95031,2.26281,0,,,,,91311.85354,24.56014092
18,3.00016,2.31487,0,,,,,93412.6464,24.97512207
18.3,3.05047,2.33032,0,,,,,94036.10491,25.39393253
18.6,3.10047,2.38937,-0.00001,,,,,96418.96734,25.81016236
18.9,3.15,2.41487,0,,,,,97447.97652,26.22247964
19.2,3.20047,2.445,0,,,,,98663.82149,26.64262204
19.5,3.25031,2.49257,0,,,,,100583.428,27.05751994
19.8,3.3,2.52575,0,,,,,101922.3506,27.47116915
20.1,3.35031,2.56172,0,,,,,103373.8588,27.88997961
20.4,3.40062,2.61552,0,,,,,105544.8664,28.30879007
20.7,3.45,2.62714,0,,,,,106013.7718,28.71985865
21,3.50031,2.66979,0,,,,,107734.8401,29.13866911
21.3,3.55062,2.71505,0,,,,,109561.2305,29.55747957
21.6,3.6,2.74899,0,,,,,110930.8215,29.96854816
21.9,3.65031,2.78987,0,,,,,112580.4645,30.38735862
22.2,3.70047,2.83193,0,,,,,114277.7243,30.80492039
22.5,3.75016,2.87047,0,,,,,115832.9406,31.2185696
22.8,3.8,2.88581,0,,,,,116451.9602,31.6334675
23.1,3.85047,2.91711,-0.00001,,,,,117715.0185,32.0536099
23.4,3.90031,2.98562,0.00001,,,,,120479.6232,32.4685078
23.7,3.95,3.01242,0,,,,,121561.0917,32.88215701
24,4.00062,3.04509,-0.00001,,,,,122879.434,33.30354809
24.3,4.05016,3.09162,0,,,,,124757.0731,33.71594862
24.6,4.10016,3.12609,0,,,,,126148.0514,34.13217845
24.9,4.15047,3.15069,0,,,,,127140.7426,34.55098891
25.2,4.20047,3.19256,0,,,,,128830.3354,34.96721875
25.5,4.25016,3.24702,0,,,,,131027.9761,35.38086796
25.8,4.30047,3.27249,0,,,,,132055.7747,35.79967842
26.1,4.35047,3.31235,0,,,,,133664.2573,36.21590825
26.4,4.4,3.34524,0,,,,,134991.4774,36.62822553
26.7,4.45047,3.38647,0,,,,,136655.244,37.04836792
27,4.50047,3.40421,0,,,,,137371.1116,37.46459776
27.3,4.55,3.46246,0,,,,,139721.6914,37.87691504
27.6,4.60031,3.49616,0,,,,,141081.5976,38.2957255
27.9,4.65062,3.51291,0,,,,,141757.5154,38.71453596
28.2,4.7,3.6806,0.00009,,,,,148524.3605,39.12560454
28.5,4.75031,3.59381,-0.00049,,,,,145022.0975,39.544415
28.8,4.80062,3.63581,-0.00007,,,,,146716.9361,39.96322546
29.1,4.85,3.72156,0,,,,,150177.2317,40.37429405
29.4,4.90031,3.7105,0.0001,,,,,149730.9242,40.79310451
29.7,4.95047,3.74373,0.00002,,,,,151071.8644,41.21066628
30,5.00016,3.76946,-0.00002,,,,,152110.1548,41.62431549
30.3,5.05,3.81637,-0.00001,,,,,154003.1282,42.03921339
30.6,5.10062,3.84268,-0.00001,,,,,155064.8235,42.46060448
30.9,5.15031,3.90062,0,,,,,157402.8938,42.87425369
31.2,5.20016,3.90603,0.00001,,,,,157621.2052,43.28923483
31.5,5.25047,3.97568,0.00001,,,,,160431.8126,43.70804529
31.8,5.30016,3.96746,0.00001,,,,,160100.1085,44.1216945
32.1,5.35016,4.02215,0,,,,,162307.0305,44.53792434
32.4,5.40047,4.06804,0,,,,,164158.8435,44.9567348
32.7,5.45031,4.10974,0,,,,,165841.5762,45.3716327
33,5.50016,4.13521,0.00001,,,,,166869.3747,45.78661385
33.3,5.55047,4.15937,0.00001,,,,,167844.3105,46.20542431
33.6,5.60047,4.23084,0.00001,,,,,170728.3609,46.62165414
33.9,5.65,4.23262,0,,,,,170800.1898,47.03397142
34.2,5.70047,4.27079,0,,,,,172340.4753,47.45411381
34.5,5.75047,4.29515,0,,,,,173323.4817,47.87034365
34.8,5.8,4.36512,0,,,,,176147.0022,48.28266092
35.1,5.85016,4.37432,0,,,,,176518.2526,48.7002227
35.4,5.90062,4.44197,0.00001,,,,,179248.1534,49.12028185
35.7,5.95,4.43153,0,,,,,178826.865,49.53135043
36,6.00031,4.4923,0.00001,,,,,181279.1351,49.95016089
36.3,6.05062,4.54478,0,,,,,183396.8763,50.36897135
36.6,6.09984,4.53802,0,,,,,183124.088,50.778708
36.9,6.15031,4.61902,0.00002,,,,,186392.7054,51.1988504
37.2,6.20062,4.61021,0.00001,,,,,186037.1928,51.61766086
37.5,6.25016,4.68175,0.00001,,,,,188924.068,52.03006138
37.8,6.3,4.6732,0,,,,,188579.0473,52.44495928
38.1,6.35062,4.72982,0,,,,,190863.8512,52.86635037
38.4,6.40047,4.80653,0,,,,,193959.3529,53.28133151
38.7,6.45,4.77225,0,,,,,192576.0418,53.69364879
39,6.50062,4.825,0.00001,,,,,194704.6784,54.11503987
39.3,6.55016,4.86474,0,,,,,196308.3186,54.52744039
39.6,6.60016,4.914,0,,,,,198296.1222,54.94367023
39.9,6.65047,4.95612,0,,,,,199995.8033,55.36248069
40.2,6.70031,4.95089,0,,,,,199784.7555,55.77737859
40.5,6.75,4.9935,-0.00001,,,,,201504.2097,56.1910278
40.8,6.80047,5.03661,0,,,,,203243.8405,56.6111702
41.1,6.85047,5.08283,0.00001,,,,,205108.9701,57.02740003
41.4,6.9,5.09724,0.00001,,,,,205690.4611,57.43971731
41.7,6.95047,5.17526,0.00001,,,,,208838.8257,57.8598597
42,7.00047,5.17322,0,,,,,208756.505,58.27608954
42.3,7.05,5.19114,0,,,,,209479.6361,58.68840681
42.6,7.10031,5.24907,0,,,,,211817.3028,59.10721727
42.9,7.15062,5.26184,0,,,,,212332.6145,59.52602773
43.2,7.2,5.31357,0,,,,,214420.0908,59.93709632
43.5,7.25031,5.31926,0,,,,,214649.7011,60.35590678
43.8,7.30062,5.3726,0,,,,,216802.1461,60.77471724
44.1,7.35,5.4044,0,,,,,218085.3811,61.18578583
44.4,7.40031,5.46162,0,,,,,220394.397,61.60459629
44.7,7.45047,5.49828,0,,,,,221873.749,62.02215806
45,7.50016,5.5147,0,,,,,222536.3503,62.43580727
45.3,7.55,5.53533,0,,,,,223368.8389,62.85070517
45.6,7.60062,5.5701,0,,,,,224771.9231,63.27209625
45.9,7.65031,5.61994,0,,,,,226783.1317,63.68574547
46.2,7.7,5.6667,0,,,,,228670.052,64.09939468
46.5,7.75078,5.66832,0,,,,,228735.4244,64.5221177
46.8,7.80016,5.70052,0,,,,,230034.8007,64.93318628
47.1,7.85015,5.74675,0,,,,,231900.3338,65.34933287
47.4,7.90047,5.77275,0,,,,,232949.5196,65.76822658
47.7,7.95031,5.81871,0,,,,,234804.1574,66.18312448
48,8,5.86328,0,,,,,236602.704,66.59677369
48.3,8.05047,5.88264,0,,,,,237383.9439,67.01691609
48.6,8.10047,5.91083,0,,,,,238521.5035,67.43314592
48.9,8.15,5.95828,0,,,,,240436.2676,67.8454632
49.2,8.20047,5.98329,0,,,,,241445.5037,68.26560559
49.5,8.25031,6.02154,0,,,,,242989.0174,68.68050349
49.8,8.3,6.06812,0,,,,,244868.6742,69.0941527
50.1,8.35015,6.08286,0,,,,,245463.4819,69.51163123
50.4,8.40062,6.11234,0,,,,,246653.0972,69.93177362
50.7,8.45,6.134,0.00001,,,,,247527.1497,70.34284221
51,8.50031,6.16912,0,,,,,248944.3576,70.76165267
51.3,8.55062,6.19954,0,,,,,250171.9051,71.18046313
51.6,8.6,6.23797,0,,,,,251722.6824,71.59153172
51.9,8.65031,6.2795,0,,,,,253398.555,72.01034218
52.2,8.70047,6.30929,0,,,,,254600.6799,72.42790395
52.5,8.75015,6.34012,0,,,,,255844.7721,72.84146991
52.8,8.8,6.36447,0,,,,,256827.375,73.25645106
53.1,8.85062,6.39657,0,,,,,258122.716,73.67784214
53.4,8.90031,6.4527,0,,,,,260387.7468,74.09149135
53.7,8.95015,6.47581,0,,,,,261320.3116,74.50638925
54,9.00062,6.50221,0,,,,,262385.6387,74.92653165
54.3,9.05015,6.5432,0,,,,,264039.7206,75.33884893
54.6,9.10015,6.57122,0,,,,,265170.4201,75.75507876
54.9,9.15047,6.59397,0,,,,,266088.4577,76.17397247
55.2,9.20031,6.62343,0,,,,,267277.2659,76.58887037
55.5,9.25,6.67323,0,,,,,269286.8603,77.00251958
55.8,9.30047,6.68694,0,,,,,269840.1041,77.42266197
56.1,9.35047,6.73297,0,,,,,271697.5665,77.83889181
56.4,9.4,6.7689,0,,,,,273147.4606,78.25120908
56.7,9.45047,6.79987,0,,,,,274397.2024,78.67135148
57,9.50031,6.84213,0,,,,,276102.5329,79.08624938
57.3,9.55015,6.85125,0,,,,,276470.555,79.50114728
57.6,9.60015,6.89147,0,,,,,278093.5648,79.91737712
57.9,9.65062,6.91184,0,,,,,278915.5615,80.33751951
58.2,9.69984,6.96071,0,,,,,280887.6274,80.74725616
58.5,9.75031,6.97805,0,,,,,281587.3536,81.16739856
58.8,9.80062,7.01469,0,,,,,283065.8986,81.58620902
59.1,9.85,7.05578,0,,,,,284724.0157,81.9972776
59.4,9.90031,7.09008,0,,,,,286108.1339,82.41608807
59.7,9.95047,7.12261,0,,,,,287420.8268,82.83364984
60,10.00031,7.15116,0,,,,,288572.9136,83.24854774
60.3,10.05,7.20674,0,,,,,290815.7501,83.66219695
60.6,10.10062,7.22183,0,,,,,291424.6814,84.08358803
60.9,10.15031,7.24767,0,,,,,292467.4107,84.49723724
61.2,10.20016,7.28887,0,,,,,294129.9667,84.91221839
61.5,10.25078,7.31633,0,,,,,295238.0683,85.33360947
61.8,10.30015,7.34302,0,,,,,296315.0979,85.74459481
62.1,10.35015,7.39182,0,,,,,298284.339,86.16082465
62.4,10.40047,7.42771,0,,,,,299732.619,86.57971836
62.7,10.45047,7.43393,0,,,,,299983.6166,86.99594819
63,10.50015,7.47305,0,,,,,301562.2377,87.40951416
63.3,10.55047,7.49599,0,,,,,302487.9424,87.82840786
63.6,10.60047,7.54167,0,,,,,304331.2812,88.2446377
63.9,10.65,7.5582,0,,,,,304998.3213,88.65695497
64.2,10.70047,7.57843,0,,,,,305814.6686,89.07709737
64.5,10.75047,7.64508,0,,,,,308504.2161,89.49332721
64.8,10.80015,7.68024,0,,,,,309923.0382,89.90689317
65.1,10.85031,7.69443,0,,,,,310495.6515,90.32445494
65.4,10.90062,7.72929,0,,,,,311902.3676,90.7432654
65.7,10.95,7.75587,0,,,,,312974.9584,91.15433399
66,11.00015,7.79349,0,,,,,314493.0495,91.57181251
66.3,11.05062,7.83612,0,,,,,316213.3108,91.99195491
66.6,11.1,7.84365,0,,,,,316517.1711,92.40302349
66.9,11.15031,7.88811,0,,,,,318311.2789,92.82183395
67.2,11.20047,7.91524,0,,,,,319406.064,93.23939573
67.5,11.25031,7.97268,0,,,,,321723.9576,93.65429363
67.8,11.3,7.97413,0,,,,,321782.4699,94.06794284
68.1,11.35062,8.02422,0,,,,,323803.7667,94.48933392
68.4,11.40031,8.03159,0,,,,,324101.1706,94.90298313
68.7,11.45015,8.0725,0,,,,,325752.0241,95.31788103
69,11.50062,8.10007,0,,,,,326864.5646,95.73802343
69.3,11.55015,8.15486,0,,,,,329075.522,96.1503407
69.6,11.60015,8.1712,0,,,,,329734.895,96.56657054
69.9,11.65047,8.20115,0,,,,,330943.4763,96.98546425
70.2,11.70031,8.22687,0,,,,,331981.3632,97.40036215
70.5,11.75,8.28025,0,,,,,334135.4225,97.81401136
70.8,11.80047,8.30149,0,,,,,334992.5266,98.23415375
71.1,11.85047,8.33374,0,,,,,336293.9205,98.65038359
71.4,11.9,8.35638,0,,,,,337207.5193,99.06270086
71.7,11.95047,8.38413,0,,,,,338327.3234,99.48284326
72,12.00047,8.43028,0,,,,,340189.6282,99.89907309
72.3,12.05,8.45115,0,,,,,341031.8016,100.3113904
72.6,12.10031,8.48581,0.00001,,,,,342430.4471,100.7302008
72.9,12.15062,8.51699,0,,,,,343688.663,101.1490113
73.2,12.2,8.55965,0,,,,,345410.1348,101.5600799
73.5,12.25031,8.58405,0,,,,,346394.7554,101.9788903
73.8,12.30062,8.62969,0,,,,,348236.48,102.3977008
74.1,12.34984,8.65305,0,,,,,349179.1331,102.8074374
74.4,12.40031,8.68131,0,,,,,350319.5174,103.2275798
74.7,12.45047,8.71178,0,,,,,351549.0825,103.6451416
75,12.50015,8.75213,0,,,,,353177.3382,104.0587076
75.3,12.55,8.77913,0,,,,,354266.8774,104.4736887
75.6,12.60062,8.80498,0,,,,,355310.0102,104.8950798
75.9,12.65031,8.83318,0,,,,,356447.9733,105.308729
76.2,12.7,8.87061,0,,,,,357958.3974,105.7223782
76.5,12.75062,8.90491,0,,,,,359342.5156,106.1437693
76.8,12.80015,8.95267,0,,,,,361269.7893,106.5560866
77.1,12.85015,8.98104,0,,,,,362414.6124,106.9723164
77.4,12.90047,8.99057,0,,,,,362799.1794,107.3912101
77.7,12.95031,9.02995,0,,,,,364388.2924,107.806108
78,13.00015,9.07128,0,,,,,366056.0943,108.2210059
78.3,13.05047,9.10552,0,,,,,367437.7914,108.6398996
78.6,13.10047,9.10376,0,,,,,367366.7695,109.0561295
78.9,13.15,9.16229,0,,,,,369728.6483,109.4684468
79.2,13.20047,9.18822,0,,,,,370775.0094,109.8885891
79.5,13.25047,9.22132,0,,,,,372110.7036,110.304819
79.8,13.30015,9.25484,0,,,,,373463.3463,110.7183849
80.1,13.35031,9.27197,0,,,,,374154.5983,111.1359467
80.4,13.40062,9.30223,0,,,,,375375.6892,111.5547572
80.7,13.45,9.35048,0,,,,,377322.736,111.9658258
81,13.50015,9.37305,0,,,,,378233.51,112.3833043
81.3,13.55062,9.41186,0,,,,,379799.6216,112.8034467
81.6,13.6,9.45006,0,,,,,381341.1178,113.2145153
81.9,13.65031,9.48294,0,,,,,382667.9343,113.6333257
82.2,13.70047,9.50885,0,,,,,383713.4883,114.0508875
82.5,13.75031,9.53549,0,,,,,384788.5003,114.4657854
82.8,13.8,9.56532,0,,,,,385992.2393,114.8794346
83.1,13.85062,9.59879,0,,,,,387342.8642,115.3008257
83.4,13.90031,9.63058,0,,,,,388625.6957,115.7144749
83.7,13.95,9.66669,0,,,,,390082.8534,116.1281241
84,14.00062,9.70064,0,,,,,391452.848,116.5495152
84.3,14.05015,9.71724,0,,,,,392122.7128,116.9618325
84.6,14.10015,9.7498,0,,,,,393436.6163,117.3780623
84.9,14.15047,9.78057,0,,,,,394678.2873,117.796956
85.2,14.20031,9.82225,0,,,,,396360.2129,118.2118539
85.5,14.25,9.84459,0,,,,,397261.7057,118.6255031
85.8,14.30047,9.8817,0,,,,,398759.2167,119.0456455
86.1,14.35047,9.91778,0,,,,,400215.1638,119.4618754
86.4,14.4,9.94842,0,,,,,401451.589,119.8741926
86.7,14.45062,9.98989,0,,,,,403125.0404,120.2955837
87,14.50047,10.00589,0,,,,,403770.6932,120.7105649
87.3,14.55,10.06343,0,,,,,406092.6221,121.1228821
87.6,14.60031,10.09653,0,,,,,407428.3164,121.5416926
87.9,14.65062,10.11526,0,,,,,408184.1337,121.9605031
88.2,14.7,10.15387,0,,,,,409742.1747,122.3715717
88.5,14.75015,10.17577,0,,,,,410625.912,122.7890502
88.8,14.80062,10.21598,0,,,,,412248.5182,123.2091926
89.1,14.85,10.23162,0,,,,,412879.6439,123.6202612
89.4,14.90031,10.27899,0,,,,,414791.1797,124.0390716
89.7,14.95047,10.31144,0,,,,,416100.6444,124.4566334
90,15.00015,10.3316,0,,,,,416914.1669,124.8701994
90.3,15.05,10.36908,0,,,,,418426.6086,125.2851805
90.6,15.10062,10.39788,0,,,,,419588.7837,125.7065716
90.9,15.15031,10.42899,0,,,,,420844.1749,126.1202208
91.2,15.2,10.47471,0,,,,,422689.1279,126.53387
91.5,15.25062,10.4863,0,,,,,423156.8226,126.9552611
91.8,15.30015,10.52515,0,,,,,424724.5484,127.3675784
92.1,15.35031,10.5639,0,,,,,426288.2388,127.7851401
92.4,15.40031,10.58995,0,,,,,427339.4423,128.20137
92.7,15.45031,10.62163,0,,,,,428617.8349,128.6175998
93,15.5,10.65548,0,,,,,429983.7941,129.031249
93.3,15.55047,10.66293,0,,,,,430284.4262,129.4513914
93.6,15.60047,10.70928,0,,,,,432154.8017,129.8676213
93.9,15.65,10.75631,0,,,,,434052.6175,130.2799385
94.2,15.70062,10.7921,0,,,,,435496.8621,130.7013296
94.5,15.75031,10.81738,0,,,,,436516.9936,131.1149788
94.8,15.80015,10.84346,0,,,,,437569.4077,131.5298767
95.1,15.85031,10.87573,0,,,,,438871.6087,131.9474385
95.4,15.90062,10.91936,0,,,,,440632.2232,132.366249
95.7,15.95,10.94748,0,,,,,441766.9581,132.7773175
96,16.00031,10.96706,0,,,,,442557.0757,133.196128
96.3,16.05062,11.01083,0,,,,,444323.3397,133.6149385
96.6,16.1,11.05716,0,,,,,446192.9081,134.026007
96.9,16.15031,11.07246,0,,,,,446810.3137,134.4448175
97.2,16.20047,11.1024,0,,,,,448018.4915,134.8623793
97.5,16.25015,11.12594,0,,,,,448968.4082,135.2759452
97.8,16.3,11.18309,0,,,,,451274.5994,135.6909264
98.1,16.35062,11.20345,0,,,,,452096.1926,136.1123175
98.4,16.40031,11.23433,0,,,,,453342.3025,136.5259667
98.7,16.45015,11.2569,0,,,,,454253.0765,136.9408646
99,16.50062,11.3131,0,,,,,456520.9321,137.361007
99.3,16.55015,11.33509,0,,,,,457408.3012,137.7733243
99.6,16.60015,11.35536,0,,,,,458226.2626,138.1895541
99.9,16.65047,11.38589,0,,,,,459458.2489,138.6084478
100.2,16.70031,11.42164,0,,,,,460900.8794,139.0233457
100.5,16.75015,11.45635,0,,,,,462301.5425,139.4382436
100.8,16.80046,11.48342,0,,,,,463393.9063,139.8570541
101.1,16.85047,11.53037,0,,,,,465288.4938,140.2733671
101.4,16.9,11.58316,0,,,,,467418.7446,140.6856844
101.7,16.95047,11.58592,0,,,,,467530.1197,141.1058268
102,17.00047,11.62266,0,,,,,469012.7,141.5220566
102.3,17.05,11.67309,0,,,,,471047.717,141.9343739
102.6,17.10031,11.70462,0,,,,,472320.0566,142.3531844
102.9,17.15047,11.72222,0,,,,,473030.2747,142.7707462
103.2,17.2,11.76099,0,,,,,474594.7721,143.1830634
103.5,17.25015,11.77717,0,,,,,475247.6886,143.600542
103.8,17.30062,11.80657,0,,,,,476434.0756,144.0206844
104.1,17.35,11.85344,0,,,,,478325.4348,144.4317529
104.4,17.40031,11.89585,0,,,,,480036.8184,144.8505634
104.7,17.45046,11.92957,0,,,,,481397.5317,145.2680419
105,17.50031,11.94273,0,,,,,481928.5811,145.6830231
105.3,17.55015,11.99894,0,,,,,484196.8402,146.097921
105.6,17.60062,12.00896,0,,,,,484601.1803,146.5180634
105.9,17.65031,12.05562,0,,,,,486484.0653,146.9317126
106.2,17.70015,12.0838,0,,,,,487621.2213,147.3466105
106.5,17.75062,12.09018,0,,,,,487878.6754,147.7667529
106.8,17.80015,12.14456,0,,,,,490073.0879,148.1790701
107.1,17.85015,12.18446,0,,,,,491683.1846,148.5953
107.4,17.90047,12.21681,0,,,,,492988.6139,149.0141937
107.7,17.95031,12.2389,0,,,,,493880.0183,149.4290916
108,18.00015,12.26666,0,,,,,495000.226,149.8439895
108.3,18.05047,12.30436,0,,,,,496521.5454,150.2628832
108.6,18.10046,12.35717,0,,,,,498652.6033,150.6790298
108.9,18.15,12.37341,0,,,,,499307.9409,151.0914303
109.2,18.20047,12.4086,0,,,,,500727.9736,151.5115727
109.5,18.25047,12.44133,0,,,,,502048.7371,151.9278025
109.8,18.30015,12.47775,0,,,,,503518.4043,152.3413685
110.1,18.35015,12.5176,0,,,,,505126.4834,152.7575983
110.4,18.40062,12.5364,0,,,,,505885.1255,153.1777407
110.7,18.45,12.57635,0,,,,,507497.2398,153.5888093
111,18.50031,12.6075,0,,,,,508754.2452,154.0076198
111.3,18.55062,12.64336,0,,,,,510201.3145,154.4264302
111.6,18.59984,12.6788,0,,,,,511631.4355,154.8361669
111.9,18.65031,12.71315,0,,,,,513017.5714,155.2563093
112.2,18.70047,12.75663,0,,,,,514772.133,155.6738711
112.5,18.75031,12.77506,0,,,,,515515.8443,156.088769
112.8,18.80015,12.81924,0,,,,,517298.6532,156.5036669
113.1,18.85062,12.83063,0,,,,,517758.2773,156.9238093
113.4,18.90031,12.86389,0,,,,,519100.4281,157.3374585
113.7,18.95015,12.91872,0,,,,,521312.9996,157.7523564
114,19.00078,12.94049,0,,,,,522191.4909,158.1738307
114.3,19.05015,12.97099,0,,,,,523422.2666,158.584816
114.6,19.10015,13.01008,0,,,,,524999.6772,159.0010459
114.9,19.15047,13.04391,0,,,,,526364.8294,159.4199396
115.2,19.20031,13.06673,0,,,,,527285.6917,159.8348375
115.5,19.25015,13.09643,0,,,,,528484.1847,160.2497354
115.8,19.30046,13.1398,0,,,,,530234.3074,160.6685458
116.1,19.35047,13.18144,0,,,,,531914.6189,161.0848589
116.4,19.4,13.21731,0,,,,,533362.0918,161.4971762
116.7,19.45062,13.23442,0,,,,,534052.5368,161.9185673
117,19.50031,13.28524,0,,,,,536103.2915,162.3322165
117.3,19.55,13.32225,0,,,,,537596.7672,162.7458657
117.6,19.60031,13.34335,0,,,,,538448.2219,163.1646762
117.9,19.65062,13.3918,0,,,,,540403.3393,163.5834866
118.2,19.7,13.41638,0,,,,,541395.2235,163.9945552
118.5,19.75031,13.44302,0,,,,,542470.2354,164.4133657
118.8,19.80062,13.46376,0,,,,,543307.1629,164.8321761
119.1,19.85,13.53037,0,,,,,545995.0963,165.2432447
119.4,19.90047,13.56124,0,,,,,547240.8027,165.6633871
119.7,19.95062,13.58851,0,,,,,548341.2372,166.0808656
120,20.00031,13.61072,0,,,,,549237.484,166.4945148
120.3,20.05015,13.65928,0,,,,,551197.0403,166.9094127
120.6,20.10062,13.67214,0,,,,,551715.9838,167.3295551
120.9,20.15031,13.70874,0,,,,,553192.9146,167.7432044
121.2,20.2,13.747,0,,,,,554736.8319,168.1568536
121.5,20.25078,13.78617,0,,,,,556317.4707,168.5795766
121.8,20.30015,13.82208,0,,,,,557766.5578,168.9905619
122.1,20.35015,13.85742,0,,,,,559192.6434,169.4067918
122.4,20.40047,13.89778,0,,,,,560821.3027,169.8256855
122.7,20.45031,13.91046,0,,,,,561332.9825,170.2405834
123,20.50015,13.95804,0,,,,,563252.9926,170.6554813
123.3,20.55046,13.98934,0,,,,,564516.0509,171.0742917
123.6,20.60047,14.03061,0.00001,,,,,566181.4317,171.4906048
123.9,20.65,14.0847,0.00001,,,,,568364.1417,171.9029221
124.2,20.70047,14.10761,0,,,,,569288.6359,172.3230645
124.5,20.75031,14.11882,0,,,,,569740.9964,172.7379624
124.8,20.8,14.14978,0,,,,,570990.3346,173.1516116
125.1,20.85031,14.18937,0,,,,,572587.9218,173.5704221
125.4,20.90062,14.22909,0,,,,,574190.7549,173.9892325
125.7,20.95,14.26994,0,,,,,575839.1873,174.4003011
126,21.00015,14.30928,0,,,,,577426.6861,174.8177796
126.3,21.05062,14.35476,0,,,,,579261.9543,175.237922
126.6,21.1,14.37267,0,,,,,579984.6819,175.6489906
126.9,21.15031,14.40629,0,,,,,581341.3599,176.0678011
127.2,21.20046,14.44323,0,,,,,582832.0108,176.4852796
127.5,21.25015,14.46616,0,,,,,583757.312,176.8989288
127.8,21.3,14.49362,-0.00001,,,,,584865.4137,177.3139099
128.1,21.35062,14.55235,0,,,,,587235.3631,177.735301
128.4,21.40031,14.56647,0,,,,,587805.1517,178.1489502
128.7,21.45015,14.61676,0,,,,,589834.5192,178.5638481
129,21.50062,14.65263,0,,,,,591281.9921,178.9839905
129.3,21.55015,14.68219,0,,,,,592474.8357,179.3963078
129.6,21.60015,14.7205,0,,,,,594020.7707,179.8125376
129.9,21.65047,14.75611,0,,,,,595457.7517,180.2314314
130.2,21.70031,14.78936,0,,,,,596799.499,180.6463293
130.5,21.75,14.81389,0,,,,,597789.3655,181.0599785
130.8,21.80047,14.86705,0,,,,,599934.5469,181.4801209
131.1,21.85047,14.89816,0,,,,,601189.9381,181.8963507
131.4,21.9,14.93316,0,,,,,602602.3037,182.308668
131.7,21.95046,14.96947,0,,,,,604067.5321,182.7287271
132,22.00047,15.01366,0,,,,,605850.7444,183.1450402
132.3,22.05015,15.04905,0,,,,,607278.8478,183.5586062
132.6,22.10015,15.06916,0,,,,,608090.3527,183.974836
132.9,22.15062,15.10498,0,,,,,609535.8079,184.3949784
133.2,22.2,15.14722,0,,,,,611240.3313,184.806047
133.5,22.25031,15.17192,0,,,,,612237.0579,185.2248574
133.8,22.30062,15.21441,0,,,,,613951.6697,185.6436679
134.1,22.35,15.25145,0,,,,,615446.3559,186.0547365
134.4,22.40031,15.27756,0,,,,,616499.9806,186.473547
134.7,22.45047,15.32502,0,,,,,618415.1483,186.8911087
135,22.50015,15.36871,0,,,,,620178.184,187.3046747
135.3,22.55015,15.3962,0,,,,,621287.4963,187.7209045
135.6,22.60062,15.43978,0,,,,,623046.0932,188.1410469
135.9,22.65031,15.45098,0,,,,,623498.0501,188.5546961
136.2,22.7,15.50614,0,,,,,625723.9382,188.9683453
136.5,22.75078,15.53665,0,,,,,626955.1174,189.3910684
136.8,22.80015,15.57661,-0.00001,,,,,628567.6354,189.8020537
137.1,22.85015,15.6206,0,,,,,630342.7771,190.2182835
137.4,22.90047,15.64643,0,,,,,631385.1029,190.6371772
137.7,22.95031,15.6796,0,,,,,632723.6219,191.0520751
138,23.00015,15.71237,0,,,,,634045.9995,191.466973
138.3,23.05046,15.75226,0,,,,,635655.6927,191.8857835
138.6,23.10047,15.77054,0,,,,,636393.3511,192.3020966
138.9,23.15,15.80966,0,,,,,637971.9722,192.7144139
139.2,23.20047,15.86018,-0.00001,,,,,640010.621,193.1345563
139.5,23.25047,15.91206,-0.00001,,,,,642104.1503,193.5507861
139.8,23.30015,15.94887,0,,,,,643589.5553,193.9643521
140.1,23.35031,15.97149,0,,,,,644502.3469,194.3819138
140.4,23.40062,16.00005,-0.00001,,,,,645654.8372,194.8007243
140.7,23.45,16.03939,0,,,,,647242.3361,195.2117929
141,23.50031,16.08248,0,,,,,648981.1599,195.6306033
141.3,23.55062,16.12687,0,,,,,650772.4429,196.0494138
141.6,23.6,16.129,0,,,,,650858.3954,196.4604824
141.9,23.65031,16.20372,0,,,,,653873.5941,196.8792928
142.2,23.70046,16.21144,0,,,,,654185.1216,197.2967714
142.5,23.75031,16.25717,0,,,,,656030.478,197.7117525
142.8,23.80015,16.30308,0,,,,,657883.0981,198.1266504
143.1,23.85062,16.32979,0,,,,,658960.9348,198.5467928
143.4,23.90031,16.38277,0,,,,,661098.8527,198.960442
143.7,23.95015,16.40463,0,,,,,661980.9758,199.3753399
144,24.00078,16.44497,0,,,,,663608.828,199.7968143
144.3,24.05015,16.4835,0,,,,,665163.6407,200.2077996
144.6,24.10015,16.52296,0,,,,,666755.982,200.6240294
144.9,24.15062,16.54321,-0.00001,,,,,667573.1363,201.0441718
145.2,24.20047,16.58706,0,,,,,669342.6286,201.459153
145.5,24.25,16.6251,0,,,,,670877.6682,201.8714702
145.8,24.30046,16.66731,0,,,,,672580.981,202.2915294
146.1,24.35047,16.68592,0,,,,,673331.9559,202.7078425
146.4,24.4,16.74354,0,,,,,675657.1132,203.1201598
146.7,24.45047,16.7826,0,,,,,677233.3131,203.5403021
147,24.50047,16.81447,0,,,,,678519.3728,203.956532
147.3,24.55015,16.83499,0,,,,,679347.4226,204.3700979
147.6,24.60015,16.88239,0,,,,,681260.169,204.7863278
147.9,24.65062,16.92414,0,,,,,682944.9194,205.2064702
148.2,24.7,16.96906,0,,,,,684757.5896,205.6175388
148.5,24.75031,17.00426,0,,,,,686178.0259,206.0363492
148.8,24.80062,17.03515,0,,,,,687424.5393,206.4551597
149.1,24.85,17.08519,0,,,,,689443.8185,206.8662283
149.4,24.90031,17.09182,0,,,,,689711.3609,207.2850387
149.7,24.95046,17.15079,0,,,,,692090.9951,207.7025173
150,25.00031,17.19254,0,,,,,693775.7454,208.1174984
150.3,25.05,17.23594,0,,,,,695527.0787,208.5311476
150.6,25.10062,17.27711,-0.00001,,,,,697188.4241,208.9525387
150.9,25.15031,17.3093,0,,,,,698487.3969,209.3661879
151.2,25.2,17.3255,0,,,,,699141.1203,209.7798371
151.5,25.25062,17.37717,0,,,,,701226.1754,210.2012282
151.8,25.30015,17.41435,-0.00001,,,,,702726.5112,210.6135455
152.1,25.35015,17.46527,0,,,,,704781.3012,211.0297753
152.4,25.40047,17.48578,0,,,,,705608.9475,211.448669
152.7,25.45031,17.51545,0,,,,,706806.2299,211.8635669
153,25.5,17.57546,0,,,,,709227.8315,212.2772161
153.3,25.55047,17.59977,0,,,,,710208.8203,212.6973585
153.6,25.60047,17.64259,0,,,,,711936.7486,213.1135884
153.9,25.65,17.68926,0,,,,,713820.0372,213.5259056
154.2,25.70046,17.71144,0,,,,,714715.0734,213.9459648
154.5,25.75047,17.76239,0,,,,,716771.0741,214.3622779
154.8,25.8,17.80742,0,,,,,718588.1833,214.7745951
155.1,25.85015,17.84519,0,,,,,720112.3274,215.1920737
155.4,25.90047,17.88081,0,,,,,721549.712,215.6109674
155.7,25.95,17.91336,0,,,,,722863.212,216.0232847
156,26.00031,17.96121,0,,,,,724794.1175,216.4420951
156.3,26.05062,17.99086,-0.00001,,,,,725990.5928,216.8609056
156.6,26.1,18.03038,0,,,,,727585.3553,217.2719742
156.9,26.15031,18.05976,0,,,,,728770.9353,217.6907846
157.2,26.20047,18.09131,0,,,,,730044.0819,218.1083464
157.5,26.25015,18.13176,0,,,,,731676.373,218.5219124
157.8,26.3,18.17229,0,,,,,733311.8923,218.9368935
158.1,26.35062,18.21514,0,,,,,735041.0312,219.3582846
158.4,26.40031,18.26104,-0.00001,,,,,736893.2478,219.7719338
158.7,26.45,18.3013,0,,,,,738517.8717,220.185583
159,26.50062,18.33871,0,,,,,740027.4887,220.6069741
159.3,26.55031,18.39204,0,,,,,742179.5302,221.0206233
159.6,26.60015,18.42265,0,,,,,743414.7448,221.4355212
159.9,26.65047,18.4502,0,,,,,744526.4782,221.8544149
160.2,26.70031,18.50576,0,,,,,746768.5076,222.2693128
160.5,26.75015,18.55145,0,,,,,748612.25,222.6842107
160.8,26.80046,18.57389,0,,,,,749517.7781,223.1030212
161.1,26.85047,18.61185,0,,,,,751049.5894,223.5193343
161.4,26.9,18.63855,0,,,,,752127.0225,223.9316515
161.7,26.95047,18.68925,0,,,,,754172.9349,224.3517939
162,27.00047,18.73369,0,,,,,755966.2356,224.7680238
162.3,27.05015,18.76996,0,,,,,757429.8498,225.1815897
162.6,27.10015,18.80532,0,,,,,758856.7426,225.5978196
162.9,27.15062,18.86151,0,,,,,761124.1945,226.017962
163.2,27.2,18.88069,0,,,,,761898.1709,226.4290305
163.5,27.25015,18.9215,0,,,,,763544.9891,226.8465091
163.8,27.30062,18.9806,0,,,,,765929.8692,227.2666515
164.1,27.35,19.01348,0,,,,,767256.6857,227.67772
164.4,27.40031,19.04368,-0.00001,,,,,768475.3554,228.0965305
164.7,27.45046,19.07822,0,,,,,769869.1585,228.514009
165,27.50015,19.15225,0,,,,,772856.5133,228.9276582
165.3,27.55015,19.17968,0,,,,,773963.4044,229.3438881
165.6,27.60062,19.22014,0,,,,,775596.099,229.7640305
165.9,27.65031,19.24922,0,,,,,776769.573,230.1776797
166.2,27.70015,19.28725,0,,,,,778304.209,230.5925776
166.5,27.75062,19.3407,-0.00001,,,,,780461.093,231.01272
166.8,27.80015,19.37847,-0.00001,,,,,781985.2371,231.4250373
167.1,27.85015,19.40867,0,,,,,783203.9068,231.8412671
167.4,27.90047,19.45327,0,,,,,785003.6641,232.2601608
167.7,27.95031,19.50217,-0.00001,,,,,786976.9405,232.6750587
168,28,19.52249,0,,,,,787796.9196,233.0887079
168.3,28.05046,19.57021,0,,,,,789722.5791,233.5087671
168.6,28.10046,19.61465,0,,,,,791515.8798,233.9249969
168.9,28.15,19.66481,0,,,,,793540.0014,234.3373974
169.2,28.20046,19.68595,0,,,,,794393.0702,234.7574566
169.5,28.25031,19.74091,0,,,,,796610.8876,235.1724377
169.8,28.30015,19.78314,0,,,,,798315.0076,235.5873356
170.1,28.35031,19.81423,0,,,,,799569.5917,236.0048974
170.4,28.40062,19.86373,0,,,,,801567.0801,236.4237078
170.7,28.45,19.91343,0,,,,,803572.6392,236.8347764
171,28.50031,19.94643,-0.00001,,,,,804904.2981,237.2535869
171.3,28.55062,19.98727,-0.00001,,,,,806552.3269,237.6723974
171.6,28.59984,20.03737,0,,,,,808574.0273,238.082134
171.9,28.65031,20.05715,0,,,,,809372.2156,238.5022764
172.2,28.70047,20.08193,0,,,,,810372.1704,238.9198382
172.5,28.75015,20.15935,0,,,,,813496.323,239.3334041
172.8,28.8,20.17814,0,,,,,814254.5615,239.7483853
173.1,28.85062,20.2317,0,,,,,816415.8844,240.1697764
173.4,28.90031,20.28334,0,,,,,818499.7288,240.5834256
173.7,28.95,20.32853,0,,,,,820323.2945,240.9970748
174,29.00062,20.35504,-0.00001,,,,,821393.0605,241.4184659
174.3,29.05015,20.41131,0,,,,,823663.7408,241.8307831
174.6,29.10015,20.45326,0,,,,,825356.5618,242.247013
174.9,29.15047,20.49389,0,,,,,826996.1164,242.6659067
175.2,29.20031,20.5239,0,,,,,828207.119,243.0808046
175.5,29.25,20.57347,0,,,,,830207.4321,243.4944538
175.8,29.30046,20.60876,0,,,,,831631.5001,243.914513
176.1,29.35047,20.64146,0,,,,,832951.0531,244.330826
176.4,29.4,20.70489,0,,,,,835510.663,244.7431433
176.7,29.45046,20.72931,-0.00001,,,,,836496.0906,245.1632025
177,29.50047,20.76789,-0.00001,,,,,838052.9209,245.5795155
177.3,29.55015,20.82027,0,,,,,840166.6269,245.9930815
177.6,29.60031,20.8601,0,,,,,841773.8988,246.4106433
177.9,29.65047,20.89381,-0.00001,,,,,843134.2086,246.828205
178.2,29.7,20.95009,0,,,,,845405.2924,247.2405223
178.5,29.75031,20.97679,0,,,,,846482.7256,247.6593328
178.8,29.80062,21.0318,0,,,,,848702.5607,248.0781432
179.1,29.85,21.08169,-0.00001,,,,,850715.7869,248.4892118
179.4,29.90031,21.11936,0,,,,,852235.8957,248.9080223
179.7,29.95047,21.1659,0,,,,,854113.9384,249.3255841
180,30.00031,21.20336,-0.00001,,,,,855625.573,249.740482
180.3,30.05,21.254,-0.00001,,,,,857669.0642,250.1541312
180.6,30.10062,21.2853,0,,,,,858932.1225,250.5755223
180.9,30.15031,21.34361,0,,,,,861285.1235,250.9891715
181.2,30.2,21.37374,0,,,,,862500.9685,251.4028207
181.5,30.25062,21.40859,0,,,,,863907.281,251.8242118
181.8,30.30031,21.46669,0,,,,,866251.8078,252.237861
182.1,30.35015,21.50712,0,,,,,867883.2918,252.6527589
182.4,30.40047,21.54445,-0.00001,,,,,869389.6805,253.0716526
182.7,30.45031,21.5835,-0.00001,,,,,870965.4769,253.4865505
183,30.50015,21.64573,0,,,,,873476.6629,253.9014484
183.3,30.55046,21.67553,0,,,,,874679.1913,254.3202588
183.6,30.60047,21.71959,0,,,,,876457.1577,254.7365719
183.9,30.65,21.76453,0,,,,,878270.6351,255.1488892
184.2,30.70047,21.81212,0,,,,,880191.0487,255.5690316
184.5,30.75031,21.86916,0,,,,,882492.801,255.9839295
184.8,30.80015,21.89501,-0.00001,,,,,883535.9338,256.3988274
185.1,30.85031,21.94621,0,,,,,885602.0228,256.8163892
185.4,30.90062,21.99542,0,,,,,887587.8088,257.2351996
185.7,30.95,22.03995,0,,,,,889384.7413,257.6462682
186,31.00015,22.06745,-0.00001,,,,,890494.4571,258.0637467
186.3,31.05062,22.12442,0,,,,,892793.3846,258.4838891
186.6,31.09999,22.16039,0,,,,,894244.8929,258.8948745
186.9,31.15031,22.19949,0,,,,,895822.707,259.3137682
187.2,31.20046,22.2376,0,,,,,897360.5713,259.7312467
187.5,31.25031,22.29091,0,,,,,899511.8058,260.1462278
187.8,31.29999,22.33747,0,,,,,901390.6555,260.5597938
188.1,31.35062,22.37095,0,,,,,902741.684,260.9812681
188.4,31.4003,22.4206,-0.00001,,,,,904745.2254,261.3948341
188.7,31.45015,22.47776,-0.00001,,,,,907051.8201,261.8098153
189,31.50062,22.51989,-0.00001,,,,,908751.9047,262.2299577
189.3,31.55015,22.55643,-0.00001,,,,,910226.4143,262.6422749
189.6,31.60015,22.60589,0,,,,,912222.2886,263.0585048
189.9,31.65046,22.65564,0,,,,,914229.8653,263.4773152
190.2,31.70031,22.70313,0,,,,,916146.2436,263.8922964
190.5,31.75015,22.75259,-0.00001,,,,,918142.1179,264.3071943
190.8,31.80046,22.79138,0,,,,,919707.4224,264.7260047
191.1,31.85046,22.83522,0,,,,,921476.5112,265.1422346
191.4,31.89999,22.8863,0,,,,,923537.7578,265.5545518
191.7,31.95062,22.91825,0,,,,,924827.0458,265.9760262
192,32.00031,22.97215,0,,,,,927002.0887,266.3896754
192.3,32.05,23.01443,0,,,,,928708.2263,266.8033246
192.6,32.1003,23.05546,0,,,,,930363.9222,267.2220518
192.9,32.15046,23.12113,-0.00001,,,,,933013.9235,267.6396136
193.2,32.19999,23.16952,-0.00001,,,,,934966.6197,268.0519309
193.5,32.25031,23.21369,0,,,,,936749.0251,268.4708246
193.8,32.30062,23.23899,-0.00001,,,,,937769.9636,268.889635
194.1,32.34983,23.30256,-0.00001,,,,,940335.2229,269.2992884
194.4,32.40031,23.33351,0,,,,,941584.1576,269.7195141
194.7,32.45046,23.38608,0,,,,,943705.5307,270.1369926
195,32.50015,23.43076,-0.00001,,,,,945508.5162,270.5506418
195.3,32.54999,23.46665,0,,,,,946956.7961,270.9655397
195.6,32.60062,23.50623,0,,,,,948553.9798,271.387014
195.9,32.65015,23.56555,-0.00001,,,,,950947.7376,271.7993313
196.2,32.69999,23.6167,0,,,,,953011.809,272.2142292
196.5,32.75062,23.66791,-0.00001,,,,,955078.3015,272.6357035
196.8,32.80015,23.71272,0,,,,,956886.533,273.0480208
197.1,32.85015,23.76212,-0.00001,,,,,958879.9861,273.4642507
197.4,32.90046,23.80524,-0.00001,,,,,960620.0204,273.8830611
197.7,32.95031,23.84639,0,,,,,962280.5587,274.2980423
198,33.00015,23.88048,0,,,,,963656.2028,274.7129402
198.3,33.05046,23.93572,-0.00001,,,,,965885.3191,275.1317506
198.6,33.10046,23.9799,-0.00001,,,,,967668.128,275.5479805
198.9,33.14999,24.0122,-0.00001,,,,,968971.5396,275.9602977
199.2,33.20046,24.08113,0,,,,,971753.0927,276.3804401
199.5,33.25031,24.12429,-0.00001,,,,,973494.7412,276.7954213
199.8,33.3,24.17397,-0.00001,,,,,975499.4932,277.2090705
200.1,33.35015,24.20942,0,,,,,976930.0177,277.626549
200.4,33.40062,24.26492,0,,,,,979169.6259,278.0466914
200.7,33.44999,24.3109,0,,,,,981025.0707,278.4576767
201,33.50031,24.36146,-0.00001,,,,,983065.3336,278.8765704
201.3,33.55062,24.41682,0,,,,,985299.2924,279.2953809
201.6,33.59999,24.44428,0,,,,,986407.394,279.7063662
201.9,33.65046,24.5107,-0.00001,,,,,989087.6603,280.1265086
202.2,33.70046,24.5589,0,,,,,991032.6894,280.5427385
202.5,33.75031,24.5982,0,,,,,992618.5741,280.9577196
202.8,33.8,24.66754,0,,,,,995416.672,281.3713688
203.1,33.85062,24.69471,-0.00001,,,,,996513.0712,281.7927599
203.4,33.90031,24.75736,0,,,,,999041.2056,282.2064091
203.7,33.94999,24.79248,0,,,,,1000458.414,282.6199751
204,34.00077,24.8484,-0.00001,,,,,1002714.97,283.0426981
204.3,34.0503,24.8848,-0.00001,,,,,1004183.83,283.4550154
204.6,34.10015,24.93174,0,,,,,1006078.014,283.8699965
204.9,34.15046,24.98606,0,,,,,1008270.006,284.288807
205.2,34.20031,25.0267,-0.00001,,,,,1009909.964,284.7037881
205.5,34.25015,25.08692,0,,,,,1012340.04,285.118686
205.8,34.30046,25.12234,-0.00001,,,,,1013769.353,285.5374965
206.1,34.35046,25.15098,-0.00001,,,,,1014925.072,285.9537263
206.4,34.39984,25.24609,0,,,,,1018763.074,286.3647949
206.7,34.45046,25.28147,0,,,,,1020190.774,286.786186
207,34.50031,25.32817,-0.00001,,,,,1022075.273,287.2011672
207.3,34.55015,25.37304,-0.00001,,,,,1023885.926,287.6160651
207.6,34.60031,25.4126,-0.00001,,,,,1025482.303,288.0336268
207.9,34.65046,25.4527,-0.00001,,,,,1027100.47,288.4511054
208.2,34.7,25.54446,0.00001,,,,,1030803.289,288.8635059
208.5,34.75031,25.58521,-0.00001,,,,,1032447.686,289.2823163
208.8,34.80062,25.60683,-0.00002,,,,,1033320.124,289.7011268
209.1,34.84999,25.67394,-0.00001,,,,,1036028.234,290.1121121
209.4,34.90031,25.73208,0,,,,,1038374.375,290.5310058
209.7,34.95046,25.78567,-0.00001,,,,,1040536.909,290.9484844
210,35.00031,25.80997,-0.00002,,,,,1041517.494,291.3634655
210.3,35.05,25.88336,-0.00001,,,,,1044479.023,291.7771147
210.6,35.10062,25.94566,0,,,,,1046993.033,292.1985058
210.9,35.1503,25.98241,0,,,,,1048476.017,292.6120718
211.2,35.19999,26.02186,-0.00001,,,,,1050067.955,293.025721
211.5,35.25077,26.05914,0,,,,,1051572.326,293.448444
211.8,35.30015,26.1222,0,,,,,1054117.005,293.8595126
212.1,35.35031,26.14102,-0.00002,,,,,1054876.454,294.2770744
212.4,35.40046,26.22925,-0.00001,,,,,1058436.826,294.6945529
212.7,35.45031,26.28639,0,,,,,1060742.614,295.109534
213,35.50015,26.29036,-0.00002,,,,,1060902.816,295.5244319
213.3,35.55046,26.36732,-0.00002,,,,,1064008.406,295.9432424
213.6,35.60046,26.4558,0.00001,,,,,1067578.866,296.3594722
213.9,35.64999,26.49395,0,,,,,1069118.345,296.7717895
214.2,35.70046,26.50648,-0.00001,,,,,1069623.972,297.1919319
214.5,35.75031,26.59132,0,,,,,1073047.546,297.606913
214.8,35.8,26.59859,-0.00001,,,,,1073340.914,298.0205623
215.1,35.8503,26.67969,0,,,,,1076613.567,298.4392895
215.4,35.90062,26.71278,-0.00001,,,,,1077948.858,298.8581832
215.7,35.94999,26.74902,-0.00001,,,,,1079411.261,299.2691685
216,36.00031,26.86679,0,,,,,1084163.67,299.6880622
216.3,36.05062,26.81234,-0.00002,,,,,1081966.433,300.1068727
216.6,36.09999,26.86778,-0.00002,,,,,1084203.62,300.517858
216.9,36.15031,27.083,0.00013,,,,,1092888.457,300.9367517
217.2,36.20046,27.002,-0.00004,,,,,1089619.84,301.3542303
217.5,36.25031,27.02923,-0.00003,,,,,1090718.66,301.7692114
217.8,36.30015,27.16833,0.0001,,,,,1096331.804,302.1841093
218.1,36.35062,27.18012,0.0002,,,,,1096807.57,302.6042517
218.4,36.40031,27.22911,-0.00002,,,,,1098784.478,303.0179009
218.7,36.45015,27.32206,-0.00004,,,,,1102535.317,303.4327988
219,36.50077,27.31212,-0.00005,,,,,1102134.205,303.8541899
219.3,36.55015,27.39179,0,,,,,1105349.153,304.2652585
219.6,36.60015,27.46408,0.00001,,,,,1108266.293,304.6814883
219.9,36.65046,27.49928,0,,,,,1109686.729,305.1002988
220.2,36.70031,27.52221,0,,,,,1110612.03,305.5152799
220.5,36.74999,27.61953,0.00001,,,,,1114539.214,305.9288459
220.8,36.80046,27.64613,-0.00001,,,,,1115612.612,306.3489883
221.1,36.85046,27.71571,-0.00001,,,,,1118420.394,306.7652181
221.4,36.89999,27.74631,-0.00001,,,,,1119655.205,307.1775354
221.7,36.95062,27.82574,0.00001,,,,,1122860.468,307.5990097
222,37.00046,27.86529,0,,,,,1124456.441,308.0139076
222.3,37.05,27.94035,-0.00001,,,,,1127485.36,308.4263081
222.6,37.10031,27.96422,-0.00002,,,,,1128448.593,308.8451186
222.9,37.15062,27.99003,0,,,,,1129490.112,309.2639291
223.2,37.19999,28.12549,0,,,,,1134956.37,309.6749144
223.5,37.25046,28.13577,-0.00001,,,,,1135371.202,310.0950568
223.8,37.30062,28.17368,-0.00001,,,,,1136900.996,310.5126186
224.1,37.34999,28.24165,0,,,,,1139643.809,310.9236039
224.4,37.40031,28.32143,0,,,,,1142863.196,311.3424976
224.7,37.45046,28.33782,-0.00001,,,,,1143524.586,311.7599761
225,37.50031,28.40836,0,,,,,1146371.108,312.1749573
225.3,37.55,28.46324,0,,,,,1148585.697,312.5886065
225.6,37.60062,28.48976,-0.00001,,,,,1149655.867,313.0099976
225.9,37.65031,28.56526,-0.00001,,,,,1152702.541,313.4236468
226.2,37.70015,28.62679,0,,,,,1155185.48,313.8385447
226.5,37.75062,28.66927,0,,,,,1156899.688,314.2586871
226.8,37.80015,28.70966,-0.00001,,,,,1158529.558,314.6710044
227.1,37.8503,28.78331,-0.00001,,,,,1161501.579,315.0884829
227.4,37.90062,28.82413,0,,,,,1163148.8,315.5073766
227.7,37.95046,28.88706,0,,,,,1165688.234,315.9222745
228,38.00015,28.94317,-0.00001,,,,,1167952.457,316.3359237
228.3,38.05046,28.99451,-0.00001,,,,,1170024.196,316.7547342
228.6,38.10046,29.0567,0,,,,,1172533.768,317.170964
228.9,38.14999,29.11337,0,,,,,1174820.589,317.5832813
229.2,38.20046,29.1583,-0.00001,,,,,1176633.663,318.0034237
229.5,38.25031,29.23717,0,,,,,1179816.328,318.4184048
229.8,38.30015,29.26895,0,,,,,1181098.756,318.8333027
230.1,38.35015,29.33389,-0.00001,,,,,1183719.299,319.2495326
230.4,38.40046,29.36652,-0.00001,,,,,1185036.027,319.668343
230.7,38.45,29.45848,-0.00001,,,,,1188746.917,320.0807435
231,38.50031,29.48517,0,,,,,1189823.947,320.499554
231.3,38.55062,29.55539,-0.00001,,,,,1192657.555,320.9183645
231.6,38.59999,29.62092,-0.00001,,,,,1195301.907,321.3293498
231.9,38.6503,29.66512,0,,,,,1197085.523,321.7481603
232.2,38.70046,29.73554,0,,,,,1199927.203,322.165722
232.5,38.75031,29.77819,-0.00001,,,,,1201648.271,322.5807032
232.8,38.80015,29.82581,-0.00001,,,,,1203569.895,322.9956011
233.1,38.85062,29.88065,0,,,,,1205782.87,323.4157435
233.4,38.9003,29.96322,0,,,,,1209114.842,323.8293094
233.7,38.94999,30.02592,-0.00001,,,,,1211644.994,324.2429587
234,39.00077,30.04838,-0.00001,,,,,1212551.329,324.6656817
234.3,39.05015,30.11741,0,,,,,1215336.918,325.0767503
234.6,39.10015,30.15091,-0.00001,,,,,1216688.753,325.4929801
234.9,39.15046,30.21878,-0.00001,,,,,1219427.532,325.9117906
235.2,39.20031,30.27411,0,,,,,1221660.28,326.3267717
235.5,39.25015,30.33463,0,,,,,1224102.462,326.7416696
235.8,39.30046,30.38719,0,,,,,1226223.431,327.1604801
236.1,39.35046,30.45194,-0.00001,,,,,1228836.308,327.5767099
236.4,39.39999,30.51986,-0.00001,,,,,1231577.104,327.9890272
236.7,39.45062,30.56017,0,,,,,1233203.745,328.4105015
237,39.50047,30.64626,-0.00001,,,,,1236677.761,328.8254827
237.3,39.55,30.68343,-0.00001,,,,,1238177.693,329.2377999
237.6,39.60015,30.73928,0,,,,,1240431.425,329.6552785
237.85,39.64156,30.77707,0,,,,,1241956.376,330